Workbook

Sheet ทดสอบ
E9: วันที่ 28/08/69 PO.28/08/69
B10: ผู้ส่ง : 7-11 บางบัวทอง 6 ล้อ 83-8096 โม
B12: เซเว่น-บางบัวทอง | D12: บรรจุ/ตก. | E12: 14.00 น. | G12: 13.00 น. | I12: 11.00 น | K12: 09.00 น | N12: 08.00 น. | Q12: ยอดรวม | S12: ยอดเผื่อ | T12: คงเหลือ | V12: KK | W12: SRR | X12: CMI | Y12: HKT | Z12: HDY
E13: ขอนแก่น KK | G13: สุราษร์ธานี ST | I13: เชียงใหม่ CM | K13: ภูเก็ต PK | N13: หาดใหญ่ HY
E14: PO1 | F14: PO 2 | G14: PO1 | H14: PO 2 | I14: PO1 | J14: PO 2 | K14: PO1 | L14: PO 2 | M14: PO3 | N14: PO1 | O14: PO2 | P14: PO3 | Q14: รวมแพค | R14: ตะกร้า | AK14: 32
B15: 1 | C15: องุ่นดำไร้เมล็ด 150 กรัม x36P | D15: 36 | Q15: =SUM(E15:P15) -> 0 | R15: ='บางบัวทอง-รถ'!C10 -> 0 | S15: 260 | T15: =SUM(S15-Q15) -> 260 | V15: =SUM(E15,F15) -> 0 | W15: =SUM(G15,H15) -> 0 | X15: =SUM(I15,J15) -> 0 | Y15: =SUM(K15,L15,M15,) -> 0 | Z15: =SUM(N15,O15,P15) -> 0 | AK15: =IF(AK14=0, "", IF(MOD(AK14, $D$15) = 0, AK14 / $D$15, IF(INT(AK14 / $D$15) = 0, MOD(AK14, $D$15) & " P", INT(AK14 / $D$15) & " + " & MOD(AK14, $D$15) & " P"))) -> 32 P
C16: BlackGrapesSeedless150 g. (8859388000025 ) | E16: =IF(E15=0, "", IF(MOD(E15, $D$15) = 0, E15 / $D$15, IF(INT(E15 / $D$15) = 0, MOD(E15, $D$15) & " P", INT(E15 / $D$15) & " + " & MOD(E15, $D$15) & " P"))) | F16: =IF(F15=0, "", IF(MOD(F15, $D$15) = 0, F15 / $D$15, IF(INT(F15 / $D$15) = 0, MOD(F15, $D$15) & " P", INT(F15 / $D$15) & " + " & MOD(F15, $D$15) & " P"))) | G16: =IF(G15=0, "", IF(MOD(G15, $D$15) = 0, G15 / $D$15, IF(INT(G15 / $D$15) = 0, MOD(G15, $D$15) & " P", INT(G15 / $D$15) & " + " & MOD(G15, $D$15) & " P"))) | H16: =IF(H15=0, "", IF(MOD(H15, $D$15) = 0, H15 / $D$15, IF(INT(H15 / $D$15) = 0, MOD(H15, $D$15) & " P", INT(H15 / $D$15) & " + " & MOD(H15, $D$15) & " P"))) | I16: =IF(I15=0, "", IF(MOD(I15, $D$15) = 0, I15 / $D$15, IF(INT(I15 / $D$15) = 0, MOD(I15, $D$15) & " P", INT(I15 / $D$15) & " + " & MOD(I15, $D$15) & " P"))) | J16: =IF(J15=0, "", IF(MOD(J15, $D$15) = 0, J15 / $D$15, IF(INT(J15 / $D$15) = 0, MOD(J15, $D$15) & " P", INT(J15 / $D$15) & " + " & MOD(J15, $D$15) & " P"))) | K16: =IF(K15=0, "", IF(MOD(K15, $D$15) = 0, K15 / $D$15, IF(INT(K15 / $D$15) = 0, MOD(K15, $D$15) & " P", INT(K15 / $D$15) & " + " & MOD(K15, $D$15) & " P"))) | L16: =IF(L15=0, "", IF(MOD(L15, $D$15) = 0, L15 / $D$15, IF(INT(L15 / $D$15) = 0, MOD(L15, $D$15) & " P", INT(L15 / $D$15) & " + " & MOD(L15, $D$15) & " P"))) | ... P16: =IF(P15=0, "", IF(MOD(P15, $D$15) = 0, P15 / $D$15, IF(INT(P15 / $D$15) = 0, MOD(P15, $D$15) & " P", INT(P15 / $D$15) & " + " & MOD(P15, $D$15) & " P"))) | AK16: 129
B17: 2 | C17: องุ่นแดงนอกมีเมล็ด 200 กรัม x 32 P | D17: 32 | Q17: =SUM(E17:P17) -> 0 | R17: ='บางบัวทอง-รถ'!C11 -> 0 | S17: 650 | T17: =SUM(S17-Q17) -> 650 | V17: =SUM(E17,F17) -> 0 | W17: =SUM(G17,H17) -> 0 | X17: =SUM(I17,J17) -> 0 | Y17: =SUM(K17,L17,M17,) -> 0 | Z17: =SUM(N17,O17,P17) -> 0 | AK17: =IF(AK16=0, "", IF(MOD(AK16, $D$17) = 0, AK16 / $D$17, IF(INT(AK16 / $D$17) = 0, MOD(AK16, $D$17) & " P", INT(AK16 / $D$17) & " + " & MOD(AK16, $D$17) & " P"))) -> 4 + 1 P
C18: Red Seed 200 g. ( 8859388000100 ) | E18: =IF(E17=0, "", IF(MOD(E17, $D$17) = 0, E17 / $D$17, IF(INT(E17 / $D$17) = 0, MOD(E17, $D$17) & " P", INT(E17 / $D$17) & " + " & MOD(E17, $D$17) & " P"))) | F18: =IF(F17=0, "", IF(MOD(F17, $D$17) = 0, F17 / $D$17, IF(INT(F17 / $D$17) = 0, MOD(F17, $D$17) & " P", INT(F17 / $D$17) & " + " & MOD(F17, $D$17) & " P"))) | G18: =IF(G17=0, "", IF(MOD(G17, $D$17) = 0, G17 / $D$17, IF(INT(G17 / $D$17) = 0, MOD(G17, $D$17) & " P", INT(G17 / $D$17) & " + " & MOD(G17, $D$17) & " P"))) | H18: =IF(H17=0, "", IF(MOD(H17, $D$17) = 0, H17 / $D$17, IF(INT(H17 / $D$17) = 0, MOD(H17, $D$17) & " P", INT(H17 / $D$17) & " + " & MOD(H17, $D$17) & " P"))) | I18: =IF(I17=0, "", IF(MOD(I17, $D$17) = 0, I17 / $D$17, IF(INT(I17 / $D$17) = 0, MOD(I17, $D$17) & " P", INT(I17 / $D$17) & " + " & MOD(I17, $D$17) & " P"))) | J18: =IF(J17=0, "", IF(MOD(J17, $D$17) = 0, J17 / $D$17, IF(INT(J17 / $D$17) = 0, MOD(J17, $D$17) & " P", INT(J17 / $D$17) & " + " & MOD(J17, $D$17) & " P"))) | K18: =IF(K17=0, "", IF(MOD(K17, $D$17) = 0, K17 / $D$17, IF(INT(K17 / $D$17) = 0, MOD(K17, $D$17) & " P", INT(K17 / $D$17) & " + " & MOD(K17, $D$17) & " P"))) | L18: =IF(L17=0, "", IF(MOD(L17, $D$17) = 0, L17 / $D$17, IF(INT(L17 / $D$17) = 0, MOD(L17, $D$17) & " P", INT(L17 / $D$17) & " + " & MOD(L17, $D$17) & " P"))) | ... P18: =IF(P17=0, "", IF(MOD(P17, $D$17) = 0, P17 / $D$17, IF(INT(P17 / $D$17) = 0, MOD(P17, $D$17) & " P", INT(P17 / $D$17) & " + " & MOD(P17, $D$17) & " P"))) | AK18: 54
B19: 3 | C19: เชอร์รี่สดนำเข้า 150 กรัม (USA.) x36 P | D19: 36 | Q19: =SUM(E19:P19) -> 0 | R19: ='บางบัวทอง-รถ'!C12 -> 0 | S19: 260 | T19: =SUM(S19-Q19) -> 260 | V19: =SUM(E19,F19) -> 0 | W19: =SUM(G19,H19) -> 0 | X19: =SUM(I19,J19) -> 0 | Y19: =SUM(K19,L19,M19,) -> 0 | Z19: =SUM(N19,O19,P19) -> 0 | AK19: =IF(AK18=0, "", IF(MOD(AK18, $D$19) = 0, AK18/ $D$19, IF(INT(AK18 / $D$19) = 0, MOD(AK18, $D$19) & " P", INT(AK18 / $D$19) & " + " & MOD(AK18, $D$19) & " P"))) -> 1 + 18 P
C20: Cherry150g (8859388008885 ) | E20: =IF(E19=0, "", IF(MOD(E19, $D$19) = 0, E19 / $D$19, IF(INT(E19 / $D$19) = 0, MOD(E19, $D$19) & " P", INT(E19 / $D$19) & " + " & MOD(E19, $D$19) & " P"))) | F20: =IF(F19=0, "", IF(MOD(F19, $D$19) = 0, F19 / $D$19, IF(INT(F19 / $D$19) = 0, MOD(F19, $D$19) & " P", INT(F19 / $D$19) & " + " & MOD(F19, $D$19) & " P"))) | G20: =IF(G19=0, "", IF(MOD(G19, $D$19) = 0, G19 / $D$19, IF(INT(G19 / $D$19) = 0, MOD(G19, $D$19) & " P", INT(G19 / $D$19) & " + " & MOD(G19, $D$19) & " P"))) | H20: =IF(H19=0, "", IF(MOD(H19, $D$19) = 0, H19 / $D$19, IF(INT(H19 / $D$19) = 0, MOD(H19, $D$19) & " P", INT(H19 / $D$19) & " + " & MOD(H19, $D$19) & " P"))) | I20: =IF(I19=0, "", IF(MOD(I19, $D$19) = 0, I19 / $D$19, IF(INT(I19 / $D$19) = 0, MOD(I19, $D$19) & " P", INT(I19 / $D$19) & " + " & MOD(I19, $D$19) & " P"))) | J20: =IF(J19=0, "", IF(MOD(J19, $D$19) = 0, J19 / $D$19, IF(INT(J19 / $D$19) = 0, MOD(J19, $D$19) & " P", INT(J19 / $D$19) & " + " & MOD(J19, $D$19) & " P"))) | K20: =IF(K19=0, "", IF(MOD(K19, $D$19) = 0, K19 / $D$19, IF(INT(K19 / $D$19) = 0, MOD(K19, $D$19) & " P", INT(K19 / $D$19) & " + " & MOD(K19, $D$19) & " P"))) | L20: =IF(L19=0, "", IF(MOD(L19, $D$19) = 0, L19 / $D$19, IF(INT(L19 / $D$19) = 0, MOD(L19, $D$19) & " P", INT(L19 / $D$19) & " + " & MOD(L19, $D$19) & " P"))) | ... P20: =IF(P19=0, "", IF(MOD(P19, $D$19) = 0, P19 / $D$19, IF(INT(P19 / $D$19) = 0, MOD(P19, $D$19) & " P", INT(P19 / $D$19) & " + " & MOD(P19, $D$19) & " P"))) | AK20: 12
B21: 4 | C21: ส้มแพ็ก 4 ผล(450 กรัม) x14 P | D21: 14 | Q21: =SUM(E21:P21) -> 0 | R21: ='บางบัวทอง-รถ'!C13 -> 0 | S21: 220 | T21: =SUM(S21-Q21) -> 220 | V21: =SUM(E21,F21) -> 0 | W21: =SUM(G21,H21) -> 0 | X21: =SUM(I21,J21) -> 0 | Y21: =SUM(K21,L21,M21,) -> 0 | Z21: =SUM(N21,O21,P21) -> 0 | AK21: =IF(AK20=0, "", IF(MOD(AK20, $D$21) = 0, AK20/ $D$21, IF(INT(AK20 / $D$21) = 0, MOD(AK20, $D$21) & " P", INT(AK20 / $D$21) & " + " & MOD(AK20, $D$21) & " P"))) -> 12 P
C22: Mandarin orange P.4 (8859388000445) | E22: =IF(E21=0, "", IF(MOD(E21, $D$21) = 0, E21/ $D$21, IF(INT(E21 / $D$21) = 0, MOD(E21, $D$21) & " P", INT(E21 / $D$21) & " + " & MOD(E21, $D$21) & " P"))) | F22: =IF(F21=0, "", IF(MOD(F21, $D$21) = 0, F21/ $D$21, IF(INT(F21 / $D$21) = 0, MOD(F21, $D$21) & " P", INT(F21 / $D$21) & " + " & MOD(F21, $D$21) & " P"))) | G22: =IF(G21=0, "", IF(MOD(G21, $D$21) = 0, G21/ $D$21, IF(INT(G21 / $D$21) = 0, MOD(G21, $D$21) & " P", INT(G21 / $D$21) & " + " & MOD(G21, $D$21) & " P"))) | H22: =IF(H21=0, "", IF(MOD(H21, $D$21) = 0, H21/ $D$21, IF(INT(H21 / $D$21) = 0, MOD(H21, $D$21) & " P", INT(H21 / $D$21) & " + " & MOD(H21, $D$21) & " P"))) | I22: =IF(I21=0, "", IF(MOD(I21, $D$21) = 0, I21/ $D$21, IF(INT(I21 / $D$21) = 0, MOD(I21, $D$21) & " P", INT(I21 / $D$21) & " + " & MOD(I21, $D$21) & " P"))) | J22: =IF(J21=0, "", IF(MOD(J21, $D$21) = 0, J21/ $D$21, IF(INT(J21 / $D$21) = 0, MOD(J21, $D$21) & " P", INT(J21 / $D$21) & " + " & MOD(J21, $D$21) & " P"))) | K22: =IF(K21=0, "", IF(MOD(K21, $D$21) = 0, K21/ $D$21, IF(INT(K21 / $D$21) = 0, MOD(K21, $D$21) & " P", INT(K21 / $D$21) & " + " & MOD(K21, $D$21) & " P"))) | L22: =IF(L21=0, "", IF(MOD(L21, $D$21) = 0, L21/ $D$21, IF(INT(L21 / $D$21) = 0, MOD(L21, $D$21) & " P", INT(L21 / $D$21) & " + " & MOD(L21, $D$21) & " P"))) | ... P22: =IF(P21=0, "", IF(MOD(P21, $D$21) = 0, P21/ $D$21, IF(INT(P21 / $D$21) = 0, MOD(P21, $D$21) & " P", INT(P21 / $D$21) & " + " & MOD(P21, $D$21) & " P"))) | AK22: 227
B23: 5 | C23: แอปเปิ้ลแพ็ก 4 ผล(400 กรัม) x14 P | D23: 14 | Q23: =SUM(E23:P23) -> 0 | R23: ='บางบัวทอง-รถ'!C14 -> 0 | S23: 230 | T23: =SUM(S23-Q23) -> 230 | V23: =SUM(E23,F23) -> 0 | W23: =SUM(G23,H23) -> 0 | X23: =SUM(I23,J23) -> 0 | Y23: =SUM(K23,L23,M23,) -> 0 | Z23: =SUM(N23,O23,P23) -> 0 | AK23: =IF(AK22=0, "", IF(MOD(AK22, $D$23) = 0, AK22/ $D$23, IF(INT(AK22 / $D$23) = 0, MOD(AK22, $D$23) & " P", INT(AK22 / $D$23) & " + " & MOD(AK22, $D$23) & " P"))) -> 16 + 3 P
C24: Apple P.4 (8859388000568 ) | E24: =IF(E23=0, "", IF(MOD(E23, $D$23) = 0, E23/ $D$23, IF(INT(E23 / $D$23) = 0, MOD(E23, $D$23) & " P", INT(E23 / $D$23) & " + " & MOD(E23, $D$23) & " P"))) | F24: =IF(F23=0, "", IF(MOD(F23, $D$23) = 0, F23/ $D$23, IF(INT(F23 / $D$23) = 0, MOD(F23, $D$23) & " P", INT(F23 / $D$23) & " + " & MOD(F23, $D$23) & " P"))) | G24: =IF(G23=0, "", IF(MOD(G23, $D$23) = 0, G23/ $D$23, IF(INT(G23 / $D$23) = 0, MOD(G23, $D$23) & " P", INT(G23 / $D$23) & " + " & MOD(G23, $D$23) & " P"))) | H24: =IF(H23=0, "", IF(MOD(H23, $D$23) = 0, H23/ $D$23, IF(INT(H23 / $D$23) = 0, MOD(H23, $D$23) & " P", INT(H23 / $D$23) & " + " & MOD(H23, $D$23) & " P"))) | I24: =IF(I23=0, "", IF(MOD(I23, $D$23) = 0, I23/ $D$23, IF(INT(I23 / $D$23) = 0, MOD(I23, $D$23) & " P", INT(I23 / $D$23) & " + " & MOD(I23, $D$23) & " P"))) | J24: =IF(J23=0, "", IF(MOD(J23, $D$23) = 0, J23/ $D$23, IF(INT(J23 / $D$23) = 0, MOD(J23, $D$23) & " P", INT(J23 / $D$23) & " + " & MOD(J23, $D$23) & " P"))) | K24: =IF(K23=0, "", IF(MOD(K23, $D$23) = 0, K23/ $D$23, IF(INT(K23 / $D$23) = 0, MOD(K23, $D$23) & " P", INT(K23 / $D$23) & " + " & MOD(K23, $D$23) & " P"))) | L24: =IF(L23=0, "", IF(MOD(L23, $D$23) = 0, L23/ $D$23, IF(INT(L23 / $D$23) = 0, MOD(L23, $D$23) & " P", INT(L23 / $D$23) & " + " & MOD(L23, $D$23) & " P"))) | ... P24: =IF(P23=0, "", IF(MOD(P23, $D$23) = 0, P23/ $D$23, IF(INT(P23 / $D$23) = 0, MOD(P23, $D$23) & " P", INT(P23 / $D$23) & " + " & MOD(P23, $D$23) & " P"))) | AK24: 25
B25: 6 | C25: องุ่นแดงไร้เมล็ด150กรัม x 32 Pไข่ปลา | D25: 32 | Q25: =SUM(E25:P25) -> 0 | R25: ='บางบัวทอง-รถ'!C15 -> 0 | S25: 320 | T25: =SUM(S25-Q25) -> 320 | V25: =SUM(E25,F25) -> 0 | W25: =SUM(G25,H25) -> 0 | X25: =SUM(I25,J25) -> 0 | Y25: =SUM(K25,L25,M25,) -> 0 | Z25: =SUM(N25,O25,P25) -> 0 | AK25: =IF(AK24=0, "", IF(MOD(AK24, $D$25) = 0, AK24/ $D$25, IF(INT(AK24 / $D$25) = 0, MOD(AK24, $D$25) & " P", INT(AK24 / $D$25) & " + " & MOD(AK24, $D$25) & " P"))) -> 25 P
C26: Red Seedless 150 g. ( 8859388007000 ) | E26: =IF(E25=0, "", IF(MOD(E25, $D$25) = 0, E25/ $D$25, IF(INT(E25 / $D$25) = 0, MOD(E25, $D$25) & " P", INT(E25 / $D$25) & " + " & MOD(E25, $D$25) & " P"))) | F26: =IF(F25=0, "", IF(MOD(F25, $D$25) = 0, F25/ $D$25, IF(INT(F25 / $D$25) = 0, MOD(F25, $D$25) & " P", INT(F25 / $D$25) & " + " & MOD(F25, $D$25) & " P"))) | G26: =IF(G25=0, "", IF(MOD(G25, $D$25) = 0, G25/ $D$25, IF(INT(G25 / $D$25) = 0, MOD(G25, $D$25) & " P", INT(G25 / $D$25) & " + " & MOD(G25, $D$25) & " P"))) | H26: =IF(H25=0, "", IF(MOD(H25, $D$25) = 0, H25/ $D$25, IF(INT(H25 / $D$25) = 0, MOD(H25, $D$25) & " P", INT(H25 / $D$25) & " + " & MOD(H25, $D$25) & " P"))) | I26: =IF(I25=0, "", IF(MOD(I25, $D$25) = 0, I25/ $D$25, IF(INT(I25 / $D$25) = 0, MOD(I25, $D$25) & " P", INT(I25 / $D$25) & " + " & MOD(I25, $D$25) & " P"))) | J26: =IF(J25=0, "", IF(MOD(J25, $D$25) = 0, J25/ $D$25, IF(INT(J25 / $D$25) = 0, MOD(J25, $D$25) & " P", INT(J25 / $D$25) & " + " & MOD(J25, $D$25) & " P"))) | K26: =IF(K25=0, "", IF(MOD(K25, $D$25) = 0, K25/ $D$25, IF(INT(K25 / $D$25) = 0, MOD(K25, $D$25) & " P", INT(K25 / $D$25) & " + " & MOD(K25, $D$25) & " P"))) | L26: =IF(L25=0, "", IF(MOD(L25, $D$25) = 0, L25/ $D$25, IF(INT(L25 / $D$25) = 0, MOD(L25, $D$25) & " P", INT(L25 / $D$25) & " + " & MOD(L25, $D$25) & " P"))) | ... P26: =IF(P25=0, "", IF(MOD(P25, $D$25) = 0, P25/ $D$25, IF(INT(P25 / $D$25) = 0, MOD(P25, $D$25) & " P", INT(P25 / $D$25) & " + " & MOD(P25, $D$25) & " P"))) | AK26: 2
B27: 7 | C27: สตรอเบอร์รี่ 250 กรัม x 27 P | D27: 27 | Q27: =SUM(E27:P27) -> 0 | R27: ='บางบัวทอง-รถ'!C16 -> 0 | S27: 280 | T27: =SUM(S27-Q27) -> 280 | V27: =SUM(E27,F27) -> 0 | W27: =SUM(G27,H27) -> 0 | X27: =SUM(I27,J27) -> 0 | Y27: =SUM(K27,L27,M27,) -> 0 | Z27: =SUM(N27,O27,P27) -> 0 | AK27: =IF(AK26=0, "", IF(MOD(AK26, $D$27) = 0, AK26/ $D$27, IF(INT(AK26 / $D$27) = 0, MOD(AK26, $D$27) & " P", INT(AK26 / $D$27) & " + " & MOD(AK26, $D$27) & " P"))) -> 2 P
C28: Straw AUS 250 g. ( 2003009710008 ) | E28: =IF(E27=0, "", IF(MOD(E27, $D$27) = 0, E27/ $D$27, IF(INT(E27 / $D$27) = 0, MOD(E27, $D$27) & " P", INT(E27 / $D$27) & " + " & MOD(E27, $D$27) & " P"))) | F28: =IF(F27=0, "", IF(MOD(F27, $D$27) = 0, F27/ $D$27, IF(INT(F27 / $D$27) = 0, MOD(F27, $D$27) & " P", INT(F27 / $D$27) & " + " & MOD(F27, $D$27) & " P"))) | G28: =IF(G27=0, "", IF(MOD(G27, $D$27) = 0, G27/ $D$27, IF(INT(G27 / $D$27) = 0, MOD(G27, $D$27) & " P", INT(G27 / $D$27) & " + " & MOD(G27, $D$27) & " P"))) | H28: =IF(H27=0, "", IF(MOD(H27, $D$27) = 0, H27/ $D$27, IF(INT(H27 / $D$27) = 0, MOD(H27, $D$27) & " P", INT(H27 / $D$27) & " + " & MOD(H27, $D$27) & " P"))) | I28: =IF(I27=0, "", IF(MOD(I27, $D$27) = 0, I27/ $D$27, IF(INT(I27 / $D$27) = 0, MOD(I27, $D$27) & " P", INT(I27 / $D$27) & " + " & MOD(I27, $D$27) & " P"))) | J28: =IF(J27=0, "", IF(MOD(J27, $D$27) = 0, J27/ $D$27, IF(INT(J27 / $D$27) = 0, MOD(J27, $D$27) & " P", INT(J27 / $D$27) & " + " & MOD(J27, $D$27) & " P"))) | K28: =IF(K27=0, "", IF(MOD(K27, $D$27) = 0, K27/ $D$27, IF(INT(K27 / $D$27) = 0, MOD(K27, $D$27) & " P", INT(K27 / $D$27) & " + " & MOD(K27, $D$27) & " P"))) | L28: =IF(L27=0, "", IF(MOD(L27, $D$27) = 0, L27/ $D$27, IF(INT(L27 / $D$27) = 0, MOD(L27, $D$27) & " P", INT(L27 / $D$27) & " + " & MOD(L27, $D$27) & " P"))) | ... P28: =IF(P27=0, "", IF(MOD(P27, $D$27) = 0, P27/ $D$27, IF(INT(P27 / $D$27) = 0, MOD(P27, $D$27) & " P", INT(P27 / $D$27) & " + " & MOD(P27, $D$27) & " P"))) | AK28: 74
B29: 8 | C29: บลูเบอร์รี่ 125 กรัม x 36 P | D29: 36 | Q29: =SUM(E29:P29) -> 0 | R29: ='บางบัวทอง-รถ'!C17 -> 0 | S29: 680 | T29: =SUM(S29-Q29) -> 680 | V29: =SUM(E29,F29) -> 0 | W29: =SUM(G29,H29) -> 0 | X29: =SUM(I29,J29) -> 0 | Y29: =SUM(K29,L29,M29,) -> 0 | Z29: =SUM(N29,O29,P29) -> 0 | AK29: =IF(AK28=0, "", IF(MOD(AK28, $D$29) = 0, AK28/ $D$29, IF(INT(AK28 / $D$29) = 0, MOD(AK28, $D$29) & " P", INT(AK28 / $D$29) & " + " & MOD(AK28, $D$29) & " P"))) -> 2 + 2 P
C30: Blue 125 g. ( 2003009720007 ) | E30: =IF(E29=0, "", IF(MOD(E29, $D$29) = 0, E29/ $D$29, IF(INT(E29 / $D$29) = 0, MOD(E29, $D$29) & " P", INT(E29 / $D$29) & " + " & MOD(E29, $D$29) & " P"))) | F30: =IF(F29=0, "", IF(MOD(F29, $D$29) = 0, F29/ $D$29, IF(INT(F29 / $D$29) = 0, MOD(F29, $D$29) & " P", INT(F29 / $D$29) & " + " & MOD(F29, $D$29) & " P"))) | G30: =IF(G29=0, "", IF(MOD(G29, $D$29) = 0, G29/ $D$29, IF(INT(G29 / $D$29) = 0, MOD(G29, $D$29) & " P", INT(G29 / $D$29) & " + " & MOD(G29, $D$29) & " P"))) | H30: =IF(H29=0, "", IF(MOD(H29, $D$29) = 0, H29/ $D$29, IF(INT(H29 / $D$29) = 0, MOD(H29, $D$29) & " P", INT(H29 / $D$29) & " + " & MOD(H29, $D$29) & " P"))) | I30: =IF(I29=0, "", IF(MOD(I29, $D$29) = 0, I29/ $D$29, IF(INT(I29 / $D$29) = 0, MOD(I29, $D$29) & " P", INT(I29 / $D$29) & " + " & MOD(I29, $D$29) & " P"))) | J30: =IF(J29=0, "", IF(MOD(J29, $D$29) = 0, J29/ $D$29, IF(INT(J29 / $D$29) = 0, MOD(J29, $D$29) & " P", INT(J29 / $D$29) & " + " & MOD(J29, $D$29) & " P"))) | K30: =IF(K29=0, "", IF(MOD(K29, $D$29) = 0, K29/ $D$29, IF(INT(K29 / $D$29) = 0, MOD(K29, $D$29) & " P", INT(K29 / $D$29) & " + " & MOD(K29, $D$29) & " P"))) | L30: =IF(L29=0, "", IF(MOD(L29, $D$29) = 0, L29/ $D$29, IF(INT(L29 / $D$29) = 0, MOD(L29, $D$29) & " P", INT(L29 / $D$29) & " + " & MOD(L29, $D$29) & " P"))) | ... P30: =IF(P29=0, "", IF(MOD(P29, $D$29) = 0, P29/ $D$29, IF(INT(P29 / $D$29) = 0, MOD(P29, $D$29) & " P", INT(P29 / $D$29) & " + " & MOD(P29, $D$29) & " P"))) | AK30: 34
B31: 9 | C31: องุ่นดำไร้เมล็ด 300 กรัม x20P | D31: 20 | Q31: =SUM(E31:P31) -> 0 | R31: ='บางบัวทอง-รถ'!C18 -> 0 | S31: 160 | T31: =SUM(S31-Q31) -> 160 | V31: =SUM(E31,F31) -> 0 | W31: =SUM(G31,H31) -> 0 | X31: =SUM(I31,J31) -> 0 | Y31: =SUM(K31,L31,M31,) -> 0 | Z31: =SUM(N31,O31,P31) -> 0 | AK31: =IF(AK30=0, "", IF(MOD(AK30, $D$31) = 0, AK30/ $D$31, IF(INT(AK30 / $D$31) = 0, MOD(AK30, $D$31) & " P", INT(AK30 / $D$31) & " + " & MOD(AK30, $D$31) & " P"))) -> 1 + 14 P
C32: BlackGrapesSeedless300g. (8859388002562 ) | E32: =IF(E31=0, "", IF(MOD(E31, $D$31) = 0, E31/ $D$31, IF(INT(E31 / $D$31) = 0, MOD(E31, $D$31) & " P", INT(E31 / $D$31) & " + " & MOD(E31, $D$31) & " P"))) | F32: =IF(F31=0, "", IF(MOD(F31, $D$31) = 0, F31/ $D$31, IF(INT(F31 / $D$31) = 0, MOD(F31, $D$31) & " P", INT(F31 / $D$31) & " + " & MOD(F31, $D$31) & " P"))) | G32: =IF(G31=0, "", IF(MOD(G31, $D$31) = 0, G31/ $D$31, IF(INT(G31 / $D$31) = 0, MOD(G31, $D$31) & " P", INT(G31 / $D$31) & " + " & MOD(G31, $D$31) & " P"))) | H32: =IF(H31=0, "", IF(MOD(H31, $D$31) = 0, H31/ $D$31, IF(INT(H31 / $D$31) = 0, MOD(H31, $D$31) & " P", INT(H31 / $D$31) & " + " & MOD(H31, $D$31) & " P"))) | I32: =IF(I31=0, "", IF(MOD(I31, $D$31) = 0, I31/ $D$31, IF(INT(I31 / $D$31) = 0, MOD(I31, $D$31) & " P", INT(I31 / $D$31) & " + " & MOD(I31, $D$31) & " P"))) | J32: =IF(J31=0, "", IF(MOD(J31, $D$31) = 0, J31/ $D$31, IF(INT(J31 / $D$31) = 0, MOD(J31, $D$31) & " P", INT(J31 / $D$31) & " + " & MOD(J31, $D$31) & " P"))) | K32: =IF(K31=0, "", IF(MOD(K31, $D$31) = 0, K31/ $D$31, IF(INT(K31 / $D$31) = 0, MOD(K31, $D$31) & " P", INT(K31 / $D$31) & " + " & MOD(K31, $D$31) & " P"))) | L32: =IF(L31=0, "", IF(MOD(L31, $D$31) = 0, L31/ $D$31, IF(INT(L31 / $D$31) = 0, MOD(L31, $D$31) & " P", INT(L31 / $D$31) & " + " & MOD(L31, $D$31) & " P"))) | ... P32: =IF(P31=0, "", IF(MOD(P31, $D$31) = 0, P31/ $D$31, IF(INT(P31 / $D$31) = 0, MOD(P31, $D$31) & " P", INT(P31 / $D$31) & " + " & MOD(P31, $D$31) & " P"))) | AK32: 33
B33: 10 | C33: องุ่นไชน์มัสแคท 300 กรัมx 15 P | D33: 15 | Q33: =SUM(E33:P33) -> 0 | R33: ='บางบัวทอง-รถ'!C19 -> 0 | S33: 160 | T33: =SUM(S33-Q33) -> 160 | V33: =SUM(E33,F33) -> 0 | W33: =SUM(G33,H33) -> 0 | X33: =SUM(I33,J33) -> 0 | Y33: =SUM(K33,L33,M33,) -> 0 | Z33: =SUM(N33,O33,P33) -> 0 | AK33: =IF(AK32=0, "", IF(MOD(AK32, $D$31) = 0, AK32/ $D$31, IF(INT(AK32 / $D$31) = 0, MOD(AK32, $D$31) & " P", INT(AK32 / $D$31) & " + " & MOD(AK32, $D$31) & " P"))) -> 1 + 13 P
C34: Shine Muscat 300g ( 88593880000189 ) | E34: =IF(E33=0, "", IF(MOD(E33, $D$33) = 0, E33/ $D$33, IF(INT(E33 / $D$33) = 0, MOD(E33, $D$33) & " P", INT(E33 / $D$33) & " + " & MOD(E33, $D$33) & " P"))) | F34: =IF(F33=0, "", IF(MOD(F33, $D$33) = 0, F33/ $D$33, IF(INT(F33 / $D$33) = 0, MOD(F33, $D$33) & " P", INT(F33 / $D$33) & " + " & MOD(F33, $D$33) & " P"))) | G34: =IF(G33=0, "", IF(MOD(G33, $D$33) = 0, G33/ $D$33, IF(INT(G33 / $D$33) = 0, MOD(G33, $D$33) & " P", INT(G33 / $D$33) & " + " & MOD(G33, $D$33) & " P"))) | H34: =IF(H33=0, "", IF(MOD(H33, $D$33) = 0, H33/ $D$33, IF(INT(H33 / $D$33) = 0, MOD(H33, $D$33) & " P", INT(H33 / $D$33) & " + " & MOD(H33, $D$33) & " P"))) | I34: =IF(I33=0, "", IF(MOD(I33, $D$33) = 0, I33/ $D$33, IF(INT(I33 / $D$33) = 0, MOD(I33, $D$33) & " P", INT(I33 / $D$33) & " + " & MOD(I33, $D$33) & " P"))) | J34: =IF(J33=0, "", IF(MOD(J33, $D$33) = 0, J33/ $D$33, IF(INT(J33 / $D$33) = 0, MOD(J33, $D$33) & " P", INT(J33 / $D$33) & " + " & MOD(J33, $D$33) & " P"))) | K34: =IF(K33=0, "", IF(MOD(K33, $D$33) = 0, K33/ $D$33, IF(INT(K33 / $D$33) = 0, MOD(K33, $D$33) & " P", INT(K33 / $D$33) & " + " & MOD(K33, $D$33) & " P"))) | L34: =IF(L33=0, "", IF(MOD(L33, $D$33) = 0, L33/ $D$33, IF(INT(L33 / $D$33) = 0, MOD(L33, $D$33) & " P", INT(L33 / $D$33) & " + " & MOD(L33, $D$33) & " P"))) | ... P34: =IF(P33=0, "", IF(MOD(P33, $D$33) = 0, P33/ $D$33, IF(INT(P33 / $D$33) = 0, MOD(P33, $D$33) & " P", INT(P33 / $D$33) & " + " & MOD(P33, $D$33) & " P"))) | AK34: 33
B35: 11 | C35: แอปเปิ้ลแดงวอชิงตันลูกเดี่ยว x 45 P | D35: 45 | Q35: =SUM(E35:P35) -> 0 | R35: ='บางบัวทอง-รถ'!C20 -> 0 | S35: 50 | T35: =SUM(S35-Q35) -> 50 | V35: =SUM(E35,F35) -> 0 | W35: =SUM(G35,H35) -> 0 | X35: =SUM(I35,J35) -> 0 | Y35: =SUM(K35,L35,M35,) -> 0 | Z35: =SUM(N35,O35,P35) -> 0 | AK35: =IF(AK30=0, "", IF(MOD(AK30, $D$37) = 0, AK30/ $D$37, IF(INT(AK30 / $D$37) = 0, MOD(AK30, $D$37) & " P", INT(AK30 / $D$37) & " + " & MOD(AK30, $D$37) & " P"))) -> 2 + 4 P
C36: Washington ( 8859388000759 ) | E36: =IF(E35=0, "", IF(MOD(E35, $D$35) = 0, E35/ $D$35, IF(INT(E35 / $D$35) = 0, MOD(E35, $D$35) & " P", INT(E35 / $D$35) & " + " & MOD(E35, $D$35) & " P"))) | F36: =IF(F35=0, "", IF(MOD(F35, $D$35) = 0, F35/ $D$35, IF(INT(F35 / $D$35) = 0, MOD(F35, $D$35) & " P", INT(F35 / $D$35) & " + " & MOD(F35, $D$35) & " P"))) | G36: =IF(G35=0, "", IF(MOD(G35, $D$35) = 0, G35/ $D$35, IF(INT(G35 / $D$35) = 0, MOD(G35, $D$35) & " P", INT(G35 / $D$35) & " + " & MOD(G35, $D$35) & " P"))) | H36: =IF(H35=0, "", IF(MOD(H35, $D$35) = 0, H35/ $D$35, IF(INT(H35 / $D$35) = 0, MOD(H35, $D$35) & " P", INT(H35 / $D$35) & " + " & MOD(H35, $D$35) & " P"))) | I36: =IF(I35=0, "", IF(MOD(I35, $D$35) = 0, I35/ $D$35, IF(INT(I35 / $D$35) = 0, MOD(I35, $D$35) & " P", INT(I35 / $D$35) & " + " & MOD(I35, $D$35) & " P"))) | J36: =IF(J35=0, "", IF(MOD(J35, $D$35) = 0, J35/ $D$35, IF(INT(J35 / $D$35) = 0, MOD(J35, $D$35) & " P", INT(J35 / $D$35) & " + " & MOD(J35, $D$35) & " P"))) | K36: =IF(K35=0, "", IF(MOD(K35, $D$35) = 0, K35/ $D$35, IF(INT(K35 / $D$35) = 0, MOD(K35, $D$35) & " P", INT(K35 / $D$35) & " + " & MOD(K35, $D$35) & " P"))) | L36: =IF(L35=0, "", IF(MOD(L35, $D$35) = 0, L35/ $D$35, IF(INT(L35 / $D$35) = 0, MOD(L35, $D$35) & " P", INT(L35 / $D$35) & " + " & MOD(L35, $D$35) & " P"))) | ... P36: =IF(P35=0, "", IF(MOD(P35, $D$35) = 0, P35/ $D$35, IF(INT(P35 / $D$35) = 0, MOD(P35, $D$35) & " P", INT(P35 / $D$35) & " + " & MOD(P35, $D$35) & " P")))
B37: 12 | C37: องุ่นสวีทแซฟไฟร์300 กรัม x 15 P | D37: 15 | Q37: =SUM(E37:P37) -> 0 | R37: ='บางบัวทอง-รถ'!C21 -> 0 | S37: 190 | T37: =SUM(S37-Q37) -> 190 | V37: =SUM(E37,F37) -> 0 | W37: =SUM(G37,H37) -> 0 | X37: =SUM(I37,J37) -> 0 | Y37: =SUM(K37,L37,M37,) -> 0 | Z37: =SUM(N37,O37,P37) -> 0 | AK37: =IF(AK32=0, "", IF(MOD(AK32, $D$37) = 0, AK32/ $D$37, IF(INT(AK32 / $D$37) = 0, MOD(AK32, $D$37) & " P", INT(AK32 / $D$37) & " + " & MOD(AK32, $D$37) & " P"))) -> 2 + 3 P
C38: Sweet Sapphire ( 8859388000223 ) | E38: =IF(E37=0, "", IF(MOD(E37, $D$37) = 0, E37/ $D$37, IF(INT(E37 / $D$37) = 0, MOD(E37, $D$37) & " P", INT(E37 / $D$37) & " + " & MOD(E37, $D$37) & " P"))) | F38: =IF(F37=0, "", IF(MOD(F37, $D$37) = 0, F37/ $D$37, IF(INT(F37 / $D$37) = 0, MOD(F37, $D$37) & " P", INT(F37 / $D$37) & " + " & MOD(F37, $D$37) & " P"))) | G38: =IF(G37=0, "", IF(MOD(G37, $D$37) = 0, G37/ $D$37, IF(INT(G37 / $D$37) = 0, MOD(G37, $D$37) & " P", INT(G37 / $D$37) & " + " & MOD(G37, $D$37) & " P"))) | H38: =IF(H37=0, "", IF(MOD(H37, $D$37) = 0, H37/ $D$37, IF(INT(H37 / $D$37) = 0, MOD(H37, $D$37) & " P", INT(H37 / $D$37) & " + " & MOD(H37, $D$37) & " P"))) | I38: =IF(I37=0, "", IF(MOD(I37, $D$37) = 0, I37/ $D$37, IF(INT(I37 / $D$37) = 0, MOD(I37, $D$37) & " P", INT(I37 / $D$37) & " + " & MOD(I37, $D$37) & " P"))) | J38: =IF(J37=0, "", IF(MOD(J37, $D$37) = 0, J37/ $D$37, IF(INT(J37 / $D$37) = 0, MOD(J37, $D$37) & " P", INT(J37 / $D$37) & " + " & MOD(J37, $D$37) & " P"))) | K38: =IF(K37=0, "", IF(MOD(K37, $D$37) = 0, K37/ $D$37, IF(INT(K37 / $D$37) = 0, MOD(K37, $D$37) & " P", INT(K37 / $D$37) & " + " & MOD(K37, $D$37) & " P"))) | L38: =IF(L37=0, "", IF(MOD(L37, $D$37) = 0, L37/ $D$37, IF(INT(L37 / $D$37) = 0, MOD(L37, $D$37) & " P", INT(L37 / $D$37) & " + " & MOD(L37, $D$37) & " P"))) | ... P38: =IF(P37=0, "", IF(MOD(P37, $D$37) = 0, P37/ $D$37, IF(INT(P37 / $D$37) = 0, MOD(P37, $D$37) & " P", INT(P37 / $D$37) & " + " & MOD(P37, $D$37) & " P")))
B39: 13 | C39: องุ่นเคียวโฮ 300 กรัม x 15 P | D39: 15 | Q39: =SUM(E39:P39) -> 0 | R39: ='บางบัวทอง-รถ'!C22 -> 0 | S39: 100 | T39: =SUM(S39-Q39) -> 100 | V39: =SUM(E39,F39) -> 0 | W39: =SUM(G39,H39) -> 0 | X39: =SUM(I39,J39) -> 0 | Y39: =SUM(K39,L39,M39,) -> 0 | Z39: =SUM(N39,O39,P39) -> 0 | AK39: =IF(AK36=0, "", IF(MOD(AK36, $D$37) = 0, AK36/ $D$37, IF(INT(AK36 / $D$37) = 0, MOD(AK36, $D$37) & " P", INT(AK36 / $D$37) & " + " & MOD(AK36, $D$37) & " P")))
C40: Kyoho Grape (888593880000063 ) | E40: =IF(E39=0, "", IF(MOD(E39, $D$39) = 0, E39/ $D$39, IF(INT(E39 / $D$39) = 0, MOD(E39, $D$39) & " P", INT(E39 / $D$39) & " + " & MOD(E39, $D$39) & " P"))) | F40: =IF(F39=0, "", IF(MOD(F39, $D$39) = 0, F39/ $D$39, IF(INT(F39 / $D$39) = 0, MOD(F39, $D$39) & " P", INT(F39 / $D$39) & " + " & MOD(F39, $D$39) & " P"))) | G40: =IF(G39=0, "", IF(MOD(G39, $D$39) = 0, G39/ $D$39, IF(INT(G39 / $D$39) = 0, MOD(G39, $D$39) & " P", INT(G39 / $D$39) & " + " & MOD(G39, $D$39) & " P"))) | H40: =IF(H39=0, "", IF(MOD(H39, $D$39) = 0, H39/ $D$39, IF(INT(H39 / $D$39) = 0, MOD(H39, $D$39) & " P", INT(H39 / $D$39) & " + " & MOD(H39, $D$39) & " P"))) | I40: =IF(I39=0, "", IF(MOD(I39, $D$39) = 0, I39/ $D$39, IF(INT(I39 / $D$39) = 0, MOD(I39, $D$39) & " P", INT(I39 / $D$39) & " + " & MOD(I39, $D$39) & " P"))) | J40: =IF(J39=0, "", IF(MOD(J39, $D$39) = 0, J39/ $D$39, IF(INT(J39 / $D$39) = 0, MOD(J39, $D$39) & " P", INT(J39 / $D$39) & " + " & MOD(J39, $D$39) & " P"))) | K40: =IF(K39=0, "", IF(MOD(K39, $D$39) = 0, K39/ $D$39, IF(INT(K39 / $D$39) = 0, MOD(K39, $D$39) & " P", INT(K39 / $D$39) & " + " & MOD(K39, $D$39) & " P"))) | L40: =IF(L39=0, "", IF(MOD(L39, $D$39) = 0, L39/ $D$39, IF(INT(L39 / $D$39) = 0, MOD(L39, $D$39) & " P", INT(L39 / $D$39) & " + " & MOD(L39, $D$39) & " P"))) | ... P40: =IF(P39=0, "", IF(MOD(P39, $D$39) = 0, P39/ $D$39, IF(INT(P39 / $D$39) = 0, MOD(P39, $D$39) & " P", INT(P39 / $D$39) & " + " & MOD(P39, $D$39) & " P")))
B41: 14 | C41: ลูกไหนจิ๋ว 200 g. x 27 p | D41: 27 | Q41: =SUM(E41:P41) -> 0 | R41: ='บางบัวทอง-รถ'!C23 -> 0 | S41: 812 | T41: =SUM(S41-Q41) -> 812 | V41: =SUM(E41,F41) -> 0 | W41: =SUM(G41,H41) -> 0 | X41: =SUM(I41,J41) -> 0 | Y41: =SUM(K41,L41,M41,) -> 0 | Z41: =SUM(N41,O41,P41) -> 0 | AK41: =IF(AK38=0, "", IF(MOD(AK38, $D$37) = 0, AK38/ $D$37, IF(INT(AK38 / $D$37) = 0, MOD(AK38, $D$37) & " P", INT(AK38 / $D$37) & " + " & MOD(AK38, $D$37) & " P")))
C42: Plum 200 g. ( 8859388001091 ) | E42: =IF(E41=0, "", IF(MOD(E41, $D$41) = 0, E41/ $D$41, IF(INT(E41 / $D$41) = 0, MOD(E41, $D$41) & " P", INT(E41 / $D$41) & " + " & MOD(E41, $D$41) & " P"))) | F42: =IF(F41=0, "", IF(MOD(F41, $D$41) = 0, F41/ $D$41, IF(INT(F41 / $D$41) = 0, MOD(F41, $D$41) & " P", INT(F41 / $D$41) & " + " & MOD(F41, $D$41) & " P"))) | G42: =IF(G41=0, "", IF(MOD(G41, $D$41) = 0, G41/ $D$41, IF(INT(G41 / $D$41) = 0, MOD(G41, $D$41) & " P", INT(G41 / $D$41) & " + " & MOD(G41, $D$41) & " P"))) | H42: =IF(H41=0, "", IF(MOD(H41, $D$41) = 0, H41/ $D$41, IF(INT(H41 / $D$41) = 0, MOD(H41, $D$41) & " P", INT(H41 / $D$41) & " + " & MOD(H41, $D$41) & " P"))) | I42: =IF(I41=0, "", IF(MOD(I41, $D$41) = 0, I41/ $D$41, IF(INT(I41 / $D$41) = 0, MOD(I41, $D$41) & " P", INT(I41 / $D$41) & " + " & MOD(I41, $D$41) & " P"))) | J42: =IF(J41=0, "", IF(MOD(J41, $D$41) = 0, J41/ $D$41, IF(INT(J41 / $D$41) = 0, MOD(J41, $D$41) & " P", INT(J41 / $D$41) & " + " & MOD(J41, $D$41) & " P"))) | K42: =IF(K41=0, "", IF(MOD(K41, $D$41) = 0, K41/ $D$41, IF(INT(K41 / $D$41) = 0, MOD(K41, $D$41) & " P", INT(K41 / $D$41) & " + " & MOD(K41, $D$41) & " P"))) | L42: =IF(L41=0, "", IF(MOD(L41, $D$41) = 0, L41/ $D$41, IF(INT(L41 / $D$41) = 0, MOD(L41, $D$41) & " P", INT(L41 / $D$41) & " + " & MOD(L41, $D$41) & " P"))) | ... P42: =IF(P41=0, "", IF(MOD(P41, $D$41) = 0, P41/ $D$41, IF(INT(P41 / $D$41) = 0, MOD(P41, $D$41) & " P", INT(P41 / $D$41) & " + " & MOD(P41, $D$41) & " P")))
B43: 15 | C43: องุ่นแดงไร้เมล็ด 300 g. x 20 p | D43: 20 | Q43: =SUM(E43:P43) -> 0 | R43: ='บางบัวทอง-รถ'!C24 -> 0 | S43: 400 | T43: =SUM(S43-Q43) -> 400 | V43: =SUM(E43,F43) -> 0 | W43: =SUM(G43,H43) -> 0 | X43: =SUM(I43,J43) -> 0 | Y43: =SUM(K43,L43,M43,) -> 0 | Z43: =SUM(N43,O43,P43) -> 0 | AK43: =IF(AK36=0, "", IF(MOD(AK36, $D$37) = 0, AK36/ $D$37, IF(INT(AK36 / $D$37) = 0, MOD(AK36, $D$37) & " P", INT(AK36 / $D$37) & " + " & MOD(AK36, $D$37) & " P")))
C44: Red Seedless 300 g.( 8859388001084 ) | E44: =IF(E43=0, "", IF(MOD(E43, $D$43) = 0, E43/ $D$43, IF(INT(E43 / $D$43) = 0, MOD(E43, $D$43) & " P", INT(E43 / $D$43) & " + " & MOD(E43, $D$43) & " P"))) | F44: =IF(F43=0, "", IF(MOD(F43, $D$43) = 0, F43/ $D$43, IF(INT(F43 / $D$43) = 0, MOD(F43, $D$43) & " P", INT(F43 / $D$43) & " + " & MOD(F43, $D$43) & " P"))) | G44: =IF(G43=0, "", IF(MOD(G43, $D$43) = 0, G43/ $D$43, IF(INT(G43 / $D$43) = 0, MOD(G43, $D$43) & " P", INT(G43 / $D$43) & " + " & MOD(G43, $D$43) & " P"))) | H44: =IF(H43=0, "", IF(MOD(H43, $D$43) = 0, H43/ $D$43, IF(INT(H43 / $D$43) = 0, MOD(H43, $D$43) & " P", INT(H43 / $D$43) & " + " & MOD(H43, $D$43) & " P"))) | I44: =IF(I43=0, "", IF(MOD(I43, $D$43) = 0, I43/ $D$43, IF(INT(I43 / $D$43) = 0, MOD(I43, $D$43) & " P", INT(I43 / $D$43) & " + " & MOD(I43, $D$43) & " P"))) | J44: =IF(J43=0, "", IF(MOD(J43, $D$43) = 0, J43/ $D$43, IF(INT(J43 / $D$43) = 0, MOD(J43, $D$43) & " P", INT(J43 / $D$43) & " + " & MOD(J43, $D$43) & " P"))) | K44: =IF(K43=0, "", IF(MOD(K43, $D$43) = 0, K43/ $D$43, IF(INT(K43 / $D$43) = 0, MOD(K43, $D$43) & " P", INT(K43 / $D$43) & " + " & MOD(K43, $D$43) & " P"))) | L44: =IF(L43=0, "", IF(MOD(L43, $D$43) = 0, L43/ $D$43, IF(INT(L43 / $D$43) = 0, MOD(L43, $D$43) & " P", INT(L43 / $D$43) & " + " & MOD(L43, $D$43) & " P"))) | ... P44: =IF(P43=0, "", IF(MOD(P43, $D$43) = 0, P43/ $D$43, IF(INT(P43 / $D$43) = 0, MOD(P43, $D$43) & " P", INT(P43 / $D$43) & " + " & MOD(P43, $D$43) & " P")))
B45: 16 | C45: เบอร์รี่ดูโอ้ 160 กรัม x 32 P | D45: 32 | Q45: =SUM(E45:P45) -> 0 | R45: ='บางบัวทอง-รถ'!C25 -> 0 | S45: 200 | T45: =SUM(S45-Q45) -> 200 | V45: =SUM(E45,F45) -> 0 | W45: =SUM(G45,H45) -> 0 | X45: =SUM(I45,J45) -> 0 | Y45: =SUM(K45,L45,M45,) -> 0 | Z45: =SUM(N45,O45,P45) -> 0 | AK45: =IF(AK38=0, "", IF(MOD(AK38, $D$37) = 0, AK38/ $D$37, IF(INT(AK38 / $D$37) = 0, MOD(AK38, $D$37) & " P", INT(AK38 / $D$37) & " + " & MOD(AK38, $D$37) & " P")))
C46: Berry Duo 160g. ( 8859388010239 ) | E46: =IF(E45=0, "", IF(MOD(E45, $D$45) = 0, E45/ $D$45, IF(INT(E45 / $D$45) = 0, MOD(E45, $D$45) & " P", INT(E45 / $D$45) & " + " & MOD(E45, $D$45) & " P"))) | F46: =IF(F45=0, "", IF(MOD(F45, $D$45) = 0, F45/ $D$45, IF(INT(F45 / $D$45) = 0, MOD(F45, $D$45) & " P", INT(F45 / $D$45) & " + " & MOD(F45, $D$45) & " P"))) | G46: =IF(G45=0, "", IF(MOD(G45, $D$45) = 0, G45/ $D$45, IF(INT(G45 / $D$45) = 0, MOD(G45, $D$45) & " P", INT(G45 / $D$45) & " + " & MOD(G45, $D$45) & " P"))) | H46: =IF(H45=0, "", IF(MOD(H45, $D$45) = 0, H45/ $D$45, IF(INT(H45 / $D$45) = 0, MOD(H45, $D$45) & " P", INT(H45 / $D$45) & " + " & MOD(H45, $D$45) & " P"))) | I46: =IF(I45=0, "", IF(MOD(I45, $D$45) = 0, I45/ $D$45, IF(INT(I45 / $D$45) = 0, MOD(I45, $D$45) & " P", INT(I45 / $D$45) & " + " & MOD(I45, $D$45) & " P"))) | J46: =IF(J45=0, "", IF(MOD(J45, $D$45) = 0, J45/ $D$45, IF(INT(J45 / $D$45) = 0, MOD(J45, $D$45) & " P", INT(J45 / $D$45) & " + " & MOD(J45, $D$45) & " P"))) | K46: =IF(K45=0, "", IF(MOD(K45, $D$45) = 0, K45/ $D$45, IF(INT(K45 / $D$45) = 0, MOD(K45, $D$45) & " P", INT(K45 / $D$45) & " + " & MOD(K45, $D$45) & " P"))) | L46: =IF(L45=0, "", IF(MOD(L45, $D$45) = 0, L45/ $D$45, IF(INT(L45 / $D$45) = 0, MOD(L45, $D$45) & " P", INT(L45 / $D$45) & " + " & MOD(L45, $D$45) & " P"))) | ... P46: =IF(P45=0, "", IF(MOD(P45, $D$45) = 0, P45/ $D$45, IF(INT(P45 / $D$45) = 0, MOD(P45, $D$45) & " P", INT(P45 / $D$45) & " + " & MOD(P45, $D$45) & " P")))
B47: 17 | C47: สาลี่ทอง แพ็ก 2 ผล (400g.) x 15 P | D47: 15 | Q47: =SUM(E47:P47) -> 0 | R47: ='บางบัวทอง-รถ'!C26 -> 0 | S47: 110 | T47: =SUM(S47-Q47) -> 110 | V47: =SUM(E47,F47) -> 0 | W47: =SUM(G47,H47) -> 0 | X47: =SUM(I47,J47) -> 0 | Y47: =SUM(K47,L47,M47,) -> 0 | Z47: =SUM(N47,O47,P47) -> 0 | AK47: =IF(AK38=0, "", IF(MOD(AK38, $D$37) = 0, AK38/ $D$37, IF(INT(AK38 / $D$37) = 0, MOD(AK38, $D$37) & " P", INT(AK38 / $D$37) & " + " & MOD(AK38, $D$37) & " P")))
C48: Pear 400g (8859388010284 ) | E48: =IF(E47=0, "", IF(MOD(E47, $D$47) = 0, E47/ $D$47, IF(INT(E47 / $D$47) = 0, MOD(E47, $D$47) & " P", INT(E47 / $D$47) & " + " & MOD(E47, $D$47) & " P"))) | F48: =IF(F47=0, "", IF(MOD(F47, $D$47) = 0, F47/ $D$47, IF(INT(F47 / $D$47) = 0, MOD(F47, $D$47) & " P", INT(F47 / $D$47) & " + " & MOD(F47, $D$47) & " P"))) | G48: =IF(G47=0, "", IF(MOD(G47, $D$47) = 0, G47/ $D$47, IF(INT(G47 / $D$47) = 0, MOD(G47, $D$47) & " P", INT(G47 / $D$47) & " + " & MOD(G47, $D$47) & " P"))) | H48: =IF(H47=0, "", IF(MOD(H47, $D$47) = 0, H47/ $D$47, IF(INT(H47 / $D$47) = 0, MOD(H47, $D$47) & " P", INT(H47 / $D$47) & " + " & MOD(H47, $D$47) & " P"))) | I48: =IF(I47=0, "", IF(MOD(I47, $D$47) = 0, I47/ $D$47, IF(INT(I47 / $D$47) = 0, MOD(I47, $D$47) & " P", INT(I47 / $D$47) & " + " & MOD(I47, $D$47) & " P"))) | J48: =IF(J47=0, "", IF(MOD(J47, $D$47) = 0, J47/ $D$47, IF(INT(J47 / $D$47) = 0, MOD(J47, $D$47) & " P", INT(J47 / $D$47) & " + " & MOD(J47, $D$47) & " P"))) | K48: =IF(K47=0, "", IF(MOD(K47, $D$47) = 0, K47/ $D$47, IF(INT(K47 / $D$47) = 0, MOD(K47, $D$47) & " P", INT(K47 / $D$47) & " + " & MOD(K47, $D$47) & " P"))) | L48: =IF(L47=0, "", IF(MOD(L47, $D$47) = 0, L47/ $D$47, IF(INT(L47 / $D$47) = 0, MOD(L47, $D$47) & " P", INT(L47 / $D$47) & " + " & MOD(L47, $D$47) & " P"))) | ... P48: =IF(P47=0, "", IF(MOD(P47, $D$47) = 0, P47/ $D$47, IF(INT(P47 / $D$47) = 0, MOD(P47, $D$47) & " P", INT(P47 / $D$47) & " + " & MOD(P47, $D$47) & " P")))
B49: 18 | C49: สาลี่ทอง แพ็ก 4 ผล (800g.) x 8 P | D49: 8 | Q49: =SUM(E49:P49) -> 0 | R49: ='บางบัวทอง-รถ'!C27 -> 0 | S49: 50 | T49: =SUM(S49-Q49) -> 50 | V49: =SUM(E49,F49) -> 0 | W49: =SUM(G49,H49) -> 0 | X49: =SUM(I49,J49) -> 0 | Y49: =SUM(K49,L49,M49,) -> 0 | Z49: =SUM(N49,O49,P49) -> 0 | AK49: =IF(AK40=0, "", IF(MOD(AK40, $D$37) = 0, AK40/ $D$37, IF(INT(AK40 / $D$37) = 0, MOD(AK40, $D$37) & " P", INT(AK40 / $D$37) & " + " & MOD(AK40, $D$37) & " P")))
...

Sheet บางบัวทอง-ผลิต (2)
B10: ผู้ส่ง : 7-11 บางบัวทอง 4ล้อจัมโบ้ | E10: วันที่ 03/08/69 PO.03/08/69
B12: เซเว่น-บางบัวทอง | D12: บรรจุ/ตก. | E12: 14.00 น. | G12: 13.00 น. | I12: 11.00 น | K12: 09.00 น | N12: 08.00 น. | Q12: ยอดรวม | S12: ยอดเผื่อ | T12: คงเหลือ | V12: KK | W12: SRR | X12: CMI | Y12: HKT | Z12: HDY
E13: ขอนแก่น KK | G13: สุราษร์ธานี ST | I13: เชียงใหม่ CM | K13: ภูเก็ต PK | N13: หาดใหญ่ HY
E14: PO1 | F14: PO 2 | G14: PO1 | H14: PO 2 | I14: PO1 | J14: PO 2 | K14: PO1 | L14: PO 2 | M14: PO3 | N14: PO1 | O14: PO2 | P14: PO3 | Q14: รวมแพค | R14: ตะกร้า | AK14: 32
B15: 1 | C15: องุ่นดำไร้เมล็ด 150 กรัม x36P | D15: 36 | E15: 18 | F15: 16 | G15: 52 | H15: 55 | Q15: =SUM(E15:P15) -> 141 | R15: 6 | S15: 350 | T15: =SUM(S15-Q15) -> 209 | V15: =SUM(E15,F15) -> 34 | W15: =SUM(G15,H15) -> 107 | X15: =SUM(I15,J15) -> 0 | Y15: =SUM(K15,L15,M15,) -> 0 | Z15: =SUM(N15,O15,P15) -> 0 | AK15: =IF(AK14=0, "", IF(MOD(AK14, $D$15) = 0, AK14 / $D$15, IF(INT(AK14 / $D$15) = 0, MOD(AK14, $D$15) & " P", INT(AK14 / $D$15) & " + " & MOD(AK14, $D$15) & " P"))) -> 32 P
C16: BlackGrapesSeedless150 g. (8859388000025 ) | E16: =IF(E15=0, "", IF(MOD(E15, $D$15) = 0, E15 / $D$15, IF(INT(E15 / $D$15) = 0, MOD(E15, $D$15) & " P", INT(E15 / $D$15) & " + " & MOD(E15, $D$15) & " P"))) -> 18 P | F16: =IF(F15=0, "", IF(MOD(F15, $D$15) = 0, F15 / $D$15, IF(INT(F15 / $D$15) = 0, MOD(F15, $D$15) & " P", INT(F15 / $D$15) & " + " & MOD(F15, $D$15) & " P"))) -> 16 P | G16: =IF(G15=0, "", IF(MOD(G15, $D$15) = 0, G15 / $D$15, IF(INT(G15 / $D$15) = 0, MOD(G15, $D$15) & " P", INT(G15 / $D$15) & " + " & MOD(G15, $D$15) & " P"))) -> 1 + 16 P | H16: =IF(H15=0, "", IF(MOD(H15, $D$15) = 0, H15 / $D$15, IF(INT(H15 / $D$15) = 0, MOD(H15, $D$15) & " P", INT(H15 / $D$15) & " + " & MOD(H15, $D$15) & " P"))) -> 1 + 19 P | I16: =IF(I15=0, "", IF(MOD(I15, $D$15) = 0, I15 / $D$15, IF(INT(I15 / $D$15) = 0, MOD(I15, $D$15) & " P", INT(I15 / $D$15) & " + " & MOD(I15, $D$15) & " P"))) | J16: =IF(J15=0, "", IF(MOD(J15, $D$15) = 0, J15 / $D$15, IF(INT(J15 / $D$15) = 0, MOD(J15, $D$15) & " P", INT(J15 / $D$15) & " + " & MOD(J15, $D$15) & " P"))) | K16: =IF(K15=0, "", IF(MOD(K15, $D$15) = 0, K15 / $D$15, IF(INT(K15 / $D$15) = 0, MOD(K15, $D$15) & " P", INT(K15 / $D$15) & " + " & MOD(K15, $D$15) & " P"))) | L16: =IF(L15=0, "", IF(MOD(L15, $D$15) = 0, L15 / $D$15, IF(INT(L15 / $D$15) = 0, MOD(L15, $D$15) & " P", INT(L15 / $D$15) & " + " & MOD(L15, $D$15) & " P"))) | ... P16: =IF(P15=0, "", IF(MOD(P15, $D$15) = 0, P15 / $D$15, IF(INT(P15 / $D$15) = 0, MOD(P15, $D$15) & " P", INT(P15 / $D$15) & " + " & MOD(P15, $D$15) & " P"))) | AK16: 129
B17: 2 | C17: องุ่นแดงนอกมีเมล็ด 200 กรัม x 32 P | D17: 32 | E17: 35 | F17: 34 | G17: 139 | H17: 90 | Q17: =SUM(E17:P17) -> 298 | R17: 12 | S17: 790 | T17: =SUM(S17-Q17) -> 492 | V17: =SUM(E17,F17) -> 69 | W17: =SUM(G17,H17) -> 229 | X17: =SUM(I17,J17) -> 0 | Y17: =SUM(K17,L17,M17,) -> 0 | Z17: =SUM(N17,O17,P17) -> 0 | AK17: =IF(AK16=0, "", IF(MOD(AK16, $D$17) = 0, AK16 / $D$17, IF(INT(AK16 / $D$17) = 0, MOD(AK16, $D$17) & " P", INT(AK16 / $D$17) & " + " & MOD(AK16, $D$17) & " P"))) -> 4 + 1 P
C18: Red Seed 200 g. ( 8859388000100 ) | E18: =IF(E17=0, "", IF(MOD(E17, $D$17) = 0, E17 / $D$17, IF(INT(E17 / $D$17) = 0, MOD(E17, $D$17) & " P", INT(E17 / $D$17) & " + " & MOD(E17, $D$17) & " P"))) -> 1 + 3 P | F18: =IF(F17=0, "", IF(MOD(F17, $D$17) = 0, F17 / $D$17, IF(INT(F17 / $D$17) = 0, MOD(F17, $D$17) & " P", INT(F17 / $D$17) & " + " & MOD(F17, $D$17) & " P"))) -> 1 + 2 P | G18: =IF(G17=0, "", IF(MOD(G17, $D$17) = 0, G17 / $D$17, IF(INT(G17 / $D$17) = 0, MOD(G17, $D$17) & " P", INT(G17 / $D$17) & " + " & MOD(G17, $D$17) & " P"))) -> 4 + 11 P | H18: =IF(H17=0, "", IF(MOD(H17, $D$17) = 0, H17 / $D$17, IF(INT(H17 / $D$17) = 0, MOD(H17, $D$17) & " P", INT(H17 / $D$17) & " + " & MOD(H17, $D$17) & " P"))) -> 2 + 26 P | I18: =IF(I17=0, "", IF(MOD(I17, $D$17) = 0, I17 / $D$17, IF(INT(I17 / $D$17) = 0, MOD(I17, $D$17) & " P", INT(I17 / $D$17) & " + " & MOD(I17, $D$17) & " P"))) | J18: =IF(J17=0, "", IF(MOD(J17, $D$17) = 0, J17 / $D$17, IF(INT(J17 / $D$17) = 0, MOD(J17, $D$17) & " P", INT(J17 / $D$17) & " + " & MOD(J17, $D$17) & " P"))) | K18: =IF(K17=0, "", IF(MOD(K17, $D$17) = 0, K17 / $D$17, IF(INT(K17 / $D$17) = 0, MOD(K17, $D$17) & " P", INT(K17 / $D$17) & " + " & MOD(K17, $D$17) & " P"))) | L18: =IF(L17=0, "", IF(MOD(L17, $D$17) = 0, L17 / $D$17, IF(INT(L17 / $D$17) = 0, MOD(L17, $D$17) & " P", INT(L17 / $D$17) & " + " & MOD(L17, $D$17) & " P"))) | ... P18: =IF(P17=0, "", IF(MOD(P17, $D$17) = 0, P17 / $D$17, IF(INT(P17 / $D$17) = 0, MOD(P17, $D$17) & " P", INT(P17 / $D$17) & " + " & MOD(P17, $D$17) & " P"))) | AK18: 54
B19: 3 | C19: เชอร์รี่สดนำเข้า 150 กรัม (USA.) x36 P | D19: 36 | E19: 3 | F19: 8 | G19: 42 | H19: 20 | Q19: =SUM(E19:P19) -> 73 | R19: 5 | S19: 240 | T19: =SUM(S19-Q19) -> 167 | V19: =SUM(E19,F19) -> 11 | W19: =SUM(G19,H19) -> 62 | X19: =SUM(I19,J19) -> 0 | Y19: =SUM(K19,L19,M19,) -> 0 | Z19: =SUM(N19,O19,P19) -> 0 | AK19: =IF(AK18=0, "", IF(MOD(AK18, $D$19) = 0, AK18/ $D$19, IF(INT(AK18 / $D$19) = 0, MOD(AK18, $D$19) & " P", INT(AK18 / $D$19) & " + " & MOD(AK18, $D$19) & " P"))) -> 1 + 18 P
C20: Cherry150g (8859388008885 ) | E20: =IF(E19=0, "", IF(MOD(E19, $D$19) = 0, E19/ $D$19, IF(INT(E19 / $D$19) = 0, MOD(E19, $D$19) & " P", INT(E19 / $D$19) & " + " & MOD(E19, $D$19) & " P"))) -> 3 P | F20: =IF(F19=0, "", IF(MOD(F19, $D$19) = 0, F19/ $D$19, IF(INT(F19 / $D$19) = 0, MOD(F19, $D$19) & " P", INT(F19 / $D$19) & " + " & MOD(F19, $D$19) & " P"))) -> 8 P | G20: =IF(G19=0, "", IF(MOD(G19, $D$19) = 0, G19/ $D$19, IF(INT(G19 / $D$19) = 0, MOD(G19, $D$19) & " P", INT(G19 / $D$19) & " + " & MOD(G19, $D$19) & " P"))) -> 1 + 6 P | H20: =IF(H19=0, "", IF(MOD(H19, $D$19) = 0, H19/ $D$19, IF(INT(H19 / $D$19) = 0, MOD(H19, $D$19) & " P", INT(H19 / $D$19) & " + " & MOD(H19, $D$19) & " P"))) -> 20 P | I20: =IF(I19=0, "", IF(MOD(I19, $D$19) = 0, I19/ $D$19, IF(INT(I19 / $D$19) = 0, MOD(I19, $D$19) & " P", INT(I19 / $D$19) & " + " & MOD(I19, $D$19) & " P"))) | J20: =IF(J19=0, "", IF(MOD(J19, $D$19) = 0, J19/ $D$19, IF(INT(J19 / $D$19) = 0, MOD(J19, $D$19) & " P", INT(J19 / $D$19) & " + " & MOD(J19, $D$19) & " P"))) | K20: =IF(K19=0, "", IF(MOD(K19, $D$19) = 0, K19/ $D$19, IF(INT(K19 / $D$19) = 0, MOD(K19, $D$19) & " P", INT(K19 / $D$19) & " + " & MOD(K19, $D$19) & " P"))) | L20: =IF(L19=0, "", IF(MOD(L19, $D$19) = 0, L19/ $D$19, IF(INT(L19 / $D$19) = 0, MOD(L19, $D$19) & " P", INT(L19 / $D$19) & " + " & MOD(L19, $D$19) & " P"))) | ... P20: =IF(P19=0, "", IF(MOD(P19, $D$19) = 0, P19/ $D$19, IF(INT(P19 / $D$19) = 0, MOD(P19, $D$19) & " P", INT(P19 / $D$19) & " + " & MOD(P19, $D$19) & " P"))) | AK20: 12
B21: 4 | C21: องุ่นแดงไร้เมล็ด150กรัม x 32 Pไข่ปลา | D21: 32 | E21: 131 | F21: 156 | G21: 203 | H21: 209 | Q21: =SUM(E21:P21) -> 699 | R21: 24 | S21: 1272 | T21: =SUM(S21-Q21) -> 573 | V21: =SUM(E21,F21) -> 287 | W21: =SUM(G21,H21) -> 412 | X21: =SUM(I21,J21) -> 0 | Y21: =SUM(K21,L21,M21,) -> 0 | Z21: =SUM(N21,O21,P21) -> 0 | AK21: =IF(AK20=0, "", IF(MOD(AK20, $D$21) = 0, AK20/ $D$21, IF(INT(AK20 / $D$21) = 0, MOD(AK20, $D$21) & " P", INT(AK20 / $D$21) & " + " & MOD(AK20, $D$21) & " P"))) -> 12 P
C22: Red Seedless 150 g. ( 8859388007000 ) | E22: =IF(E21=0, "", IF(MOD(E21, $D$21) = 0, E21/ $D$21, IF(INT(E21 / $D$21) = 0, MOD(E21, $D$21) & " P", INT(E21 / $D$21) & " + " & MOD(E21, $D$21) & " P"))) -> 4 + 3 P | F22: =IF(F21=0, "", IF(MOD(F21, $D$21) = 0, F21/ $D$21, IF(INT(F21 / $D$21) = 0, MOD(F21, $D$21) & " P", INT(F21 / $D$21) & " + " & MOD(F21, $D$21) & " P"))) -> 4 + 28 P | G22: =IF(G21=0, "", IF(MOD(G21, $D$21) = 0, G21/ $D$21, IF(INT(G21 / $D$21) = 0, MOD(G21, $D$21) & " P", INT(G21 / $D$21) & " + " & MOD(G21, $D$21) & " P"))) -> 6 + 11 P | H22: =IF(H21=0, "", IF(MOD(H21, $D$21) = 0, H21/ $D$21, IF(INT(H21 / $D$21) = 0, MOD(H21, $D$21) & " P", INT(H21 / $D$21) & " + " & MOD(H21, $D$21) & " P"))) -> 6 + 17 P | I22: =IF(I21=0, "", IF(MOD(I21, $D$21) = 0, I21/ $D$21, IF(INT(I21 / $D$21) = 0, MOD(I21, $D$21) & " P", INT(I21 / $D$21) & " + " & MOD(I21, $D$21) & " P"))) | J22: =IF(J21=0, "", IF(MOD(J21, $D$21) = 0, J21/ $D$21, IF(INT(J21 / $D$21) = 0, MOD(J21, $D$21) & " P", INT(J21 / $D$21) & " + " & MOD(J21, $D$21) & " P"))) | K22: =IF(K21=0, "", IF(MOD(K21, $D$21) = 0, K21/ $D$21, IF(INT(K21 / $D$21) = 0, MOD(K21, $D$21) & " P", INT(K21 / $D$21) & " + " & MOD(K21, $D$21) & " P"))) | L22: =IF(L21=0, "", IF(MOD(L21, $D$21) = 0, L21/ $D$21, IF(INT(L21 / $D$21) = 0, MOD(L21, $D$21) & " P", INT(L21 / $D$21) & " + " & MOD(L21, $D$21) & " P"))) | ... P22: =IF(P21=0, "", IF(MOD(P21, $D$21) = 0, P21/ $D$21, IF(INT(P21 / $D$21) = 0, MOD(P21, $D$21) & " P", INT(P21 / $D$21) & " + " & MOD(P21, $D$21) & " P"))) | AK22: 227
B23: 5 | C23: สตรอเบอร์รี่ 250 กรัม x 18 P | D23: 18 | E23: 3 | F23: 0 | G23: 24 | H23: 7 | Q23: =SUM(E23:P23) -> 34 | R23: 4 | S23: 100 | T23: =SUM(S23-Q23) -> 66 | V23: =SUM(E23,F23) -> 3 | W23: =SUM(G23,H23) -> 31 | X23: =SUM(I23,J23) -> 0 | Y23: =SUM(K23,L23,M23,) -> 0 | Z23: =SUM(N23,O23,P23) -> 0 | AK23: =IF(AK22=0, "", IF(MOD(AK22, $D$23) = 0, AK22/ $D$23, IF(INT(AK22 / $D$23) = 0, MOD(AK22, $D$23) & " P", INT(AK22 / $D$23) & " + " & MOD(AK22, $D$23) & " P"))) -> 12 + 11 P
C24: Straw USA 250 g. ( 2003009710008 ) | E24: =IF(E23=0, "", IF(MOD(E23, $D$23) = 0, E23/ $D$23, IF(INT(E23 / $D$23) = 0, MOD(E23, $D$23) & " P", INT(E23 / $D$23) & " + " & MOD(E23, $D$23) & " P"))) -> 3 P | F24: =IF(F23=0, "", IF(MOD(F23, $D$23) = 0, F23/ $D$23, IF(INT(F23 / $D$23) = 0, MOD(F23, $D$23) & " P", INT(F23 / $D$23) & " + " & MOD(F23, $D$23) & " P"))) | G24: =IF(G23=0, "", IF(MOD(G23, $D$23) = 0, G23/ $D$23, IF(INT(G23 / $D$23) = 0, MOD(G23, $D$23) & " P", INT(G23 / $D$23) & " + " & MOD(G23, $D$23) & " P"))) -> 1 + 6 P | H24: =IF(H23=0, "", IF(MOD(H23, $D$23) = 0, H23/ $D$23, IF(INT(H23 / $D$23) = 0, MOD(H23, $D$23) & " P", INT(H23 / $D$23) & " + " & MOD(H23, $D$23) & " P"))) -> 7 P | I24: =IF(I23=0, "", IF(MOD(I23, $D$23) = 0, I23/ $D$23, IF(INT(I23 / $D$23) = 0, MOD(I23, $D$23) & " P", INT(I23 / $D$23) & " + " & MOD(I23, $D$23) & " P"))) | J24: =IF(J23=0, "", IF(MOD(J23, $D$23) = 0, J23/ $D$23, IF(INT(J23 / $D$23) = 0, MOD(J23, $D$23) & " P", INT(J23 / $D$23) & " + " & MOD(J23, $D$23) & " P"))) | K24: =IF(K23=0, "", IF(MOD(K23, $D$23) = 0, K23/ $D$23, IF(INT(K23 / $D$23) = 0, MOD(K23, $D$23) & " P", INT(K23 / $D$23) & " + " & MOD(K23, $D$23) & " P"))) | L24: =IF(L23=0, "", IF(MOD(L23, $D$23) = 0, L23/ $D$23, IF(INT(L23 / $D$23) = 0, MOD(L23, $D$23) & " P", INT(L23 / $D$23) & " + " & MOD(L23, $D$23) & " P"))) | ... P24: =IF(P23=0, "", IF(MOD(P23, $D$23) = 0, P23/ $D$23, IF(INT(P23 / $D$23) = 0, MOD(P23, $D$23) & " P", INT(P23 / $D$23) & " + " & MOD(P23, $D$23) & " P"))) | AK24: 25
B25: 6 | C25: บลูเบอร์รี่ 125 กรัม x 36 P | D25: 36 | E25: 10 | F25: 8 | G25: 123 | H25: 51 | Q25: =SUM(E25:P25) -> 192 | R25: 8 | S25: 650 | T25: =SUM(S25-Q25) -> 458 | V25: =SUM(E25,F25) -> 18 | W25: =SUM(G25,H25) -> 174 | X25: =SUM(I25,J25) -> 0 | Y25: =SUM(K25,L25,M25,) -> 0 | Z25: =SUM(N25,O25,P25) -> 0 | AK25: =IF(AK24=0, "", IF(MOD(AK24, $D$25) = 0, AK24/ $D$25, IF(INT(AK24 / $D$25) = 0, MOD(AK24, $D$25) & " P", INT(AK24 / $D$25) & " + " & MOD(AK24, $D$25) & " P"))) -> 25 P
C26: Blue 125 g. ( 2003009720007 ) | E26: =IF(E25=0, "", IF(MOD(E25, $D$25) = 0, E25/ $D$25, IF(INT(E25 / $D$25) = 0, MOD(E25, $D$25) & " P", INT(E25 / $D$25) & " + " & MOD(E25, $D$25) & " P"))) -> 10 P | F26: =IF(F25=0, "", IF(MOD(F25, $D$25) = 0, F25/ $D$25, IF(INT(F25 / $D$25) = 0, MOD(F25, $D$25) & " P", INT(F25 / $D$25) & " + " & MOD(F25, $D$25) & " P"))) -> 8 P | G26: =IF(G25=0, "", IF(MOD(G25, $D$25) = 0, G25/ $D$25, IF(INT(G25 / $D$25) = 0, MOD(G25, $D$25) & " P", INT(G25 / $D$25) & " + " & MOD(G25, $D$25) & " P"))) -> 3 + 15 P | H26: =IF(H25=0, "", IF(MOD(H25, $D$25) = 0, H25/ $D$25, IF(INT(H25 / $D$25) = 0, MOD(H25, $D$25) & " P", INT(H25 / $D$25) & " + " & MOD(H25, $D$25) & " P"))) -> 1 + 15 P | I26: =IF(I25=0, "", IF(MOD(I25, $D$25) = 0, I25/ $D$25, IF(INT(I25 / $D$25) = 0, MOD(I25, $D$25) & " P", INT(I25 / $D$25) & " + " & MOD(I25, $D$25) & " P"))) | J26: =IF(J25=0, "", IF(MOD(J25, $D$25) = 0, J25/ $D$25, IF(INT(J25 / $D$25) = 0, MOD(J25, $D$25) & " P", INT(J25 / $D$25) & " + " & MOD(J25, $D$25) & " P"))) | K26: =IF(K25=0, "", IF(MOD(K25, $D$25) = 0, K25/ $D$25, IF(INT(K25 / $D$25) = 0, MOD(K25, $D$25) & " P", INT(K25 / $D$25) & " + " & MOD(K25, $D$25) & " P"))) | L26: =IF(L25=0, "", IF(MOD(L25, $D$25) = 0, L25/ $D$25, IF(INT(L25 / $D$25) = 0, MOD(L25, $D$25) & " P", INT(L25 / $D$25) & " + " & MOD(L25, $D$25) & " P"))) | ... P26: =IF(P25=0, "", IF(MOD(P25, $D$25) = 0, P25/ $D$25, IF(INT(P25 / $D$25) = 0, MOD(P25, $D$25) & " P", INT(P25 / $D$25) & " + " & MOD(P25, $D$25) & " P"))) | AK26: 2
B27: 7 | C27: องุ่นดำไร้เมล็ด 300 กรัม x20P | D27: 20 | E27: 7 | F27: 5 | G27: 22 | H27: 15 | Q27: =SUM(E27:P27) -> 49 | R27: 5 | S27: 140 | T27: =SUM(S27-Q27) -> 91 | V27: =SUM(E27,F27) -> 12 | W27: =SUM(G27,H27) -> 37 | X27: =SUM(I27,J27) -> 0 | Y27: =SUM(K27,L27,M27,) -> 0 | Z27: =SUM(N27,O27,P27) -> 0 | AK27: =IF(AK26=0, "", IF(MOD(AK26, $D$27) = 0, AK26/ $D$27, IF(INT(AK26 / $D$27) = 0, MOD(AK26, $D$27) & " P", INT(AK26 / $D$27) & " + " & MOD(AK26, $D$27) & " P"))) -> 2 P
C28: BlackGrapesSeedless300g. (8859388002562 ) | E28: =IF(E27=0, "", IF(MOD(E27, $D$27) = 0, E27/ $D$27, IF(INT(E27 / $D$27) = 0, MOD(E27, $D$27) & " P", INT(E27 / $D$27) & " + " & MOD(E27, $D$27) & " P"))) -> 7 P | F28: =IF(F27=0, "", IF(MOD(F27, $D$27) = 0, F27/ $D$27, IF(INT(F27 / $D$27) = 0, MOD(F27, $D$27) & " P", INT(F27 / $D$27) & " + " & MOD(F27, $D$27) & " P"))) -> 5 P | G28: =IF(G27=0, "", IF(MOD(G27, $D$27) = 0, G27/ $D$27, IF(INT(G27 / $D$27) = 0, MOD(G27, $D$27) & " P", INT(G27 / $D$27) & " + " & MOD(G27, $D$27) & " P"))) -> 1 + 2 P | H28: =IF(H27=0, "", IF(MOD(H27, $D$27) = 0, H27/ $D$27, IF(INT(H27 / $D$27) = 0, MOD(H27, $D$27) & " P", INT(H27 / $D$27) & " + " & MOD(H27, $D$27) & " P"))) -> 15 P | I28: =IF(I27=0, "", IF(MOD(I27, $D$27) = 0, I27/ $D$27, IF(INT(I27 / $D$27) = 0, MOD(I27, $D$27) & " P", INT(I27 / $D$27) & " + " & MOD(I27, $D$27) & " P"))) | J28: =IF(J27=0, "", IF(MOD(J27, $D$27) = 0, J27/ $D$27, IF(INT(J27 / $D$27) = 0, MOD(J27, $D$27) & " P", INT(J27 / $D$27) & " + " & MOD(J27, $D$27) & " P"))) | K28: =IF(K27=0, "", IF(MOD(K27, $D$27) = 0, K27/ $D$27, IF(INT(K27 / $D$27) = 0, MOD(K27, $D$27) & " P", INT(K27 / $D$27) & " + " & MOD(K27, $D$27) & " P"))) | L28: =IF(L27=0, "", IF(MOD(L27, $D$27) = 0, L27/ $D$27, IF(INT(L27 / $D$27) = 0, MOD(L27, $D$27) & " P", INT(L27 / $D$27) & " + " & MOD(L27, $D$27) & " P"))) | ... P28: =IF(P27=0, "", IF(MOD(P27, $D$27) = 0, P27/ $D$27, IF(INT(P27 / $D$27) = 0, MOD(P27, $D$27) & " P", INT(P27 / $D$27) & " + " & MOD(P27, $D$27) & " P"))) | AK28: 74
B29: 8 | C29: องุ่นไชน์มัสแคท 300 กรัมx 15 P | D29: 15 | E29: 10 | F29: 19 | G29: 39 | H29: 26 | Q29: =SUM(E29:P29) -> 94 | R29: 8 | S29: 240 | T29: =SUM(S29-Q29) -> 146 | V29: =SUM(E29,F29) -> 29 | W29: =SUM(G29,H29) -> 65 | X29: =SUM(I29,J29) -> 0 | Y29: =SUM(K29,L29,M29,) -> 0 | Z29: =SUM(N29,O29,P29) -> 0 | AK29: =IF(AK28=0, "", IF(MOD(AK28, $D$29) = 0, AK28/ $D$29, IF(INT(AK28 / $D$29) = 0, MOD(AK28, $D$29) & " P", INT(AK28 / $D$29) & " + " & MOD(AK28, $D$29) & " P"))) -> 4 + 14 P
C30: Shine Muscat 300g ( 88593880000189 ) | E30: =IF(E29=0, "", IF(MOD(E29, $D$29) = 0, E29/ $D$29, IF(INT(E29 / $D$29) = 0, MOD(E29, $D$29) & " P", INT(E29 / $D$29) & " + " & MOD(E29, $D$29) & " P"))) -> 10 P | F30: =IF(F29=0, "", IF(MOD(F29, $D$29) = 0, F29/ $D$29, IF(INT(F29 / $D$29) = 0, MOD(F29, $D$29) & " P", INT(F29 / $D$29) & " + " & MOD(F29, $D$29) & " P"))) -> 1 + 4 P | G30: =IF(G29=0, "", IF(MOD(G29, $D$29) = 0, G29/ $D$29, IF(INT(G29 / $D$29) = 0, MOD(G29, $D$29) & " P", INT(G29 / $D$29) & " + " & MOD(G29, $D$29) & " P"))) -> 2 + 9 P | H30: =IF(H29=0, "", IF(MOD(H29, $D$29) = 0, H29/ $D$29, IF(INT(H29 / $D$29) = 0, MOD(H29, $D$29) & " P", INT(H29 / $D$29) & " + " & MOD(H29, $D$29) & " P"))) -> 1 + 11 P | I30: =IF(I29=0, "", IF(MOD(I29, $D$29) = 0, I29/ $D$29, IF(INT(I29 / $D$29) = 0, MOD(I29, $D$29) & " P", INT(I29 / $D$29) & " + " & MOD(I29, $D$29) & " P"))) | J30: =IF(J29=0, "", IF(MOD(J29, $D$29) = 0, J29/ $D$29, IF(INT(J29 / $D$29) = 0, MOD(J29, $D$29) & " P", INT(J29 / $D$29) & " + " & MOD(J29, $D$29) & " P"))) | K30: =IF(K29=0, "", IF(MOD(K29, $D$29) = 0, K29/ $D$29, IF(INT(K29 / $D$29) = 0, MOD(K29, $D$29) & " P", INT(K29 / $D$29) & " + " & MOD(K29, $D$29) & " P"))) | L30: =IF(L29=0, "", IF(MOD(L29, $D$29) = 0, L29/ $D$29, IF(INT(L29 / $D$29) = 0, MOD(L29, $D$29) & " P", INT(L29 / $D$29) & " + " & MOD(L29, $D$29) & " P"))) | ... P30: =IF(P29=0, "", IF(MOD(P29, $D$29) = 0, P29/ $D$29, IF(INT(P29 / $D$29) = 0, MOD(P29, $D$29) & " P", INT(P29 / $D$29) & " + " & MOD(P29, $D$29) & " P"))) | AK30: 34
B31: 9 | C31: แอปเปิ้ลแดงวอชิงตันลูกเดี่ยว x 45 P | D31: 45 | E31: 1 | F31: 0 | G31: 7 | H31: 1 | Q31: =SUM(E31:P31) -> 9 | R31: 3 | S31: 70 | T31: =SUM(S31-Q31) -> 61 | V31: =SUM(E31,F31) -> 1 | W31: =SUM(G31,H31) -> 8 | X31: =SUM(I31,J31) -> 0 | Y31: =SUM(K31,L31,M31,) -> 0 | Z31: =SUM(N31,O31,P31) -> 0 | AK31: =IF(AK30=0, "", IF(MOD(AK30, $D$31) = 0, AK30/ $D$31, IF(INT(AK30 / $D$31) = 0, MOD(AK30, $D$31) & " P", INT(AK30 / $D$31) & " + " & MOD(AK30, $D$31) & " P"))) -> 34 P
C32: Washington ( 8859388000759 ) | E32: =IF(E31=0, "", IF(MOD(E31, $D$31) = 0, E31/ $D$31, IF(INT(E31 / $D$31) = 0, MOD(E31, $D$31) & " P", INT(E31 / $D$31) & " + " & MOD(E31, $D$31) & " P"))) -> 1 P | F32: =IF(F31=0, "", IF(MOD(F31, $D$31) = 0, F31/ $D$31, IF(INT(F31 / $D$31) = 0, MOD(F31, $D$31) & " P", INT(F31 / $D$31) & " + " & MOD(F31, $D$31) & " P"))) | G32: =IF(G31=0, "", IF(MOD(G31, $D$31) = 0, G31/ $D$31, IF(INT(G31 / $D$31) = 0, MOD(G31, $D$31) & " P", INT(G31 / $D$31) & " + " & MOD(G31, $D$31) & " P"))) -> 7 P | H32: =IF(H31=0, "", IF(MOD(H31, $D$31) = 0, H31/ $D$31, IF(INT(H31 / $D$31) = 0, MOD(H31, $D$31) & " P", INT(H31 / $D$31) & " + " & MOD(H31, $D$31) & " P"))) -> 1 P | I32: =IF(I31=0, "", IF(MOD(I31, $D$31) = 0, I31/ $D$31, IF(INT(I31 / $D$31) = 0, MOD(I31, $D$31) & " P", INT(I31 / $D$31) & " + " & MOD(I31, $D$31) & " P"))) | J32: =IF(J31=0, "", IF(MOD(J31, $D$31) = 0, J31/ $D$31, IF(INT(J31 / $D$31) = 0, MOD(J31, $D$31) & " P", INT(J31 / $D$31) & " + " & MOD(J31, $D$31) & " P"))) | K32: =IF(K31=0, "", IF(MOD(K31, $D$31) = 0, K31/ $D$31, IF(INT(K31 / $D$31) = 0, MOD(K31, $D$31) & " P", INT(K31 / $D$31) & " + " & MOD(K31, $D$31) & " P"))) | L32: =IF(L31=0, "", IF(MOD(L31, $D$31) = 0, L31/ $D$31, IF(INT(L31 / $D$31) = 0, MOD(L31, $D$31) & " P", INT(L31 / $D$31) & " + " & MOD(L31, $D$31) & " P"))) | ... P32: =IF(P31=0, "", IF(MOD(P31, $D$31) = 0, P31/ $D$31, IF(INT(P31 / $D$31) = 0, MOD(P31, $D$31) & " P", INT(P31 / $D$31) & " + " & MOD(P31, $D$31) & " P"))) | AK32: 33
B33: 10 | C33: องุ่นสวีทแซฟไฟร์300 กรัม x 15 P | D33: 15 | E33: 23 | F33: 25 | G33: 33 | H33: 53 | Q33: =SUM(E33:P33) -> 134 | R33: 11 | S33: 320 | T33: =SUM(S33-Q33) -> 186 | V33: =SUM(E33,F33) -> 48 | W33: =SUM(G33,H33) -> 86 | X33: =SUM(I33,J33) -> 0 | Y33: =SUM(K33,L33,M33,) -> 0 | Z33: =SUM(N33,O33,P33) -> 0 | AK33: =IF(AK32=0, "", IF(MOD(AK32, $D$31) = 0, AK32/ $D$31, IF(INT(AK32 / $D$31) = 0, MOD(AK32, $D$31) & " P", INT(AK32 / $D$31) & " + " & MOD(AK32, $D$31) & " P"))) -> 33 P
C34: Sweet Sapphire ( 8859388000223 ) | E34: =IF(E33=0, "", IF(MOD(E33, $D$33) = 0, E33/ $D$33, IF(INT(E33 / $D$33) = 0, MOD(E33, $D$33) & " P", INT(E33 / $D$33) & " + " & MOD(E33, $D$33) & " P"))) -> 1 + 8 P | F34: =IF(F33=0, "", IF(MOD(F33, $D$33) = 0, F33/ $D$33, IF(INT(F33 / $D$33) = 0, MOD(F33, $D$33) & " P", INT(F33 / $D$33) & " + " & MOD(F33, $D$33) & " P"))) -> 1 + 10 P | G34: =IF(G33=0, "", IF(MOD(G33, $D$33) = 0, G33/ $D$33, IF(INT(G33 / $D$33) = 0, MOD(G33, $D$33) & " P", INT(G33 / $D$33) & " + " & MOD(G33, $D$33) & " P"))) -> 2 + 3 P | H34: =IF(H33=0, "", IF(MOD(H33, $D$33) = 0, H33/ $D$33, IF(INT(H33 / $D$33) = 0, MOD(H33, $D$33) & " P", INT(H33 / $D$33) & " + " & MOD(H33, $D$33) & " P"))) -> 3 + 8 P | I34: =IF(I33=0, "", IF(MOD(I33, $D$33) = 0, I33/ $D$33, IF(INT(I33 / $D$33) = 0, MOD(I33, $D$33) & " P", INT(I33 / $D$33) & " + " & MOD(I33, $D$33) & " P"))) | J34: =IF(J33=0, "", IF(MOD(J33, $D$33) = 0, J33/ $D$33, IF(INT(J33 / $D$33) = 0, MOD(J33, $D$33) & " P", INT(J33 / $D$33) & " + " & MOD(J33, $D$33) & " P"))) | K34: =IF(K33=0, "", IF(MOD(K33, $D$33) = 0, K33/ $D$33, IF(INT(K33 / $D$33) = 0, MOD(K33, $D$33) & " P", INT(K33 / $D$33) & " + " & MOD(K33, $D$33) & " P"))) | L34: =IF(L33=0, "", IF(MOD(L33, $D$33) = 0, L33/ $D$33, IF(INT(L33 / $D$33) = 0, MOD(L33, $D$33) & " P", INT(L33 / $D$33) & " + " & MOD(L33, $D$33) & " P"))) | ... P34: =IF(P33=0, "", IF(MOD(P33, $D$33) = 0, P33/ $D$33, IF(INT(P33 / $D$33) = 0, MOD(P33, $D$33) & " P", INT(P33 / $D$33) & " + " & MOD(P33, $D$33) & " P"))) | AK34: 33
B35: 11 | C35: องุ่นเคียวโฮ 300 กรัม x 15 P | D35: 15 | E35: 9 | F35: 10 | G35: 36 | H35: 27 | Q35: =SUM(E35:P35) -> 82 | R35: 7 | S35: 190 | T35: =SUM(S35-Q35) -> 108 | V35: =SUM(E35,F35) -> 19 | W35: =SUM(G35,H35) -> 63 | X35: =SUM(I35,J35) -> 0 | Y35: =SUM(K35,L35,M35,) -> 0 | Z35: =SUM(N35,O35,P35) -> 0 | AK35: =IF(AK30=0, "", IF(MOD(AK30, $D$37) = 0, AK30/ $D$37, IF(INT(AK30 / $D$37) = 0, MOD(AK30, $D$37) & " P", INT(AK30 / $D$37) & " + " & MOD(AK30, $D$37) & " P"))) -> 1 + 7 P
C36: Kyoho Grape (888593880000063 ) | E36: =IF(E35=0, "", IF(MOD(E35, $D$35) = 0, E35/ $D$35, IF(INT(E35 / $D$35) = 0, MOD(E35, $D$35) & " P", INT(E35 / $D$35) & " + " & MOD(E35, $D$35) & " P"))) -> 9 P | F36: =IF(F35=0, "", IF(MOD(F35, $D$35) = 0, F35/ $D$35, IF(INT(F35 / $D$35) = 0, MOD(F35, $D$35) & " P", INT(F35 / $D$35) & " + " & MOD(F35, $D$35) & " P"))) -> 10 P | G36: =IF(G35=0, "", IF(MOD(G35, $D$35) = 0, G35/ $D$35, IF(INT(G35 / $D$35) = 0, MOD(G35, $D$35) & " P", INT(G35 / $D$35) & " + " & MOD(G35, $D$35) & " P"))) -> 2 + 6 P | H36: =IF(H35=0, "", IF(MOD(H35, $D$35) = 0, H35/ $D$35, IF(INT(H35 / $D$35) = 0, MOD(H35, $D$35) & " P", INT(H35 / $D$35) & " + " & MOD(H35, $D$35) & " P"))) -> 1 + 12 P | I36: =IF(I35=0, "", IF(MOD(I35, $D$35) = 0, I35/ $D$35, IF(INT(I35 / $D$35) = 0, MOD(I35, $D$35) & " P", INT(I35 / $D$35) & " + " & MOD(I35, $D$35) & " P"))) | J36: =IF(J35=0, "", IF(MOD(J35, $D$35) = 0, J35/ $D$35, IF(INT(J35 / $D$35) = 0, MOD(J35, $D$35) & " P", INT(J35 / $D$35) & " + " & MOD(J35, $D$35) & " P"))) | K36: =IF(K35=0, "", IF(MOD(K35, $D$35) = 0, K35/ $D$35, IF(INT(K35 / $D$35) = 0, MOD(K35, $D$35) & " P", INT(K35 / $D$35) & " + " & MOD(K35, $D$35) & " P"))) | L36: =IF(L35=0, "", IF(MOD(L35, $D$35) = 0, L35/ $D$35, IF(INT(L35 / $D$35) = 0, MOD(L35, $D$35) & " P", INT(L35 / $D$35) & " + " & MOD(L35, $D$35) & " P"))) | ... P36: =IF(P35=0, "", IF(MOD(P35, $D$35) = 0, P35/ $D$35, IF(INT(P35 / $D$35) = 0, MOD(P35, $D$35) & " P", INT(P35 / $D$35) & " + " & MOD(P35, $D$35) & " P")))
B37: 12 | C37: ลูกไหนจิ๋ว 200 g. x 27 p | D37: 27 | E37: 29 | F37: 37 | G37: 52 | H37: 74 | Q37: =SUM(E37:P37) -> 192 | R37: 9 | S37: 440 | T37: =SUM(S37-Q37) -> 248 | V37: =SUM(E37,F37) -> 66 | W37: =SUM(G37,H37) -> 126 | X37: =SUM(I37,J37) -> 0 | Y37: =SUM(K37,L37,M37,) -> 0 | Z37: =SUM(N37,O37,P37) -> 0 | AK37: =IF(AK32=0, "", IF(MOD(AK32, $D$37) = 0, AK32/ $D$37, IF(INT(AK32 / $D$37) = 0, MOD(AK32, $D$37) & " P", INT(AK32 / $D$37) & " + " & MOD(AK32, $D$37) & " P"))) -> 1 + 6 P
C38: Plum 200 g. ( 8859388001091 ) | E38: =IF(E37=0, "", IF(MOD(E37, $D$37) = 0, E37/ $D$37, IF(INT(E37 / $D$37) = 0, MOD(E37, $D$37) & " P", INT(E37 / $D$37) & " + " & MOD(E37, $D$37) & " P"))) -> 1 + 2 P | F38: =IF(F37=0, "", IF(MOD(F37, $D$37) = 0, F37/ $D$37, IF(INT(F37 / $D$37) = 0, MOD(F37, $D$37) & " P", INT(F37 / $D$37) & " + " & MOD(F37, $D$37) & " P"))) -> 1 + 10 P | G38: =IF(G37=0, "", IF(MOD(G37, $D$37) = 0, G37/ $D$37, IF(INT(G37 / $D$37) = 0, MOD(G37, $D$37) & " P", INT(G37 / $D$37) & " + " & MOD(G37, $D$37) & " P"))) -> 1 + 25 P | H38: =IF(H37=0, "", IF(MOD(H37, $D$37) = 0, H37/ $D$37, IF(INT(H37 / $D$37) = 0, MOD(H37, $D$37) & " P", INT(H37 / $D$37) & " + " & MOD(H37, $D$37) & " P"))) -> 2 + 20 P | I38: =IF(I37=0, "", IF(MOD(I37, $D$37) = 0, I37/ $D$37, IF(INT(I37 / $D$37) = 0, MOD(I37, $D$37) & " P", INT(I37 / $D$37) & " + " & MOD(I37, $D$37) & " P"))) | J38: =IF(J37=0, "", IF(MOD(J37, $D$37) = 0, J37/ $D$37, IF(INT(J37 / $D$37) = 0, MOD(J37, $D$37) & " P", INT(J37 / $D$37) & " + " & MOD(J37, $D$37) & " P"))) | K38: =IF(K37=0, "", IF(MOD(K37, $D$37) = 0, K37/ $D$37, IF(INT(K37 / $D$37) = 0, MOD(K37, $D$37) & " P", INT(K37 / $D$37) & " + " & MOD(K37, $D$37) & " P"))) | L38: =IF(L37=0, "", IF(MOD(L37, $D$37) = 0, L37/ $D$37, IF(INT(L37 / $D$37) = 0, MOD(L37, $D$37) & " P", INT(L37 / $D$37) & " + " & MOD(L37, $D$37) & " P"))) | ... P38: =IF(P37=0, "", IF(MOD(P37, $D$37) = 0, P37/ $D$37, IF(INT(P37 / $D$37) = 0, MOD(P37, $D$37) & " P", INT(P37 / $D$37) & " + " & MOD(P37, $D$37) & " P")))
B39: 13 | C39: องุ่นแดงไร้เมล็ด 300 g. x 20 p | D39: 20 | E39: 14 | F39: 17 | G39: 115 | H39: 67 | Q39: =SUM(E39:P39) -> 213 | R39: 12 | S39: 450 | T39: =SUM(S39-Q39) -> 237 | V39: =SUM(E39,F39) -> 31 | W39: =SUM(G39,H39) -> 182 | X39: =SUM(I39,J39) -> 0 | Y39: =SUM(K39,L39,M39,) -> 0 | Z39: =SUM(N39,O39,P39) -> 0 | AK39: =IF(AK36=0, "", IF(MOD(AK36, $D$37) = 0, AK36/ $D$37, IF(INT(AK36 / $D$37) = 0, MOD(AK36, $D$37) & " P", INT(AK36 / $D$37) & " + " & MOD(AK36, $D$37) & " P")))
