Workbook

Sheet บางบัวทอง-ผลิต
E3: วันที่ผลิต 07/09/69 ส่งวันที่ PO 08/09/69
B6: ผู้ส่ง : 7-11 บางบัวทอง10 ล้อ 83-8522 พี่บาส+หม่องโต | E6: บาร์โค๊ดระบุ วันที่ PO | F6: บาร์โค๊ดระบุ วันที่ผลิต | L6: ยอดรวม | N6: ของคืน
B7: NO. | C7: บางบัวทอง (BB) | D7: บรรจุ/ตก. | E7: 01.00 น. | F7: 20.30 น. | H7: 20.00 น. | J7: 19.00 น.
E9: บางบัวทอง | F9: ชลุบรี | H9: นครสวรรค์ | J9: นครราชสีมา
E11: PO 1 | F11: PO 1 | G11: PO 2 | H11: PO 1 | I11: PO 2 | J11: PO 1 | K11: PO 2 | L11: แพค | M11: ตะกร้า | P11: บางบัว | Q11: ชลบุรี | R11: นครสวรรค์ | S11: นครราชสีมา
B12: 1 | C12: องุ่นดำไร้เมล็ด 150 กรัม x36P | D12: 36 | L12: =SUM(E12:K12) -> 0 | M12: ='บางบัวทอง-รถ'!C10 -> 0 | P12: =SUM(E12) -> 0 | Q12: =SUM(F12:G12) -> 0 | R12: =SUM(H12,I12) -> 0 | S12: =SUM(J12:K12) -> 0
C13: BlackGrapesSeedless150g.(8859388000025) | E13: =IF(E12=0, "", IF(MOD(E12, $D$12) = 0, E12 / $D$12, IF(INT(E12 / $D$12) = 0, MOD(E12, $D$12) & " P", INT(E12 / $D$12) & " + " & MOD(E12, $D$12) & " P"))) | F13: =IF(F12=0, "", IF(MOD(F12, $D$12) = 0, F12 / $D$12, IF(INT(F12 / $D$12) = 0, MOD(F12, $D$12) & " P", INT(F12 / $D$12) & " + " & MOD(F12, $D$12) & " P"))) | G13: =IF(G12=0, "", IF(MOD(G12, $D$12) = 0, G12 / $D$12, IF(INT(G12 / $D$12) = 0, MOD(G12, $D$12) & " P", INT(G12 / $D$12) & " + " & MOD(G12, $D$12) & " P"))) | H13: =IF(H12=0, "", IF(MOD(H12, $D$12) = 0, H12 / $D$12, IF(INT(H12 / $D$12) = 0, MOD(H12, $D$12) & " P", INT(H12 / $D$12) & " + " & MOD(H12, $D$12) & " P"))) | I13: =IF(I12=0, "", IF(MOD(I12, $D$12) = 0, I12 / $D$12, IF(INT(I12 / $D$12) = 0, MOD(I12, $D$12) & " P", INT(I12 / $D$12) & " + " & MOD(I12, $D$12) & " P"))) | J13: =IF(J12=0, "", IF(MOD(J12, $D$12) = 0, J12 / $D$12, IF(INT(J12 / $D$12) = 0, MOD(J12, $D$12) & " P", INT(J12 / $D$12) & " + " & MOD(J12, $D$12) & " P"))) | K13: =IF(K12=0, "", IF(MOD(K12, $D$12) = 0, K12 / $D$12, IF(INT(K12 / $D$12) = 0, MOD(K12, $D$12) & " P", INT(K12 / $D$12) & " + " & MOD(K12, $D$12) & " P")))
B14: 2 | C14: องุ่นแดงนอกมีเมล็ด 200 กรัม x 32 P | D14: 32 | L14: =SUM(E14:K14) -> 0 | M14: ='บางบัวทอง-รถ'!C11 -> 0 | P14: =SUM(E14) -> 0 | Q14: =SUM(F14:G14) -> 0 | R14: =SUM(H14,I14) -> 0 | S14: =SUM(J14:K14) -> 0
C15: Red Seed 200 g. ( 8859388000100 ) | E15: =IF(E14=0, "", IF(MOD(E14, $D$14) = 0, E14 / $D$14, IF(INT(E14 / $D$14) = 0, MOD(E14, $D$14) & " P", INT(E14 / $D$14) & " + " & MOD(E14, $D$14) & " P"))) | F15: =IF(F14=0, "", IF(MOD(F14, $D$14) = 0, F14 / $D$14, IF(INT(F14 / $D$14) = 0, MOD(F14, $D$14) & " P", INT(F14 / $D$14) & " + " & MOD(F14, $D$14) & " P"))) | G15: =IF(G14=0, "", IF(MOD(G14, $D$14) = 0, G14 / $D$14, IF(INT(G14 / $D$14) = 0, MOD(G14, $D$14) & " P", INT(G14 / $D$14) & " + " & MOD(G14, $D$14) & " P"))) | H15: =IF(H14=0, "", IF(MOD(H14, $D$14) = 0, H14 / $D$14, IF(INT(H14 / $D$14) = 0, MOD(H14, $D$14) & " P", INT(H14 / $D$14) & " + " & MOD(H14, $D$14) & " P"))) | I15: =IF(I14=0, "", IF(MOD(I14, $D$14) = 0, I14 / $D$14, IF(INT(I14 / $D$14) = 0, MOD(I14, $D$14) & " P", INT(I14 / $D$14) & " + " & MOD(I14, $D$14) & " P"))) | J15: =IF(J14=0, "", IF(MOD(J14, $D$14) = 0, J14 / $D$14, IF(INT(J14 / $D$14) = 0, MOD(J14, $D$14) & " P", INT(J14 / $D$14) & " + " & MOD(J14, $D$14) & " P"))) | K15: =IF(K14=0, "", IF(MOD(K14, $D$14) = 0, K14 / $D$14, IF(INT(K14 / $D$14) = 0, MOD(K14, $D$14) & " P", INT(K14 / $D$14) & " + " & MOD(K14, $D$14) & " P")))
B16: 3 | C16: ส้มแพ็ก 4 ผล(450 กรัม) x14 P | D16: 14 | L16: =SUM(E16:K16) -> 0 | M16: ='บางบัวทอง-รถ'!C12 -> 0 | P16: =SUM(E16) -> 0 | Q16: =SUM(F16:G16) -> 0 | R16: =SUM(H16,I16) -> 0 | S16: =SUM(J16:K16) -> 0
C17: Mandarin orange P.4 (8859388000445) | E17: =IF(E16=0, "", IF(MOD(E16, $D$16) = 0, E16/ $D$16, IF(INT(E16 / $D$16) = 0, MOD(E16, $D$16) & " P", INT(E16 / $D$16) & " + " & MOD(E16, $D$16) & " P"))) | F17: =IF(F16=0, "", IF(MOD(F16, $D$16) = 0, F16/ $D$16, IF(INT(F16 / $D$16) = 0, MOD(F16, $D$16) & " P", INT(F16 / $D$16) & " + " & MOD(F16, $D$16) & " P"))) | G17: =IF(G16=0, "", IF(MOD(G16, $D$16) = 0, G16/ $D$16, IF(INT(G16 / $D$16) = 0, MOD(G16, $D$16) & " P", INT(G16 / $D$16) & " + " & MOD(G16, $D$16) & " P"))) | H17: =IF(H16=0, "", IF(MOD(H16, $D$16) = 0, H16/ $D$16, IF(INT(H16 / $D$16) = 0, MOD(H16, $D$16) & " P", INT(H16 / $D$16) & " + " & MOD(H16, $D$16) & " P"))) | I17: =IF(I16=0, "", IF(MOD(I16, $D$16) = 0, I16/ $D$16, IF(INT(I16 / $D$16) = 0, MOD(I16, $D$16) & " P", INT(I16 / $D$16) & " + " & MOD(I16, $D$16) & " P"))) | J17: =IF(J16=0, "", IF(MOD(J16, $D$16) = 0, J16/ $D$16, IF(INT(J16 / $D$16) = 0, MOD(J16, $D$16) & " P", INT(J16 / $D$16) & " + " & MOD(J16, $D$16) & " P"))) | K17: =IF(K16=0, "", IF(MOD(K16, $D$16) = 0, K16/ $D$16, IF(INT(K16 / $D$16) = 0, MOD(K16, $D$16) & " P", INT(K16 / $D$16) & " + " & MOD(K16, $D$16) & " P")))
B18: 4 | C18: แอปเปิ้ลแพ็ก 4 ผล(400 กรัม) x14 P | D18: 14 | L18: =SUM(E18:K18) -> 0 | M18: ='บางบัวทอง-รถ'!C13 -> 0 | P18: =SUM(E18) -> 0 | Q18: =SUM(F18:G18) -> 0 | R18: =SUM(H18,I18) -> 0 | S18: =SUM(J18:K18) -> 0
C19: Apple P.4 (8859388000568 ) | E19: =IF(E18=0, "", IF(MOD(E18, $D$18) = 0, E18/ $D$18, IF(INT(E18 / $D$18) = 0, MOD(E18, $D$18) & " P", INT(E18 / $D$18) & " + " & MOD(E18, $D$18) & " P"))) | F19: =IF(F18=0, "", IF(MOD(F18, $D$18) = 0, F18/ $D$18, IF(INT(F18 / $D$18) = 0, MOD(F18, $D$18) & " P", INT(F18 / $D$18) & " + " & MOD(F18, $D$18) & " P"))) | G19: =IF(G18=0, "", IF(MOD(G18, $D$18) = 0, G18/ $D$18, IF(INT(G18 / $D$18) = 0, MOD(G18, $D$18) & " P", INT(G18 / $D$18) & " + " & MOD(G18, $D$18) & " P"))) | H19: =IF(H18=0, "", IF(MOD(H18, $D$18) = 0, H18/ $D$18, IF(INT(H18 / $D$18) = 0, MOD(H18, $D$18) & " P", INT(H18 / $D$18) & " + " & MOD(H18, $D$18) & " P"))) | I19: =IF(I18=0, "", IF(MOD(I18, $D$18) = 0, I18/ $D$18, IF(INT(I18 / $D$18) = 0, MOD(I18, $D$18) & " P", INT(I18 / $D$18) & " + " & MOD(I18, $D$18) & " P"))) | J19: =IF(J18=0, "", IF(MOD(J18, $D$18) = 0, J18/ $D$18, IF(INT(J18 / $D$18) = 0, MOD(J18, $D$18) & " P", INT(J18 / $D$18) & " + " & MOD(J18, $D$18) & " P"))) | K19: =IF(K18=0, "", IF(MOD(K18, $D$18) = 0, K18/ $D$18, IF(INT(K18 / $D$18) = 0, MOD(K18, $D$18) & " P", INT(K18 / $D$18) & " + " & MOD(K18, $D$18) & " P")))
B20: 5 | C20: องุ่นแดงไร้เมล็ด150กรัม x 32 Pไข่ปลา | D20: 32 | L20: =SUM(E20:K20) -> 0 | M20: ='บางบัวทอง-รถ'!C14 -> 0 | P20: =SUM(E20) -> 0 | Q20: =SUM(F20:G20) -> 0 | R20: =SUM(H20,I20) -> 0 | S20: =SUM(J20:K20) -> 0
C21: Red Seedless 150 g. ( 8859388007000 ) | E21: =IF(E20=0, "", IF(MOD(E20, $D$20) = 0, E20/ $D$20, IF(INT(E20 / $D$20) = 0, MOD(E20, $D$20) & " P", INT(E20 / $D$20) & " + " & MOD(E20, $D$20) & " P"))) | F21: =IF(F20=0, "", IF(MOD(F20, $D$20) = 0, F20/ $D$20, IF(INT(F20 / $D$20) = 0, MOD(F20, $D$20) & " P", INT(F20 / $D$20) & " + " & MOD(F20, $D$20) & " P"))) | G21: =IF(G20=0, "", IF(MOD(G20, $D$20) = 0, G20/ $D$20, IF(INT(G20 / $D$20) = 0, MOD(G20, $D$20) & " P", INT(G20 / $D$20) & " + " & MOD(G20, $D$20) & " P"))) | H21: =IF(H20=0, "", IF(MOD(H20, $D$20) = 0, H20/ $D$20, IF(INT(H20 / $D$20) = 0, MOD(H20, $D$20) & " P", INT(H20 / $D$20) & " + " & MOD(H20, $D$20) & " P"))) | I21: =IF(I20=0, "", IF(MOD(I20, $D$20) = 0, I20/ $D$20, IF(INT(I20 / $D$20) = 0, MOD(I20, $D$20) & " P", INT(I20 / $D$20) & " + " & MOD(I20, $D$20) & " P"))) | J21: =IF(J20=0, "", IF(MOD(J20, $D$20) = 0, J20/ $D$20, IF(INT(J20 / $D$20) = 0, MOD(J20, $D$20) & " P", INT(J20 / $D$20) & " + " & MOD(J20, $D$20) & " P"))) | K21: =IF(K20=0, "", IF(MOD(K20, $D$20) = 0, K20/ $D$20, IF(INT(K20 / $D$20) = 0, MOD(K20, $D$20) & " P", INT(K20 / $D$20) & " + " & MOD(K20, $D$20) & " P")))
B22: 6 | C22: พุทราจีน 200 กรัม x 27 P | D22: 27 | L22: =SUM(E22:K22) -> 0 | M22: ='บางบัวทอง-รถ'!C15 -> 0 | P22: =SUM(E22) -> 0 | Q22: =SUM(F22:G22) -> 0 | R22: =SUM(H22,I22) -> 0 | S22: =SUM(J22:K22) -> 0
C23: Jujube 200g.(8859388000087 ) | E23: =IF(E22=0, "", IF(MOD(E22, $D$22) = 0, E22/ $D$22, IF(INT(E22 / $D$22) = 0, MOD(E22, $D$22) & " P", INT(E22 / $D$22) & " + " & MOD(E22, $D$22) & " P"))) | F23: =IF(F22=0, "", IF(MOD(F22, $D$22) = 0, F22/ $D$22, IF(INT(F22 / $D$22) = 0, MOD(F22, $D$22) & " P", INT(F22 / $D$22) & " + " & MOD(F22, $D$22) & " P"))) | G23: =IF(G22=0, "", IF(MOD(G22, $D$22) = 0, G22/ $D$22, IF(INT(G22 / $D$22) = 0, MOD(G22, $D$22) & " P", INT(G22 / $D$22) & " + " & MOD(G22, $D$22) & " P"))) | H23: =IF(H22=0, "", IF(MOD(H22, $D$22) = 0, H22/ $D$22, IF(INT(H22 / $D$22) = 0, MOD(H22, $D$22) & " P", INT(H22 / $D$22) & " + " & MOD(H22, $D$22) & " P"))) | I23: =IF(I22=0, "", IF(MOD(I22, $D$22) = 0, I22/ $D$22, IF(INT(I22 / $D$22) = 0, MOD(I22, $D$22) & " P", INT(I22 / $D$22) & " + " & MOD(I22, $D$22) & " P"))) | J23: =IF(J22=0, "", IF(MOD(J22, $D$22) = 0, J22/ $D$22, IF(INT(J22 / $D$22) = 0, MOD(J22, $D$22) & " P", INT(J22 / $D$22) & " + " & MOD(J22, $D$22) & " P"))) | K23: =IF(K22=0, "", IF(MOD(K22, $D$22) = 0, K22/ $D$22, IF(INT(K22 / $D$22) = 0, MOD(K22, $D$22) & " P", INT(K22 / $D$22) & " + " & MOD(K22, $D$22) & " P")))
B24: 7 | C24: สตรอเบอร์รี่ 250 กรัม x 27 P | D24: 27 | L24: =SUM(E24:K24) -> 0 | M24: ='บางบัวทอง-รถ'!C16 -> 0 | P24: =SUM(E24) -> 0 | Q24: =SUM(F24:G24) -> 0 | R24: =SUM(H24,I24) -> 0 | S24: =SUM(J24:K24) -> 0
C25: Straw 250 g. ( 2003009710008 ) | E25: =IF(E24=0, "", IF(MOD(E24, $D$24) = 0, E24/ $D$24, IF(INT(E24 / $D$24) = 0, MOD(E24, $D$24) & " P", INT(E24 / $D$24) & " + " & MOD(E24, $D$24) & " P"))) | F25: =IF(F24=0, "", IF(MOD(F24, $D$24) = 0, F24/ $D$24, IF(INT(F24 / $D$24) = 0, MOD(F24, $D$24) & " P", INT(F24 / $D$24) & " + " & MOD(F24, $D$24) & " P"))) | G25: =IF(G24=0, "", IF(MOD(G24, $D$24) = 0, G24/ $D$24, IF(INT(G24 / $D$24) = 0, MOD(G24, $D$24) & " P", INT(G24 / $D$24) & " + " & MOD(G24, $D$24) & " P"))) | H25: =IF(H24=0, "", IF(MOD(H24, $D$24) = 0, H24/ $D$24, IF(INT(H24 / $D$24) = 0, MOD(H24, $D$24) & " P", INT(H24 / $D$24) & " + " & MOD(H24, $D$24) & " P"))) | I25: =IF(I24=0, "", IF(MOD(I24, $D$24) = 0, I24/ $D$24, IF(INT(I24 / $D$24) = 0, MOD(I24, $D$24) & " P", INT(I24 / $D$24) & " + " & MOD(I24, $D$24) & " P"))) | J25: =IF(J24=0, "", IF(MOD(J24, $D$24) = 0, J24/ $D$24, IF(INT(J24 / $D$24) = 0, MOD(J24, $D$24) & " P", INT(J24 / $D$24) & " + " & MOD(J24, $D$24) & " P"))) | K25: =IF(K24=0, "", IF(MOD(K24, $D$24) = 0, K24/ $D$24, IF(INT(K24 / $D$24) = 0, MOD(K24, $D$24) & " P", INT(K24 / $D$24) & " + " & MOD(K24, $D$24) & " P")))
B26: 8 | C26: บลูเบอร์รี่ 125 กรัม x 36 P | D26: 36 | L26: =SUM(E26:K26) -> 0 | M26: ='บางบัวทอง-รถ'!C17 -> 0 | P26: =SUM(E26) -> 0 | Q26: =SUM(F26:G26) -> 0 | R26: =SUM(H26,I26) -> 0 | S26: =SUM(J26:K26) -> 0
C27: Blue 125 g. ( 2003009720007 ) | E27: =IF(E26=0, "", IF(MOD(E26, $D$26) = 0, E26/ $D$26, IF(INT(E26 / $D$26) = 0, MOD(E26, $D$26) & " P", INT(E26 / $D$26) & " + " & MOD(E26, $D$26) & " P"))) | F27: =IF(F26=0, "", IF(MOD(F26, $D$26) = 0, F26/ $D$26, IF(INT(F26 / $D$26) = 0, MOD(F26, $D$26) & " P", INT(F26 / $D$26) & " + " & MOD(F26, $D$26) & " P"))) | G27: =IF(G26=0, "", IF(MOD(G26, $D$26) = 0, G26/ $D$26, IF(INT(G26 / $D$26) = 0, MOD(G26, $D$26) & " P", INT(G26 / $D$26) & " + " & MOD(G26, $D$26) & " P"))) | H27: =IF(H26=0, "", IF(MOD(H26, $D$26) = 0, H26/ $D$26, IF(INT(H26 / $D$26) = 0, MOD(H26, $D$26) & " P", INT(H26 / $D$26) & " + " & MOD(H26, $D$26) & " P"))) | I27: =IF(I26=0, "", IF(MOD(I26, $D$26) = 0, I26/ $D$26, IF(INT(I26 / $D$26) = 0, MOD(I26, $D$26) & " P", INT(I26 / $D$26) & " + " & MOD(I26, $D$26) & " P"))) | J27: =IF(J26=0, "", IF(MOD(J26, $D$26) = 0, J26/ $D$26, IF(INT(J26 / $D$26) = 0, MOD(J26, $D$26) & " P", INT(J26 / $D$26) & " + " & MOD(J26, $D$26) & " P"))) | K27: =IF(K26=0, "", IF(MOD(K26, $D$26) = 0, K26/ $D$26, IF(INT(K26 / $D$26) = 0, MOD(K26, $D$26) & " P", INT(K26 / $D$26) & " + " & MOD(K26, $D$26) & " P")))
B28: 9 | C28: องุ่นดำไร้เมล็ด 300 กรัม x20P | D28: 20 | L28: =SUM(E28:K28) -> 0 | M28: ='บางบัวทอง-รถ'!C18 -> 0 | P28: =SUM(E28) -> 0 | Q28: =SUM(F28:G28) -> 0 | R28: =SUM(H28,I28) -> 0 | S28: =SUM(J28:K28) -> 0
C29: BlackGrapesSeedless300 g.(8859388010284) | E29: =IF(E28=0, "", IF(MOD(E28, $D$28) = 0, E28/ $D$28, IF(INT(E28 / $D$28) = 0, MOD(E28, $D$28) & " P", INT(E28 / $D$28) & " + " & MOD(E28, $D$28) & " P"))) | F29: =IF(F28=0, "", IF(MOD(F28, $D$28) = 0, F28/ $D$28, IF(INT(F28 / $D$28) = 0, MOD(F28, $D$28) & " P", INT(F28 / $D$28) & " + " & MOD(F28, $D$28) & " P"))) | G29: =IF(G28=0, "", IF(MOD(G28, $D$28) = 0, G28/ $D$28, IF(INT(G28 / $D$28) = 0, MOD(G28, $D$28) & " P", INT(G28 / $D$28) & " + " & MOD(G28, $D$28) & " P"))) | H29: =IF(H28=0, "", IF(MOD(H28, $D$28) = 0, H28/ $D$28, IF(INT(H28 / $D$28) = 0, MOD(H28, $D$28) & " P", INT(H28 / $D$28) & " + " & MOD(H28, $D$28) & " P"))) | I29: =IF(I28=0, "", IF(MOD(I28, $D$28) = 0, I28/ $D$28, IF(INT(I28 / $D$28) = 0, MOD(I28, $D$28) & " P", INT(I28 / $D$28) & " + " & MOD(I28, $D$28) & " P"))) | J29: =IF(J28=0, "", IF(MOD(J28, $D$28) = 0, J28/ $D$28, IF(INT(J28 / $D$28) = 0, MOD(J28, $D$28) & " P", INT(J28 / $D$28) & " + " & MOD(J28, $D$28) & " P"))) | K29: =IF(K28=0, "", IF(MOD(K28, $D$28) = 0, K28/ $D$28, IF(INT(K28 / $D$28) = 0, MOD(K28, $D$28) & " P", INT(K28 / $D$28) & " + " & MOD(K28, $D$28) & " P")))
B30: 10 | C30: องุ่นไซน์มัสแคท 300 กรัม x 15 P | D30: 15 | L30: =SUM(E30:K30) -> 0 | M30: ='บางบัวทอง-รถ'!C19 -> 0 | P30: =SUM(E30) -> 0 | Q30: =SUM(F30:G30) -> 0 | R30: =SUM(H30,I30) -> 0 | S30: =SUM(J30:K30) -> 0
C31: Shine muscat 300 g ( 885938000018 ) | E31: =IF(E30=0, "", IF(MOD(E30, $D$30) = 0, E30/ $D$30, IF(INT(E30 / $D$30) = 0, MOD(E30, $D$30) & " P", INT(E30 / $D$30) & " + " & MOD(E30, $D$30) & " P"))) | F31: =IF(F30=0, "", IF(MOD(F30, $D$30) = 0, F30/ $D$30, IF(INT(F30 / $D$30) = 0, MOD(F30, $D$30) & " P", INT(F30 / $D$30) & " + " & MOD(F30, $D$30) & " P"))) | G31: =IF(G30=0, "", IF(MOD(G30, $D$30) = 0, G30/ $D$30, IF(INT(G30 / $D$30) = 0, MOD(G30, $D$30) & " P", INT(G30 / $D$30) & " + " & MOD(G30, $D$30) & " P"))) | H31: =IF(H30=0, "", IF(MOD(H30, $D$30) = 0, H30/ $D$30, IF(INT(H30 / $D$30) = 0, MOD(H30, $D$30) & " P", INT(H30 / $D$30) & " + " & MOD(H30, $D$30) & " P"))) | I31: =IF(I30=0, "", IF(MOD(I30, $D$30) = 0, I30/ $D$30, IF(INT(I30 / $D$30) = 0, MOD(I30, $D$30) & " P", INT(I30 / $D$30) & " + " & MOD(I30, $D$30) & " P"))) | J31: =IF(J30=0, "", IF(MOD(J30, $D$30) = 0, J30/ $D$30, IF(INT(J30 / $D$30) = 0, MOD(J30, $D$30) & " P", INT(J30 / $D$30) & " + " & MOD(J30, $D$30) & " P"))) | K31: =IF(K30=0, "", IF(MOD(K30, $D$30) = 0, K30/ $D$30, IF(INT(K30 / $D$30) = 0, MOD(K30, $D$30) & " P", INT(K30 / $D$30) & " + " & MOD(K30, $D$30) & " P")))
B32: 11 | C32: แอปเปิ้ลแดงวอชิงตันลูกเดี่ยว x 45 P | D32: 45 | L32: =SUM(E32:K32) -> 0 | M32: ='บางบัวทอง-รถ'!C20 -> 0 | P32: =SUM(E32) -> 0 | Q32: =SUM(F32:G32) -> 0 | R32: =SUM(H32,I32) -> 0 | S32: =SUM(J32:K32) -> 0
C33: Washington ( 8859388000759 ) | E33: =IF(E32=0, "", IF(MOD(E32, $D$32) = 0, E32/ $D$32, IF(INT(E32 / $D$32) = 0, MOD(E32, $D$32) & " P", INT(E32 / $D$32) & " + " & MOD(E32, $D$32) & " P"))) | F33: =IF(F32=0, "", IF(MOD(F32, $D$32) = 0, F32/ $D$32, IF(INT(F32 / $D$32) = 0, MOD(F32, $D$32) & " P", INT(F32 / $D$32) & " + " & MOD(F32, $D$32) & " P"))) | G33: =IF(G32=0, "", IF(MOD(G32, $D$32) = 0, G32/ $D$32, IF(INT(G32 / $D$32) = 0, MOD(G32, $D$32) & " P", INT(G32 / $D$32) & " + " & MOD(G32, $D$32) & " P"))) | H33: =IF(H32=0, "", IF(MOD(H32, $D$32) = 0, H32/ $D$32, IF(INT(H32 / $D$32) = 0, MOD(H32, $D$32) & " P", INT(H32 / $D$32) & " + " & MOD(H32, $D$32) & " P"))) | I33: =IF(I32=0, "", IF(MOD(I32, $D$32) = 0, I32/ $D$32, IF(INT(I32 / $D$32) = 0, MOD(I32, $D$32) & " P", INT(I32 / $D$32) & " + " & MOD(I32, $D$32) & " P"))) | J33: =IF(J32=0, "", IF(MOD(J32, $D$32) = 0, J32/ $D$32, IF(INT(J32 / $D$32) = 0, MOD(J32, $D$32) & " P", INT(J32 / $D$32) & " + " & MOD(J32, $D$32) & " P"))) | K33: =IF(K32=0, "", IF(MOD(K32, $D$32) = 0, K32/ $D$32, IF(INT(K32 / $D$32) = 0, MOD(K32, $D$32) & " P", INT(K32 / $D$32) & " + " & MOD(K32, $D$32) & " P")))
B34: 12 | C34: องุ่นสวีทแซฟไฟร์ 300 กรัม x 15 P | D34: 15 | L34: =SUM(E34:K34) -> 0 | M34: ='บางบัวทอง-รถ'!C21 -> 0 | P34: =SUM(E34) -> 0 | Q34: =SUM(F34:G34) -> 0 | R34: =SUM(H34,I34) -> 0 | S34: =SUM(J34:K34) -> 0
C35: Sweet Sapphire 300gx 15 P( 8859388000223 ) | E35: =IF(E34=0, "", IF(MOD(E34, $D$34) = 0, E34/ $D$34, IF(INT(E34 / $D$34) = 0, MOD(E34, $D$34) & " P", INT(E34 / $D$34) & " + " & MOD(E34, $D$34) & " P"))) | F35: =IF(F34=0, "", IF(MOD(F34, $D$34) = 0, F34/ $D$34, IF(INT(F34 / $D$34) = 0, MOD(F34, $D$34) & " P", INT(F34 / $D$34) & " + " & MOD(F34, $D$34) & " P"))) | G35: =IF(G34=0, "", IF(MOD(G34, $D$34) = 0, G34/ $D$34, IF(INT(G34 / $D$34) = 0, MOD(G34, $D$34) & " P", INT(G34 / $D$34) & " + " & MOD(G34, $D$34) & " P"))) | H35: =IF(H34=0, "", IF(MOD(H34, $D$34) = 0, H34/ $D$34, IF(INT(H34 / $D$34) = 0, MOD(H34, $D$34) & " P", INT(H34 / $D$34) & " + " & MOD(H34, $D$34) & " P"))) | I35: =IF(I34=0, "", IF(MOD(I34, $D$34) = 0, I34/ $D$34, IF(INT(I34 / $D$34) = 0, MOD(I34, $D$34) & " P", INT(I34 / $D$34) & " + " & MOD(I34, $D$34) & " P"))) | J35: =IF(J34=0, "", IF(MOD(J34, $D$34) = 0, J34/ $D$34, IF(INT(J34 / $D$34) = 0, MOD(J34, $D$34) & " P", INT(J34 / $D$34) & " + " & MOD(J34, $D$34) & " P"))) | K35: =IF(K34=0, "", IF(MOD(K34, $D$34) = 0, K34/ $D$34, IF(INT(K34 / $D$34) = 0, MOD(K34, $D$34) & " P", INT(K34 / $D$34) & " + " & MOD(K34, $D$34) & " P")))
B36: 13 | C36: แอปเปิ้ลเจ้าหญิง 200 g. x 27 p | D36: 27 | L36: =SUM(E36:K36) -> 0 | M36: ='บางบัวทอง-รถ'!C22 -> 0 | P36: =SUM(E36) -> 0 | Q36: =SUM(F36:G36) -> 0 | R36: =SUM(H36,I36) -> 0 | S36: =SUM(J36:K36) -> 0
C37: Princess Apple'8859388001060 | E37: =IF(E36=0, "", IF(MOD(E36, $D$36) = 0, E36/ $D$36, IF(INT(E36 / $D$36) = 0, MOD(E36, $D$36) & " P", INT(E36 / $D$36) & " + " & MOD(E36, $D$36) & " P"))) | F37: =IF(F36=0, "", IF(MOD(F36, $D$36) = 0, F36/ $D$36, IF(INT(F36 / $D$36) = 0, MOD(F36, $D$36) & " P", INT(F36 / $D$36) & " + " & MOD(F36, $D$36) & " P"))) | G37: =IF(G36=0, "", IF(MOD(G36, $D$36) = 0, G36/ $D$36, IF(INT(G36 / $D$36) = 0, MOD(G36, $D$36) & " P", INT(G36 / $D$36) & " + " & MOD(G36, $D$36) & " P"))) | H37: =IF(H36=0, "", IF(MOD(H36, $D$36) = 0, H36/ $D$36, IF(INT(H36 / $D$36) = 0, MOD(H36, $D$36) & " P", INT(H36 / $D$36) & " + " & MOD(H36, $D$36) & " P"))) | I37: =IF(I36=0, "", IF(MOD(I36, $D$36) = 0, I36/ $D$36, IF(INT(I36 / $D$36) = 0, MOD(I36, $D$36) & " P", INT(I36 / $D$36) & " + " & MOD(I36, $D$36) & " P"))) | J37: =IF(J36=0, "", IF(MOD(J36, $D$36) = 0, J36/ $D$36, IF(INT(J36 / $D$36) = 0, MOD(J36, $D$36) & " P", INT(J36 / $D$36) & " + " & MOD(J36, $D$36) & " P"))) | K37: =IF(K36=0, "", IF(MOD(K36, $D$36) = 0, K36/ $D$36, IF(INT(K36 / $D$36) = 0, MOD(K36, $D$36) & " P", INT(K36 / $D$36) & " + " & MOD(K36, $D$36) & " P")))
B38: 14 | C38: องุ่นเคียวโฮ 300 กรัม x 15 P | D38: 15 | L38: =SUM(E38:K38) -> 0 | M38: ='บางบัวทอง-รถ'!C23 -> 0 | P38: =SUM(E38) -> 0 | Q38: =SUM(F38:G38) -> 0 | R38: =SUM(H38,I38) -> 0 | S38: =SUM(J38:K38) -> 0
C39: Kyoho Grape300g(88859388000063) | E39: =IF(E38=0, "", IF(MOD(E38, $D$38) = 0, E38/ $D$38, IF(INT(E38 / $D$38) = 0, MOD(E38, $D$38) & " P", INT(E38 / $D$38) & " + " & MOD(E38, $D$38) & " P"))) | F39: =IF(F38=0, "", IF(MOD(F38, $D$38) = 0, F38/ $D$38, IF(INT(F38 / $D$38) = 0, MOD(F38, $D$38) & " P", INT(F38 / $D$38) & " + " & MOD(F38, $D$38) & " P"))) | G39: =IF(G38=0, "", IF(MOD(G38, $D$38) = 0, G38/ $D$38, IF(INT(G38 / $D$38) = 0, MOD(G38, $D$38) & " P", INT(G38 / $D$38) & " + " & MOD(G38, $D$38) & " P"))) | H39: =IF(H38=0, "", IF(MOD(H38, $D$38) = 0, H38/ $D$38, IF(INT(H38 / $D$38) = 0, MOD(H38, $D$38) & " P", INT(H38 / $D$38) & " + " & MOD(H38, $D$38) & " P"))) | I39: =IF(I38=0, "", IF(MOD(I38, $D$38) = 0, I38/ $D$38, IF(INT(I38 / $D$38) = 0, MOD(I38, $D$38) & " P", INT(I38 / $D$38) & " + " & MOD(I38, $D$38) & " P"))) | J39: =IF(J38=0, "", IF(MOD(J38, $D$38) = 0, J38/ $D$38, IF(INT(J38 / $D$38) = 0, MOD(J38, $D$38) & " P", INT(J38 / $D$38) & " + " & MOD(J38, $D$38) & " P"))) | K39: =IF(K38=0, "", IF(MOD(K38, $D$38) = 0, K38/ $D$38, IF(INT(K38 / $D$38) = 0, MOD(K38, $D$38) & " P", INT(K38 / $D$38) & " + " & MOD(K38, $D$38) & " P")))
B40: 15 | C40: ลูกไหนจิ๋ว 200 g. x 27 p | D40: 27 | L40: =SUM(E40:K40) -> 0 | M40: ='บางบัวทอง-รถ'!C24 -> 0 | P40: =SUM(E40) -> 0 | Q40: =SUM(F40:G40) -> 0 | R40: =SUM(H40,I40) -> 0 | S40: =SUM(J40:K40) -> 0
C41: Plum 200 g. ( 8859388001091 ) | E41: =IF(E40=0, "", IF(MOD(E40, $D$40) = 0, E40/ $D$40, IF(INT(E40 / $D$40) = 0, MOD(E40, $D$40) & " P", INT(E40 / $D$40) & " + " & MOD(E40, $D$40) & " P"))) | F41: =IF(F40=0, "", IF(MOD(F40, $D$40) = 0, F40/ $D$40, IF(INT(F40 / $D$40) = 0, MOD(F40, $D$40) & " P", INT(F40 / $D$40) & " + " & MOD(F40, $D$40) & " P"))) | G41: =IF(G40=0, "", IF(MOD(G40, $D$40) = 0, G40/ $D$40, IF(INT(G40 / $D$40) = 0, MOD(G40, $D$40) & " P", INT(G40 / $D$40) & " + " & MOD(G40, $D$40) & " P"))) | H41: =IF(H40=0, "", IF(MOD(H40, $D$40) = 0, H40/ $D$40, IF(INT(H40 / $D$40) = 0, MOD(H40, $D$40) & " P", INT(H40 / $D$40) & " + " & MOD(H40, $D$40) & " P"))) | I41: =IF(I40=0, "", IF(MOD(I40, $D$40) = 0, I40/ $D$40, IF(INT(I40 / $D$40) = 0, MOD(I40, $D$40) & " P", INT(I40 / $D$40) & " + " & MOD(I40, $D$40) & " P"))) | J41: =IF(J40=0, "", IF(MOD(J40, $D$40) = 0, J40/ $D$40, IF(INT(J40 / $D$40) = 0, MOD(J40, $D$40) & " P", INT(J40 / $D$40) & " + " & MOD(J40, $D$40) & " P"))) | K41: =IF(K40=0, "", IF(MOD(K40, $D$40) = 0, K40/ $D$40, IF(INT(K40 / $D$40) = 0, MOD(K40, $D$40) & " P", INT(K40 / $D$40) & " + " & MOD(K40, $D$40) & " P")))
B42: 16 | C42: องุ่นแดงไร้เมล็ด 300 g. x 20 p | D42: 20 | L42: =SUM(E42:K42) -> 0 | M42: ='บางบัวทอง-รถ'!C25 -> 0 | P42: =SUM(E42) -> 0 | Q42: =SUM(F42:G42) -> 0 | R42: =SUM(H42,I42) -> 0 | S42: =SUM(J42:K42) -> 0
C43: Red Seedless 300 g.( 8859388001084 ) | E43: =IF(E42=0, "", IF(MOD(E42, $D$42) = 0, E42/ $D$42, IF(INT(E42 / $D$42) = 0, MOD(E42, $D$42) & " P", INT(E42 / $D$42) & " + " & MOD(E42, $D$42) & " P"))) | F43: =IF(F42=0, "", IF(MOD(F42, $D$42) = 0, F42/ $D$42, IF(INT(F42 / $D$42) = 0, MOD(F42, $D$42) & " P", INT(F42 / $D$42) & " + " & MOD(F42, $D$42) & " P"))) | G43: =IF(G42=0, "", IF(MOD(G42, $D$42) = 0, G42/ $D$42, IF(INT(G42 / $D$42) = 0, MOD(G42, $D$42) & " P", INT(G42 / $D$42) & " + " & MOD(G42, $D$42) & " P"))) | H43: =IF(H42=0, "", IF(MOD(H42, $D$42) = 0, H42/ $D$42, IF(INT(H42 / $D$42) = 0, MOD(H42, $D$42) & " P", INT(H42 / $D$42) & " + " & MOD(H42, $D$42) & " P"))) | I43: =IF(I42=0, "", IF(MOD(I42, $D$42) = 0, I42/ $D$42, IF(INT(I42 / $D$42) = 0, MOD(I42, $D$42) & " P", INT(I42 / $D$42) & " + " & MOD(I42, $D$42) & " P"))) | J43: =IF(J42=0, "", IF(MOD(J42, $D$42) = 0, J42/ $D$42, IF(INT(J42 / $D$42) = 0, MOD(J42, $D$42) & " P", INT(J42 / $D$42) & " + " & MOD(J42, $D$42) & " P"))) | K43: =IF(K42=0, "", IF(MOD(K42, $D$42) = 0, K42/ $D$42, IF(INT(K42 / $D$42) = 0, MOD(K42, $D$42) & " P", INT(K42 / $D$42) & " + " & MOD(K42, $D$42) & " P")))
B44: 17 | C44: เบอร์รี่ดูโอ้ 160 กรัม x 32 P | D44: 32 | L44: =SUM(E44:K44) -> 0 | M44: ='บางบัวทอง-รถ'!C26 -> 0 | P44: =SUM(E44) -> 0 | Q44: =SUM(F44:G44) -> 0 | R44: =SUM(H44,I44) -> 0 | S44: =SUM(J44:K44) -> 0
C45: Berry Duo 160g. ( 8859388010239 ) | E45: =IF(E44=0, "", IF(MOD(E44, $D$44) = 0, E44/ $D$44, IF(INT(E44 / $D$44) = 0, MOD(E44, $D$44) & " P", INT(E44 / $D$44) & " + " & MOD(E44, $D$44) & " P"))) | F45: =IF(F44=0, "", IF(MOD(F44, $D$44) = 0, F44/ $D$44, IF(INT(F44 / $D$44) = 0, MOD(F44, $D$44) & " P", INT(F44 / $D$44) & " + " & MOD(F44, $D$44) & " P"))) | G45: =IF(G44=0, "", IF(MOD(G44, $D$44) = 0, G44/ $D$44, IF(INT(G44 / $D$44) = 0, MOD(G44, $D$44) & " P", INT(G44 / $D$44) & " + " & MOD(G44, $D$44) & " P"))) | H45: =IF(H44=0, "", IF(MOD(H44, $D$44) = 0, H44/ $D$44, IF(INT(H44 / $D$44) = 0, MOD(H44, $D$44) & " P", INT(H44 / $D$44) & " + " & MOD(H44, $D$44) & " P"))) | I45: =IF(I44=0, "", IF(MOD(I44, $D$44) = 0, I44/ $D$44, IF(INT(I44 / $D$44) = 0, MOD(I44, $D$44) & " P", INT(I44 / $D$44) & " + " & MOD(I44, $D$44) & " P"))) | J45: =IF(J44=0, "", IF(MOD(J44, $D$44) = 0, J44/ $D$44, IF(INT(J44 / $D$44) = 0, MOD(J44, $D$44) & " P", INT(J44 / $D$44) & " + " & MOD(J44, $D$44) & " P"))) | K45: =IF(K44=0, "", IF(MOD(K44, $D$44) = 0, K44/ $D$44, IF(INT(K44 / $D$44) = 0, MOD(K44, $D$44) & " P", INT(K44 / $D$44) & " + " & MOD(K44, $D$44) & " P")))
B46: 18 | C46: สาลี่ทอง แพ็ก 2 ผล (400g.) x 15 P | D46: 15 | L46: =SUM(E46:K46) -> 0 | M46: ='บางบัวทอง-รถ'!C27 -> 0 | P46: =SUM(E46) -> 0 | Q46: =SUM(F46:G46) -> 0 | R46: =SUM(H46,I46) -> 0 | S46: =SUM(J46:K46) -> 0
...

Sheet บางบัวทอง-รถ
A1: #VALUE! | B1: Global Trade and Distribution Co., Ltd. บริษัท โกลบอล เทรด แอนด์ ดิสทริบิวชั่น จำกัด | M1: Date:
M3: PO:
A4: ผู้ส่ง:
A6: เซเว่น SB | C6: สุวรรณภูมิ
C7: รับ GTD | D7: เวลาลงสินค้า 02:00-04:00 น.
D8: PO1 | E8: PO3 | F8: PO4 | G8: PO5 | H8: PO7 | I8: PO8 | J8: PO9 | K8: PO10 | M8: ยอดรับจริง | N8: ยอดส่งคืน | O8: หมายเหตุ | P8: KK - PO1 | S8: KK - PO2 | V8: SR - PO1 | Y8: SR - PO2 | AB8: CM- PO1 | AE8: CM- PO2 | AH8: PK- PO1 | AK8: PK- PO2 | AN8: HY- PO1 | AQ8: HY- PO2
A9: รายการสินค้า | B9: บรรจุ/ตก. | L9: GTD | P9: F | Q9: >H | R9: ≤H | S9: F | T9: >H | U9: ≤H | V9: F | W9: >H | X9: ≤H | Y9: F | Z9: >H | AA9: ≤H | AB9: F | AC9: >H | AD9: ≤H | AE9: F | AF9: >H | AG9: ≤H | AH9: F | AI9: >H | AJ9: ≤H | AK9: F | AL9: >H | AM9: ≤H | AN9: F | AO9: >H | AP9: ≤H | AQ9: F | AR9: >H | AS9: ≤H
A10: ='บางบัวทอง-ผลิต'!C12 -> องุ่นดำไร้เมล็ด 150 กรัม x36P | B10: 36 | C10: {=SUMPRODUCT(ROUNDUP(D10:K10/B10, 0))} -> 0 | D10: ='บางบัวทอง-ผลิต'!E12 -> 0 | E10: ='บางบัวทอง-ผลิต'!F12 -> 0 | F10: ='บางบัวทอง-ผลิต'!G12 -> 0 | G10: ='บางบัวทอง-ผลิต'!H12 -> 0 | H10: ='บางบัวทอง-ผลิต'!I12 -> 0 | I10: ='บางบัวทอง-ผลิต'!J12 -> 0 | J10: ='บางบัวทอง-ผลิต'!K12 -> 0 | L10: =INT(SUM(D10:K10)/B10) & " full, " & IF(MOD(SUM(D10:K10), B10)/B10 <= 0.5, "1 less than half", IF(MOD(SUM(D10:K10), B10)/B10 > 0.5, "1 more than half", "")) -> 0 full, 1 less than half | P10: =INT(D10/B10) -> 0 | Q10: =IF(MOD(D10,B10)/B10>0.5,1,0) -> 0 | R10: =IF(AND(MOD(D10,B10)/B10<=0.5,MOD(D10,B10)<>0),1,0) -> 0 | S10: =INT(#REF!/B10) -> #REF! | T10: =IF(MOD(#REF!,B10)/B10>0.5,1,0) -> #REF! | U10: =IF(AND(MOD(#REF!,B10)/B10<=0.5,MOD(#REF!,B10)<>0),1,0) -> #REF! | V10: =INT(E10/B10) -> 0 | W10: =IF(MOD(E10,B10)/B10>0.5,1,0) -> 0 | X10: =IF(AND(MOD(E10,B10)/B10<=0.5,MOD(E10,B10)<>0),1,0) -> 0 | Y10: =INT(F10/B10) -> 0 | Z10: =IF(MOD(F10,B10)/B10>0.5,1,0) -> 0 | AA10: =IF(AND(MOD(F10,B10)/B10<=0.5,MOD(F10,B10)<>0),1,0) -> 0 | AB10: =INT(G10/B10) -> 0 | AC10: =IF(MOD(G10,B10)/B10>0.5,1,0) -> 0 | AD10: =IF(AND(MOD(G10,B10)/B10<=0.5,MOD(G10,B10)<>0),1,0) -> 0 | AE10: =INT(#REF!/B10) -> #REF! | AF10: =IF(MOD(#REF!,B10)/B10>0.5,1,0) -> #REF! | AG10: =IF(AND(MOD(#REF!,B10)/B10<=0.5,MOD(#REF!,B10)<>0),1,0) -> #REF! | AH10: =INT(H10/B10) -> 0 | AI10: =IF(MOD(H10,B10)/B10>0.5,1,0) -> 0 | AJ10: =IF(AND(MOD(H10,B10)/B10<=0.5,MOD(H10,B10)<>0),1,0) -> 0 | AK10: =INT(I10/B10) -> 0 | AL10: =IF(MOD(I10,B10)/B10>0.5,1,0) -> 0 | AM10: =IF(AND(MOD(I10,B10)/B10<=0.5,MOD(I10,B10)<>0),1,0) -> 0 | AN10: =INT(J10/B10) -> 0 | AO10: =IF(MOD(J10,B10)/B10>0.5,1,0) -> 0 | AP10: =IF(AND(MOD(J10,B10)/B10<=0.5,MOD(J10,B10)<>0),1,0) -> 0 | AQ10: =INT(K10/B10) -> 0 | AR10: =IF(MOD(K10,B10)/B10>0.5,1,0) -> 0 | AS10: =IF(AND(MOD(K10,B10)/B10<=0.5,MOD(K10,B10)<>0),1,0) -> 0
A11: ='บางบัวทอง-ผลิต'!C14 -> องุ่นแดงนอกมีเมล็ด 200 กรัม x 32 P | B11: 32 | C11: =SUMPRODUCT(ROUNDUP(D11:K11/B11, 0)) -> 0 | D11: ='บางบัวทอง-ผลิต'!E14 -> 0 | E11: ='บางบัวทอง-ผลิต'!F14 -> 0 | F11: ='บางบัวทอง-ผลิต'!G14 -> 0 | G11: ='บางบัวทอง-ผลิต'!H14 -> 0 | H11: ='บางบัวทอง-ผลิต'!I14 -> 0 | I11: ='บางบัวทอง-ผลิต'!J14 -> 0 | J11: ='บางบัวทอง-ผลิต'!K14 -> 0 | L11: =INT(SUM(D11:K11)/B11) & " full, " & IF(MOD(SUM(D11:K11), B11)/B11 <= 0.5, "1 less than half", IF(MOD(SUM(D11:K11), B11)/B11 > 0.5, "1 more than half", "")) -> 0 full, 1 less than half | P11: =INT(D11/B11) -> 0 | Q11: =IF(MOD(D11,B11)/B11>0.5,1,0) -> 0 | R11: =IF(AND(MOD(D11,B11)/B11<=0.5,MOD(D11,B11)<>0),1,0) -> 0 | S11: =INT(#REF!/B11) -> #REF! | T11: =IF(MOD(#REF!,B11)/B11>0.5,1,0) -> #REF! | U11: =IF(AND(MOD(#REF!,B11)/B11<=0.5,MOD(#REF!,B11)<>0),1,0) -> #REF! | V11: =INT(E11/B11) -> 0 | W11: =IF(MOD(E11,B11)/B11>0.5,1,0) -> 0 | X11: =IF(AND(MOD(E11,B11)/B11<=0.5,MOD(E11,B11)<>0),1,0) -> 0 | Y11: =INT(F11/B11) -> 0 | Z11: =IF(MOD(F11,B11)/B11>0.5,1,0) -> 0 | AA11: =IF(AND(MOD(F11,B11)/B11<=0.5,MOD(F11,B11)<>0),1,0) -> 0 | AB11: =INT(G11/B11) -> 0 | AC11: =IF(MOD(G11,B11)/B11>0.5,1,0) -> 0 | AD11: =IF(AND(MOD(G11,B11)/B11<=0.5,MOD(G11,B11)<>0),1,0) -> 0 | AE11: =INT(#REF!/B11) -> #REF! | AF11: =IF(MOD(#REF!,B11)/B11>0.5,1,0) -> #REF! | AG11: =IF(AND(MOD(#REF!,B11)/B11<=0.5,MOD(#REF!,B11)<>0),1,0) -> #REF! | AH11: =INT(H11/B11) -> 0 | AI11: =IF(MOD(H11,B11)/B11>0.5,1,0) -> 0 | AJ11: =IF(AND(MOD(H11,B11)/B11<=0.5,MOD(H11,B11)<>0),1,0) -> 0 | AK11: =INT(I11/B11) -> 0 | AL11: =IF(MOD(I11,B11)/B11>0.5,1,0) -> 0 | AM11: =IF(AND(MOD(I11,B11)/B11<=0.5,MOD(I11,B11)<>0),1,0) -> 0 | AN11: =INT(J11/B11) -> 0 | AO11: =IF(MOD(J11,B11)/B11>0.5,1,0) -> 0 | AP11: =IF(AND(MOD(J11,B11)/B11<=0.5,MOD(J11,B11)<>0),1,0) -> 0 | AQ11: =INT(K11/B11) -> 0 | AR11: =IF(MOD(K11,B11)/B11>0.5,1,0) -> 0 | AS11: =IF(AND(MOD(K11,B11)/B11<=0.5,MOD(K11,B11)<>0),1,0) -> 0
A12: ส้มแพ็ก 4 ผล(450 กรัม) x14 P | B12: 14 | C12: =SUMPRODUCT(ROUNDUP(D12:K12/B12, 0)) -> 0 | D12: ='บางบัวทอง-ผลิต'!E16 -> 0 | E12: ='บางบัวทอง-ผลิต'!F16 -> 0 | F12: ='บางบัวทอง-ผลิต'!G16 -> 0 | G12: ='บางบัวทอง-ผลิต'!H16 -> 0 | H12: ='บางบัวทอง-ผลิต'!I16 -> 0 | I12: ='บางบัวทอง-ผลิต'!J16 -> 0 | J12: ='บางบัวทอง-ผลิต'!K16 -> 0
A13: แอปเปิ้ลแพ็ก 4 ผล(400 กรัม) x14 P | B13: 14 | C13: =SUMPRODUCT(ROUNDUP(D13:K13/B13, 0)) -> 0 | D13: ='บางบัวทอง-ผลิต'!E18 -> 0 | E13: ='บางบัวทอง-ผลิต'!F18 -> 0 | F13: ='บางบัวทอง-ผลิต'!G18 -> 0 | G13: ='บางบัวทอง-ผลิต'!H18 -> 0 | H13: ='บางบัวทอง-ผลิต'!I18 -> 0 | I13: ='บางบัวทอง-ผลิต'!J18 -> 0 | J13: ='บางบัวทอง-ผลิต'!K18 -> 0
A14: ='บางบัวทอง-ผลิต'!C20 -> องุ่นแดงไร้เมล็ด150กรัม x 32 Pไข่ปลา | B14: 32 | C14: =SUMPRODUCT(ROUNDUP(D14:K14/B14, 0)) -> 0 | D14: ='บางบัวทอง-ผลิต'!E20 -> 0 | E14: ='บางบัวทอง-ผลิต'!F20 -> 0 | F14: ='บางบัวทอง-ผลิต'!G20 -> 0 | G14: ='บางบัวทอง-ผลิต'!H20 -> 0 | H14: ='บางบัวทอง-ผลิต'!I20 -> 0 | I14: ='บางบัวทอง-ผลิต'!J20 -> 0 | J14: ='บางบัวทอง-ผลิต'!K20 -> 0 | L14: =INT(SUM(D14:K14)/B14) & " full, " & IF(MOD(SUM(D14:K14), B14)/B14 <= 0.5, "1 less than half", IF(MOD(SUM(D14:K14), B14)/B14 > 0.5, "1 more than half", "")) -> 0 full, 1 less than half | P14: =INT(D14/B14) -> 0 | Q14: =IF(MOD(D14,B14)/B14>0.5,1,0) -> 0 | R14: =IF(AND(MOD(D14,B14)/B14<=0.5,MOD(D14,B14)<>0),1,0) -> 0 | S14: =INT(#REF!/B14) -> #REF! | T14: =IF(MOD(#REF!,B14)/B14>0.5,1,0) -> #REF! | U14: =IF(AND(MOD(#REF!,B14)/B14<=0.5,MOD(#REF!,B14)<>0),1,0) -> #REF! | V14: =INT(E14/B14) -> 0 | W14: =IF(MOD(E14,B14)/B14>0.5,1,0) -> 0 | X14: =IF(AND(MOD(E14,B14)/B14<=0.5,MOD(E14,B14)<>0),1,0) -> 0 | Y14: =INT(F14/B14) -> 0 | Z14: =IF(MOD(F14,B14)/B14>0.5,1,0) -> 0 | AA14: =IF(AND(MOD(F14,B14)/B14<=0.5,MOD(F14,B14)<>0),1,0) -> 0 | AB14: =INT(G14/B14) -> 0 | AC14: =IF(MOD(G14,B14)/B14>0.5,1,0) -> 0 | AD14: =IF(AND(MOD(G14,B14)/B14<=0.5,MOD(G14,B14)<>0),1,0) -> 0 | AE14: =INT(#REF!/B14) -> #REF! | AF14: =IF(MOD(#REF!,B14)/B14>0.5,1,0) -> #REF! | AG14: =IF(AND(MOD(#REF!,B14)/B14<=0.5,MOD(#REF!,B14)<>0),1,0) -> #REF! | AH14: =INT(H14/B14) -> 0 | AI14: =IF(MOD(H14,B14)/B14>0.5,1,0) -> 0 | AJ14: =IF(AND(MOD(H14,B14)/B14<=0.5,MOD(H14,B14)<>0),1,0) -> 0 | AK14: =INT(I14/B14) -> 0 | AL14: =IF(MOD(I14,B14)/B14>0.5,1,0) -> 0 | AM14: =IF(AND(MOD(I14,B14)/B14<=0.5,MOD(I14,B14)<>0),1,0) -> 0 | AN14: =INT(J14/B14) -> 0 | AO14: =IF(MOD(J14,B14)/B14>0.5,1,0) -> 0 | AP14: =IF(AND(MOD(J14,B14)/B14<=0.5,MOD(J14,B14)<>0),1,0) -> 0 | AQ14: =INT(K14/B14) -> 0 | AR14: =IF(MOD(K14,B14)/B14>0.5,1,0) -> 0 | AS14: =IF(AND(MOD(K14,B14)/B14<=0.5,MOD(K14,B14)<>0),1,0) -> 0
A15: พุทราจีน 200 กรัม x 27 P | B15: 27 | C15: =SUMPRODUCT(ROUNDUP(D15:K15/B15, 0)) -> 0 | D15: ='บางบัวทอง-ผลิต'!E22 -> 0 | E15: ='บางบัวทอง-ผลิต'!F22 -> 0 | F15: ='บางบัวทอง-ผลิต'!G22 -> 0 | G15: ='บางบัวทอง-ผลิต'!H22 -> 0 | H15: ='บางบัวทอง-ผลิต'!I22 -> 0 | I15: ='บางบัวทอง-ผลิต'!J22 -> 0 | J15: ='บางบัวทอง-ผลิต'!K22 -> 0 | L15: =INT(SUM(D15:K15)/B15) & " full, " & IF(MOD(SUM(D15:K15), B15)/B15 <= 0.5, "1 less than half", IF(MOD(SUM(D15:K15), B15)/B15 > 0.5, "1 more than half", "")) -> 0 full, 1 less than half | P15: =INT(D15/B15) -> 0 | Q15: =IF(MOD(D15,B15)/B15>0.5,1,0) -> 0 | R15: =IF(AND(MOD(D15,B15)/B15<=0.5,MOD(D15,B15)<>0),1,0) -> 0 | S15: =INT(#REF!/B15) -> #REF! | T15: =IF(MOD(#REF!,B15)/B15>0.5,1,0) -> #REF! | U15: =IF(AND(MOD(#REF!,B15)/B15<=0.5,MOD(#REF!,B15)<>0),1,0) -> #REF! | V15: =INT(E15/B15) -> 0 | W15: =IF(MOD(E15,B15)/B15>0.5,1,0) -> 0 | X15: =IF(AND(MOD(E15,B15)/B15<=0.5,MOD(E15,B15)<>0),1,0) -> 0 | Y15: =INT(F15/B15) -> 0 | Z15: =IF(MOD(F15,B15)/B15>0.5,1,0) -> 0 | AA15: =IF(AND(MOD(F15,B15)/B15<=0.5,MOD(F15,B15)<>0),1,0) -> 0 | AB15: =INT(G15/B15) -> 0 | AC15: =IF(MOD(G15,B15)/B15>0.5,1,0) -> 0 | AD15: =IF(AND(MOD(G15,B15)/B15<=0.5,MOD(G15,B15)<>0),1,0) -> 0 | AE15: =INT(#REF!/B15) -> #REF! | AF15: =IF(MOD(#REF!,B15)/B15>0.5,1,0) -> #REF! | AG15: =IF(AND(MOD(#REF!,B15)/B15<=0.5,MOD(#REF!,B15)<>0),1,0) -> #REF! | AH15: =INT(H15/B15) -> 0 | AI15: =IF(MOD(H15,B15)/B15>0.5,1,0) -> 0 | AJ15: =IF(AND(MOD(H15,B15)/B15<=0.5,MOD(H15,B15)<>0),1,0) -> 0 | AK15: =INT(I15/B15) -> 0 | AL15: =IF(MOD(I15,B15)/B15>0.5,1,0) -> 0 | AM15: =IF(AND(MOD(I15,B15)/B15<=0.5,MOD(I15,B15)<>0),1,0) -> 0 | AN15: =INT(J15/B15) -> 0 | AO15: =IF(MOD(J15,B15)/B15>0.5,1,0) -> 0 | AP15: =IF(AND(MOD(J15,B15)/B15<=0.5,MOD(J15,B15)<>0),1,0) -> 0 | AQ15: =INT(K15/B15) -> 0 | AR15: =IF(MOD(K15,B15)/B15>0.5,1,0) -> 0 | AS15: =IF(AND(MOD(K15,B15)/B15<=0.5,MOD(K15,B15)<>0),1,0) -> 0
A16: ='บางบัวทอง-ผลิต'!C24 -> สตรอเบอร์รี่ 250 กรัม x 27 P | B16: 27 | C16: =SUMPRODUCT(ROUNDUP(D16:K16/B16, 0)) -> 0 | D16: ='บางบัวทอง-ผลิต'!E24 -> 0 | E16: ='บางบัวทอง-ผลิต'!F24 -> 0 | F16: ='บางบัวทอง-ผลิต'!G24 -> 0 | G16: ='บางบัวทอง-ผลิต'!H24 -> 0 | H16: ='บางบัวทอง-ผลิต'!I24 -> 0 | I16: ='บางบัวทอง-ผลิต'!J24 -> 0 | J16: ='บางบัวทอง-ผลิต'!K24 -> 0 | L16: =INT(SUM(D16:K16)/B16) & " full, " & IF(MOD(SUM(D16:K16), B16)/B16 <= 0.5, "1 less than half", IF(MOD(SUM(D16:K16), B16)/B16 > 0.5, "1 more than half", "")) -> 0 full, 1 less than half | P16: =INT(D16/B16) -> 0 | Q16: =IF(MOD(D16,B16)/B16>0.5,1,0) -> 0 | R16: =IF(AND(MOD(D16,B16)/B16<=0.5,MOD(D16,B16)<>0),1,0) -> 0 | V16: =INT(E16/B16) -> 0 | W16: =IF(MOD(E16,B16)/B16>0.5,1,0) -> 0 | X16: =IF(AND(MOD(E16,B16)/B16<=0.5,MOD(E16,B16)<>0),1,0) -> 0 | Y16: =INT(F16/B16) -> 0 | Z16: =IF(MOD(F16,B16)/B16>0.5,1,0) -> 0 | AA16: =IF(AND(MOD(F16,B16)/B16<=0.5,MOD(F16,B16)<>0),1,0) -> 0 | AB16: =INT(G16/B16) -> 0 | AC16: =IF(MOD(G16,B16)/B16>0.5,1,0) -> 0 | AD16: =IF(AND(MOD(G16,B16)/B16<=0.5,MOD(G16,B16)<>0),1,0) -> 0 | AH16: =INT(H16/B16) -> 0 | AI16: =IF(MOD(H16,B16)/B16>0.5,1,0) -> 0 | AJ16: =IF(AND(MOD(H16,B16)/B16<=0.5,MOD(H16,B16)<>0),1,0) -> 0 | AK16: =INT(I16/B16) -> 0 | AL16: =IF(MOD(I16,B16)/B16>0.5,1,0) -> 0 | AM16: =IF(AND(MOD(I16,B16)/B16<=0.5,MOD(I16,B16)<>0),1,0) -> 0 | AN16: =INT(J16/B16) -> 0 | AO16: =IF(MOD(J16,B16)/B16>0.5,1,0) -> 0 | AP16: =IF(AND(MOD(J16,B16)/B16<=0.5,MOD(J16,B16)<>0),1,0) -> 0 | AQ16: =INT(K16/B16) -> 0 | AR16: =IF(MOD(K16,B16)/B16>0.5,1,0) -> 0 | AS16: =IF(AND(MOD(K16,B16)/B16<=0.5,MOD(K16,B16)<>0),1,0) -> 0
A17: ='บางบัวทอง-ผลิต'!C26 -> บลูเบอร์รี่ 125 กรัม x 36 P | B17: 36 | C17: =SUMPRODUCT(ROUNDUP(D17:K17/B17, 0)) -> 0 | D17: ='บางบัวทอง-ผลิต'!E26 -> 0 | E17: ='บางบัวทอง-ผลิต'!F26 -> 0 | F17: ='บางบัวทอง-ผลิต'!G26 -> 0 | G17: ='บางบัวทอง-ผลิต'!H26 -> 0 | H17: ='บางบัวทอง-ผลิต'!I26 -> 0 | I17: ='บางบัวทอง-ผลิต'!J26 -> 0 | J17: ='บางบัวทอง-ผลิต'!K26 -> 0 | L17: =INT(SUM(D17:K17)/B17) & " full, " & IF(MOD(SUM(D17:K17), B17)/B17 <= 0.5, "1 less than half", IF(MOD(SUM(D17:K17), B17)/B17 > 0.5, "1 more than half", "")) -> 0 full, 1 less than half | P17: =INT(D17/B17) -> 0 | Q17: =IF(MOD(D17,B17)/B17>0.5,1,0) -> 0 | R17: =IF(AND(MOD(D17,B17)/B17<=0.5,MOD(D17,B17)<>0),1,0) -> 0 | S17: =INT(#REF!/B17) -> #REF! | T17: =IF(MOD(#REF!,B17)/B17>0.5,1,0) -> #REF! | U17: =IF(AND(MOD(#REF!,B17)/B17<=0.5,MOD(#REF!,B17)<>0),1,0) -> #REF! | V17: =INT(E17/B17) -> 0 | W17: =IF(MOD(E17,B17)/B17>0.5,1,0) -> 0 | X17: =IF(AND(MOD(E17,B17)/B17<=0.5,MOD(E17,B17)<>0),1,0) -> 0 | Y17: =INT(F17/B17) -> 0 | Z17: =IF(MOD(F17,B17)/B17>0.5,1,0) -> 0 | AA17: =IF(AND(MOD(F17,B17)/B17<=0.5,MOD(F17,B17)<>0),1,0) -> 0 | AB17: =INT(G17/B17) -> 0 | AC17: =IF(MOD(G17,B17)/B17>0.5,1,0) -> 0 | AD17: =IF(AND(MOD(G17,B17)/B17<=0.5,MOD(G17,B17)<>0),1,0) -> 0 | AE17: =INT(#REF!/B17) -> #REF! | AF17: =IF(MOD(#REF!,B17)/B17>0.5,1,0) -> #REF! | AG17: =IF(AND(MOD(#REF!,B17)/B17<=0.5,MOD(#REF!,B17)<>0),1,0) -> #REF! | AH17: =INT(H17/B17) -> 0 | AI17: =IF(MOD(H17,B17)/B17>0.5,1,0) -> 0 | AJ17: =IF(AND(MOD(H17,B17)/B17<=0.5,MOD(H17,B17)<>0),1,0) -> 0 | AK17: =INT(I17/B17) -> 0 | AL17: =IF(MOD(I17,B17)/B17>0.5,1,0) -> 0 | AM17: =IF(AND(MOD(I17,B17)/B17<=0.5,MOD(I17,B17)<>0),1,0) -> 0 | AN17: =INT(J17/B17) -> 0 | AO17: =IF(MOD(J17,B17)/B17>0.5,1,0) -> 0 | AP17: =IF(AND(MOD(J17,B17)/B17<=0.5,MOD(J17,B17)<>0),1,0) -> 0 | AQ17: =INT(K17/B17) -> 0 | AR17: =IF(MOD(K17,B17)/B17>0.5,1,0) -> 0 | AS17: =IF(AND(MOD(K17,B17)/B17<=0.5,MOD(K17,B17)<>0),1,0) -> 0
A18: ='บางบัวทอง-ผลิต'!C28 -> องุ่นดำไร้เมล็ด 300 กรัม x20P | B18: 20 | C18: {=SUMPRODUCT(ROUNDUP(D18:K18/B18, 0))} -> 0 | D18: ='บางบัวทอง-ผลิต'!E28 -> 0 | E18: ='บางบัวทอง-ผลิต'!F28 -> 0 | F18: ='บางบัวทอง-ผลิต'!G28 -> 0 | G18: ='บางบัวทอง-ผลิต'!H28 -> 0 | H18: ='บางบัวทอง-ผลิต'!I28 -> 0 | I18: ='บางบัวทอง-ผลิต'!J28 -> 0 | J18: ='บางบัวทอง-ผลิต'!K28 -> 0 | L18: =INT(SUM(D18:K18)/B18) & " full, " & IF(MOD(SUM(D18:K18), B18)/B18 <= 0.5, "1 less than half", IF(MOD(SUM(D18:K18), B18)/B18 > 0.5, "1 more than half", "")) -> 0 full, 1 less than half | P18: =INT(D18/B18) -> 0 | Q18: =IF(MOD(D18,B18)/B18>0.5,1,0) -> 0 | R18: =IF(AND(MOD(D18,B18)/B18<=0.5,MOD(D18,B18)<>0),1,0) -> 0 | S18: =INT(#REF!/B18) -> #REF! | T18: =IF(MOD(#REF!,B18)/B18>0.5,1,0) -> #REF! | U18: =IF(AND(MOD(#REF!,B18)/B18<=0.5,MOD(#REF!,B18)<>0),1,0) -> #REF! | V18: =INT(E18/B18) -> 0 | W18: =IF(MOD(E18,B18)/B18>0.5,1,0) -> 0 | X18: =IF(AND(MOD(E18,B18)/B18<=0.5,MOD(E18,B18)<>0),1,0) -> 0 | Y18: =INT(F18/B18) -> 0 | Z18: =IF(MOD(F18,B18)/B18>0.5,1,0) -> 0 | AA18: =IF(AND(MOD(F18,B18)/B18<=0.5,MOD(F18,B18)<>0),1,0) -> 0 | AB18: =INT(G18/B18) -> 0 | AC18: =IF(MOD(G18,B18)/B18>0.5,1,0) -> 0 | AD18: =IF(AND(MOD(G18,B18)/B18<=0.5,MOD(G18,B18)<>0),1,0) -> 0 | AE18: =INT(#REF!/B18) -> #REF! | AF18: =IF(MOD(#REF!,B18)/B18>0.5,1,0) -> #REF! | AG18: =IF(AND(MOD(#REF!,B18)/B18<=0.5,MOD(#REF!,B18)<>0),1,0) -> #REF! | AH18: =INT(H18/B18) -> 0 | AI18: =IF(MOD(H18,B18)/B18>0.5,1,0) -> 0 | AJ18: =IF(AND(MOD(H18,B18)/B18<=0.5,MOD(H18,B18)<>0),1,0) -> 0 | AK18: =INT(I18/B18) -> 0 | AL18: =IF(MOD(I18,B18)/B18>0.5,1,0) -> 0 | AM18: =IF(AND(MOD(I18,B18)/B18<=0.5,MOD(I18,B18)<>0),1,0) -> 0 | AN18: =INT(J18/B18) -> 0 | AO18: =IF(MOD(J18,B18)/B18>0.5,1,0) -> 0 | AP18: =IF(AND(MOD(J18,B18)/B18<=0.5,MOD(J18,B18)<>0),1,0) -> 0 | AQ18: =INT(K18/B18) -> 0 | AR18: =IF(MOD(K18,B18)/B18>0.5,1,0) -> 0 | AS18: =IF(AND(MOD(K18,B18)/B18<=0.5,MOD(K18,B18)<>0),1,0) -> 0
A19: องุ่นไซน์มัสแคท 300 กรัม x 15 P | B19: 15 | C19: {=SUMPRODUCT(ROUNDUP(D19:K19/B19, 0))} -> 0 | D19: ='บางบัวทอง-ผลิต'!E30 -> 0 | E19: ='บางบัวทอง-ผลิต'!F30 -> 0 | F19: ='บางบัวทอง-ผลิต'!G30 -> 0 | G19: ='บางบัวทอง-ผลิต'!H30 -> 0 | H19: ='บางบัวทอง-ผลิต'!I30 -> 0 | I19: ='บางบัวทอง-ผลิต'!J30 -> 0 | J19: ='บางบัวทอง-ผลิต'!K30 -> 0 | AQ19: =INT(K19/B19) -> 0 | AR19: =IF(MOD(K19,B19)/B19>0.5,1,0) -> 0 | AS19: =IF(AND(MOD(K19,B19)/B19<=0.5,MOD(K19,B19)<>0),1,0) -> 0
A20: ='บางบัวทอง-ผลิต'!C32 -> แอปเปิ้ลแดงวอชิงตันลูกเดี่ยว x 45 P | B20: 45 | C20: {=SUMPRODUCT(ROUNDUP(D20:K20/B20, 0))} -> 0 | D20: ='บางบัวทอง-ผลิต'!E32 -> 0 | E20: ='บางบัวทอง-ผลิต'!F32 -> 0 | F20: ='บางบัวทอง-ผลิต'!G32 -> 0 | G20: ='บางบัวทอง-ผลิต'!H32 -> 0 | H20: ='บางบัวทอง-ผลิต'!I32 -> 0 | I20: ='บางบัวทอง-ผลิต'!J32 -> 0 | J20: ='บางบัวทอง-ผลิต'!K32 -> 0 | L20: =INT(SUM(D20:K20)/B20) & " full, " & IF(MOD(SUM(D20:K20), B20)/B20 <= 0.5, "1 less than half", IF(MOD(SUM(D20:K20), B20)/B20 > 0.5, "1 more than half", "")) -> 0 full, 1 less than half | P20: =INT(D20/B20) -> 0 | Q20: =IF(MOD(D20,B20)/B20>0.5,1,0) -> 0 | R20: =IF(AND(MOD(D20,B20)/B20<=0.5,MOD(D20,B20)<>0),1,0) -> 0 | S20: =INT(#REF!/B20) -> #REF! | T20: =IF(MOD(#REF!,B20)/B20>0.5,1,0) -> #REF! | U20: =IF(AND(MOD(#REF!,B20)/B20<=0.5,MOD(#REF!,B20)<>0),1,0) -> #REF! | V20: =INT(E20/B20) -> 0 | W20: =IF(MOD(E20,B20)/B20>0.5,1,0) -> 0 | X20: =IF(AND(MOD(E20,B20)/B20<=0.5,MOD(E20,B20)<>0),1,0) -> 0 | Y20: =INT(F20/B20) -> 0 | Z20: =IF(MOD(F20,B20)/B20>0.5,1,0) -> 0 | AA20: =IF(AND(MOD(F20,B20)/B20<=0.5,MOD(F20,B20)<>0),1,0) -> 0 | AB20: =INT(G20/B20) -> 0 | AC20: =IF(MOD(G20,B20)/B20>0.5,1,0) -> 0 | AD20: =IF(AND(MOD(G20,B20)/B20<=0.5,MOD(G20,B20)<>0),1,0) -> 0 | AE20: =INT(#REF!/B20) -> #REF! | AF20: =IF(MOD(#REF!,B20)/B20>0.5,1,0) -> #REF! | AG20: =IF(AND(MOD(#REF!,B20)/B20<=0.5,MOD(#REF!,B20)<>0),1,0) -> #REF! | AH20: =INT(H20/B20) -> 0 | AI20: =IF(MOD(H20,B20)/B20>0.5,1,0) -> 0 | AJ20: =IF(AND(MOD(H20,B20)/B20<=0.5,MOD(H20,B20)<>0),1,0) -> 0 | AK20: =INT(I20/B20) -> 0 | AL20: =IF(MOD(I20,B20)/B20>0.5,1,0) -> 0 | AM20: =IF(AND(MOD(I20,B20)/B20<=0.5,MOD(I20,B20)<>0),1,0) -> 0 | AN20: =INT(J20/B20) -> 0 | AO20: =IF(MOD(J20,B20)/B20>0.5,1,0) -> 0 | AP20: =IF(AND(MOD(J20,B20)/B20<=0.5,MOD(J20,B20)<>0),1,0) -> 0 | AQ20: =INT(K20/B20) -> 0 | AR20: =IF(MOD(K20,B20)/B20>0.5,1,0) -> 0 | AS20: =IF(AND(MOD(K20,B20)/B20<=0.5,MOD(K20,B20)<>0),1,0) -> 0
A21: องุ่นสวีทแซฟไฟร์ 300 กรัม x 15 P | B21: 15 | C21: {=SUMPRODUCT(ROUNDUP(D21:K21/B21, 0))} -> 0 | D21: ='บางบัวทอง-ผลิต'!E34 -> 0 | E21: ='บางบัวทอง-ผลิต'!F34 -> 0 | F21: ='บางบัวทอง-ผลิต'!G34 -> 0 | G21: ='บางบัวทอง-ผลิต'!H34 -> 0 | H21: ='บางบัวทอง-ผลิต'!I34 -> 0 | I21: ='บางบัวทอง-ผลิต'!J34 -> 0 | J21: ='บางบัวทอง-ผลิต'!K34 -> 0 | L21: =INT(SUM(D21:K21)/B21) & " full, " & IF(MOD(SUM(D21:K21), B21)/B21 <= 0.5, "1 less than half", IF(MOD(SUM(D21:K21), B21)/B21 > 0.5, "1 more than half", "")) -> 0 full, 1 less than half | P21: =INT(D21/B21) -> 0 | Q21: =IF(MOD(D21,B21)/B21>0.5,1,0) -> 0 | R21: =IF(AND(MOD(D21,B21)/B21<=0.5,MOD(D21,B21)<>0),1,0) -> 0 | S21: =INT(#REF!/B21) -> #REF! | T21: =IF(MOD(#REF!,B21)/B21>0.5,1,0) -> #REF! | U21: =IF(AND(MOD(#REF!,B21)/B21<=0.5,MOD(#REF!,B21)<>0),1,0) -> #REF! | V21: =INT(E21/B21) -> 0 | W21: =IF(MOD(E21,B21)/B21>0.5,1,0) -> 0 | X21: =IF(AND(MOD(E21,B21)/B21<=0.5,MOD(E21,B21)<>0),1,0) -> 0 | Y21: =INT(F21/B21) -> 0 | Z21: =IF(MOD(F21,B21)/B21>0.5,1,0) -> 0 | AA21: =IF(AND(MOD(F21,B21)/B21<=0.5,MOD(F21,B21)<>0),1,0) -> 0 | AB21: =INT(G21/B21) -> 0 | AC21: =IF(MOD(G21,B21)/B21>0.5,1,0) -> 0 | AD21: =IF(AND(MOD(G21,B21)/B21<=0.5,MOD(G21,B21)<>0),1,0) -> 0 | AE21: =INT(#REF!/B21) -> #REF! | AF21: =IF(MOD(#REF!,B21)/B21>0.5,1,0) -> #REF! | AG21: =IF(AND(MOD(#REF!,B21)/B21<=0.5,MOD(#REF!,B21)<>0),1,0) -> #REF! | AH21: =INT(H21/B21) -> 0 | AI21: =IF(MOD(H21,B21)/B21>0.5,1,0) -> 0 | AJ21: =IF(AND(MOD(H21,B21)/B21<=0.5,MOD(H21,B21)<>0),1,0) -> 0 | AK21: =INT(I21/B21) -> 0 | AL21: =IF(MOD(I21,B21)/B21>0.5,1,0) -> 0 | AM21: =IF(AND(MOD(I21,B21)/B21<=0.5,MOD(I21,B21)<>0),1,0) -> 0 | AN21: =INT(J21/B21) -> 0 | AO21: =IF(MOD(J21,B21)/B21>0.5,1,0) -> 0 | AP21: =IF(AND(MOD(J21,B21)/B21<=0.5,MOD(J21,B21)<>0),1,0) -> 0 | AQ21: =INT(K21/B21) -> 0 | AR21: =IF(MOD(K21,B21)/B21>0.5,1,0) -> 0 | AS21: =IF(AND(MOD(K21,B21)/B21<=0.5,MOD(K21,B21)<>0),1,0) -> 0
A22: ='บางบัวทอง-ผลิต'!C36 -> แอปเปิ้ลเจ้าหญิง 200 g. x 27 p | B22: 27 | C22: {=SUMPRODUCT(ROUNDUP(D22:K22/B22, 0))} -> 0 | D22: ='บางบัวทอง-ผลิต'!E36 -> 0 | E22: ='บางบัวทอง-ผลิต'!F36 -> 0 | F22: ='บางบัวทอง-ผลิต'!G36 -> 0 | G22: ='บางบัวทอง-ผลิต'!H36 -> 0 | H22: ='บางบัวทอง-ผลิต'!I36 -> 0 | I22: ='บางบัวทอง-ผลิต'!J36 -> 0 | J22: ='บางบัวทอง-ผลิต'!K36 -> 0 | L22: =INT(SUM(D22:K22)/B22) & " full, " & IF(MOD(SUM(D22:K22), B22)/B22 <= 0.5, "1 less than half", IF(MOD(SUM(D22:K22), B22)/B22 > 0.5, "1 more than half", "")) -> 0 full, 1 less than half | P22: =INT(D22/B22) -> 0 | Q22: =IF(MOD(D22,B22)/B22>0.5,1,0) -> 0 | R22: =IF(AND(MOD(D22,B22)/B22<=0.5,MOD(D22,B22)<>0),1,0) -> 0 | V22: =INT(E22/B22) -> 0 | W22: =IF(MOD(E22,B22)/B22>0.5,1,0) -> 0 | X22: =IF(AND(MOD(E22,B22)/B22<=0.5,MOD(E22,B22)<>0),1,0) -> 0 | Y22: =INT(F22/B22) -> 0 | Z22: =IF(MOD(F22,B22)/B22>0.5,1,0) -> 0 | AA22: =IF(AND(MOD(F22,B22)/B22<=0.5,MOD(F22,B22)<>0),1,0) -> 0 | AB22: =INT(G22/B22) -> 0 | AC22: =IF(MOD(G22,B22)/B22>0.5,1,0) -> 0 | AD22: =IF(AND(MOD(G22,B22)/B22<=0.5,MOD(G22,B22)<>0),1,0) -> 0 | AH22: =INT(H22/B22) -> 0 | AI22: =IF(MOD(H22,B22)/B22>0.5,1,0) -> 0 | AJ22: =IF(AND(MOD(H22,B22)/B22<=0.5,MOD(H22,B22)<>0),1,0) -> 0 | AK22: =INT(I22/B22) -> 0 | AL22: =IF(MOD(I22,B22)/B22>0.5,1,0) -> 0 | AM22: =IF(AND(MOD(I22,B22)/B22<=0.5,MOD(I22,B22)<>0),1,0) -> 0 | AN22: =INT(J22/B22) -> 0 | AO22: =IF(MOD(J22,B22)/B22>0.5,1,0) -> 0 | AP22: =IF(AND(MOD(J22,B22)/B22<=0.5,MOD(J22,B22)<>0),1,0) -> 0 | AQ22: =INT(K22/B22) -> 0 | AR22: =IF(MOD(K22,B22)/B22>0.5,1,0) -> 0 | AS22: =IF(AND(MOD(K22,B22)/B22<=0.5,MOD(K22,B22)<>0),1,0) -> 0
A23: องุ่นเคียวโฮ 300 กรัม x 15 P | B23: 15 | C23: {=SUMPRODUCT(ROUNDUP(D23:K23/B23, 0))} -> 0 | D23: ='บางบัวทอง-ผลิต'!E38 -> 0 | E23: ='บางบัวทอง-ผลิต'!F38 -> 0 | F23: ='บางบัวทอง-ผลิต'!G38 -> 0 | G23: ='บางบัวทอง-ผลิต'!H38 -> 0 | H23: ='บางบัวทอง-ผลิต'!I38 -> 0 | I23: ='บางบัวทอง-ผลิต'!J38 -> 0 | J23: ='บางบัวทอง-ผลิต'!K38 -> 0 | AQ23: =INT(K23/B23) -> 0 | AR23: =IF(MOD(K23,B23)/B23>0.5,1,0) -> 0 | AS23: =IF(AND(MOD(K23,B23)/B23<=0.5,MOD(K23,B23)<>0),1,0) -> 0
A24: ='บางบัวทอง-ผลิต'!C40 -> ลูกไหนจิ๋ว 200 g. x 27 p | B24: 27 | C24: {=SUMPRODUCT(ROUNDUP(D24:K24/B24, 0))} -> 0 | D24: ='บางบัวทอง-ผลิต'!E40 -> 0 | E24: ='บางบัวทอง-ผลิต'!F40 -> 0 | F24: ='บางบัวทอง-ผลิต'!G40 -> 0 | G24: ='บางบัวทอง-ผลิต'!H40 -> 0 | H24: ='บางบัวทอง-ผลิต'!I40 -> 0 | I24: ='บางบัวทอง-ผลิต'!J40 -> 0 | J24: ='บางบัวทอง-ผลิต'!K40 -> 0 | L24: =INT(SUM(D24:K24)/B24) & " full, " & IF(MOD(SUM(D24:K24), B24)/B24 <= 0.5, "1 less than half", IF(MOD(SUM(D24:K24), B24)/B24 > 0.5, "1 more than half", "")) -> 0 full, 1 less than half | P24: =INT(D24/B24) -> 0 | Q24: =IF(MOD(D24,B24)/B24>0.5,1,0) -> 0 | R24: =IF(AND(MOD(D24,B24)/B24<=0.5,MOD(D24,B24)<>0),1,0) -> 0 | V24: =INT(E24/B24) -> 0 | W24: =IF(MOD(E24,B24)/B24>0.5,1,0) -> 0 | X24: =IF(AND(MOD(E24,B24)/B24<=0.5,MOD(E24,B24)<>0),1,0) -> 0 | Y24: =INT(F24/B24) -> 0 | Z24: =IF(MOD(F24,B24)/B24>0.5,1,0) -> 0 | AA24: =IF(AND(MOD(F24,B24)/B24<=0.5,MOD(F24,B24)<>0),1,0) -> 0 | AB24: =INT(G24/B24) -> 0 | AC24: =IF(MOD(G24,B24)/B24>0.5,1,0) -> 0 | AD24: =IF(AND(MOD(G24,B24)/B24<=0.5,MOD(G24,B24)<>0),1,0) -> 0 | AH24: =INT(H24/B24) -> 0 | AI24: =IF(MOD(H24,B24)/B24>0.5,1,0) -> 0 | AJ24: =IF(AND(MOD(H24,B24)/B24<=0.5,MOD(H24,B24)<>0),1,0) -> 0 | AK24: =INT(I24/B24) -> 0 | AL24: =IF(MOD(I24,B24)/B24>0.5,1,0) -> 0 | AM24: =IF(AND(MOD(I24,B24)/B24<=0.5,MOD(I24,B24)<>0),1,0) -> 0 | AN24: =INT(J24/B24) -> 0 | AO24: =IF(MOD(J24,B24)/B24>0.5,1,0) -> 0 | AP24: =IF(AND(MOD(J24,B24)/B24<=0.5,MOD(J24,B24)<>0),1,0) -> 0 | AQ24: =INT(K24/B24) -> 0 | AR24: =IF(MOD(K24,B24)/B24>0.5,1,0) -> 0 | AS24: =IF(AND(MOD(K24,B24)/B24<=0.5,MOD(K24,B24)<>0),1,0) -> 0
A25: องุ่นแดงไร้เมล็ด 300 g. x 20 p | B25: 20 | C25: {=SUMPRODUCT(ROUNDUP(D25:K25/B25, 0))} -> 0 | D25: ='บางบัวทอง-ผลิต'!E42 -> 0 | E25: ='บางบัวทอง-ผลิต'!F42 -> 0 | F25: ='บางบัวทอง-ผลิต'!G42 -> 0 | G25: ='บางบัวทอง-ผลิต'!H42 -> 0 | H25: ='บางบัวทอง-ผลิต'!I42 -> 0 | I25: ='บางบัวทอง-ผลิต'!J42 -> 0 | J25: ='บางบัวทอง-ผลิต'!K42 -> 0 | L25: =INT(SUM(D25:K25)/B25) & " full, " & IF(MOD(SUM(D25:K25), B25)/B25 <= 0.5, "1 less than half", IF(MOD(SUM(D25:K25), B25)/B25 > 0.5, "1 more than half", "")) -> 0 full, 1 less than half | P25: =INT(D25/B25) -> 0 | Q25: =IF(MOD(D25,B25)/B25>0.5,1,0) -> 0 | R25: =IF(AND(MOD(D25,B25)/B25<=0.5,MOD(D25,B25)<>0),1,0) -> 0 | V25: =INT(E25/B25) -> 0 | W25: =IF(MOD(E25,B25)/B25>0.5,1,0) -> 0 | X25: =IF(AND(MOD(E25,B25)/B25<=0.5,MOD(E25,B25)<>0),1,0) -> 0 | Y25: =INT(F25/B25) -> 0 | Z25: =IF(MOD(F25,B25)/B25>0.5,1,0) -> 0 | AA25: =IF(AND(MOD(F25,B25)/B25<=0.5,MOD(F25,B25)<>0),1,0) -> 0 | AB25: =INT(G25/B25) -> 0 | AC25: =IF(MOD(G25,B25)/B25>0.5,1,0) -> 0 | AD25: =IF(AND(MOD(G25,B25)/B25<=0.5,MOD(G25,B25)<>0),1,0) -> 0 | AH25: =INT(H25/B25) -> 0 | AI25: =IF(MOD(H25,B25)/B25>0.5,1,0) -> 0 | AJ25: =IF(AND(MOD(H25,B25)/B25<=0.5,MOD(H25,B25)<>0),1,0) -> 0 | AK25: =INT(I25/B25) -> 0 | AL25: =IF(MOD(I25,B25)/B25>0.5,1,0) -> 0 | AM25: =IF(AND(MOD(I25,B25)/B25<=0.5,MOD(I25,B25)<>0),1,0) -> 0 | AN25: =INT(J25/B25) -> 0 | AO25: =IF(MOD(J25,B25)/B25>0.5,1,0) -> 0 | AP25: =IF(AND(MOD(J25,B25)/B25<=0.5,MOD(J25,B25)<>0),1,0) -> 0 | AQ25: =INT(K25/B25) -> 0 | AR25: =IF(MOD(K25,B25)/B25>0.5,1,0) -> 0 | AS25: =IF(AND(MOD(K25,B25)/B25<=0.5,MOD(K25,B25)<>0),1,0) -> 0
A26: เบอร์รี่ดูโอ้ 160 กรัม x 32 P | B26: 32 | C26: {=SUMPRODUCT(ROUNDUP(D26:K26/B26, 0))} -> 0 | D26: ='บางบัวทอง-ผลิต'!E44 -> 0 | E26: ='บางบัวทอง-ผลิต'!F44 -> 0 | F26: ='บางบัวทอง-ผลิต'!G44 -> 0 | G26: ='บางบัวทอง-ผลิต'!H44 -> 0 | H26: ='บางบัวทอง-ผลิต'!I44 -> 0 | I26: ='บางบัวทอง-ผลิต'!J44 -> 0 | J26: ='บางบัวทอง-ผลิต'!K44 -> 0 | L26: =INT(SUM(D26:K26)/B26) & " full, " & IF(MOD(SUM(D26:K26), B26)/B26 <= 0.5, "1 less than half", IF(MOD(SUM(D26:K26), B26)/B26 > 0.5, "1 more than half", "")) -> 0 full, 1 less than half | P26: =INT(D26/B26) -> 0 | Q26: =IF(MOD(D26,B26)/B26>0.5,1,0) -> 0 | R26: =IF(AND(MOD(D26,B26)/B26<=0.5,MOD(D26,B26)<>0),1,0) -> 0 | V26: =INT(E26/B26) -> 0 | W26: =IF(MOD(E26,B26)/B26>0.5,1,0) -> 0 | X26: =IF(AND(MOD(E26,B26)/B26<=0.5,MOD(E26,B26)<>0),1,0) -> 0 | Y26: =INT(F26/B26) -> 0 | Z26: =IF(MOD(F26,B26)/B26>0.5,1,0) -> 0 | AA26: =IF(AND(MOD(F26,B26)/B26<=0.5,MOD(F26,B26)<>0),1,0) -> 0 | AB26: =INT(G26/B26) -> 0 | AC26: =IF(MOD(G26,B26)/B26>0.5,1,0) -> 0 | AD26: =IF(AND(MOD(G26,B26)/B26<=0.5,MOD(G26,B26)<>0),1,0) -> 0 | AH26: =INT(H26/B26) -> 0 | AI26: =IF(MOD(H26,B26)/B26>0.5,1,0) -> 0 | AJ26: =IF(AND(MOD(H26,B26)/B26<=0.5,MOD(H26,B26)<>0),1,0) -> 0 | AK26: =INT(I26/B26) -> 0 | AL26: =IF(MOD(I26,B26)/B26>0.5,1,0) -> 0 | AM26: =IF(AND(MOD(I26,B26)/B26<=0.5,MOD(I26,B26)<>0),1,0) -> 0 | AN26: =INT(J26/B26) -> 0 | AO26: =IF(MOD(J26,B26)/B26>0.5,1,0) -> 0 | AP26: =IF(AND(MOD(J26,B26)/B26<=0.5,MOD(J26,B26)<>0),1,0) -> 0 | AQ26: =INT(K26/B26) -> 0 | AR26: =IF(MOD(K26,B26)/B26>0.5,1,0) -> 0 | AS26: =IF(AND(MOD(K26,B26)/B26<=0.5,MOD(K26,B26)<>0),1,0) -> 0
A27: สาลี่ทอง แพ็ก 2 ผล (400g.) x 15 P | B27: 15 | C27: {=SUMPRODUCT(ROUNDUP(D27:K27/B27, 0))} -> 0 | D27: ='บางบัวทอง-ผลิต'!E46 -> 0 | E27: ='บางบัวทอง-ผลิต'!F46 -> 0 | F27: ='บางบัวทอง-ผลิต'!G46 -> 0 | G27: ='บางบัวทอง-ผลิต'!H46 -> 0 | H27: ='บางบัวทอง-ผลิต'!I46 -> 0 | I27: ='บางบัวทอง-ผลิต'!J46 -> 0 | J27: ='บางบัวทอง-ผลิต'!K46 -> 0
A28: สาลี่ทอง แพ็ก 2 ผล (400g.) x 8 P | B28: 8 | C28: {=SUMPRODUCT(ROUNDUP(D28:K28/B28, 0))} -> 0 | D28: ='บางบัวทอง-ผลิต'!E48 -> 0 | E28: ='บางบัวทอง-ผลิต'!F48 -> 0 | F28: ='บางบัวทอง-ผลิต'!G48 -> 0 | G28: ='บางบัวทอง-ผลิต'!H48 -> 0 | H28: ='บางบัวทอง-ผลิต'!I48 -> 0 | I28: ='บางบัวทอง-ผลิต'!J48 -> 0 | J28: ='บางบัวทอง-ผลิต'!K48 -> 0
A29: รวม | C29: =SUM(C10:C28) -> 0 | D29: =SUM(D30:D32)*-1 -> 0 | E29: =SUM(E30:E32)*-1 -> 0 | F29: =SUM(F30:F32)*-1 -> 0 | G29: =SUM(G30:G32)*-1 -> 0 | H29: =SUM(H30:H32)*-1 -> 0 | I29: =SUM(I30:I32)*-1 -> 0 | J29: =SUM(J30:J32)*-1 -> 0
A30: ตะกร้าเต็ม | D30: =SUM(P10:P20) -> 0 | E30: =SUM(V10:V20) -> 0 | F30: =SUM(Y10:Y20) -> 0 | G30: =SUM(AB10:AB20) -> 0 | H30: =SUM(AH10:AH20) -> 0 | I30: =SUM(AK10:AK20) -> 0
A31: เกินครึ่งตะกร้า | D31: =SUM(Q10:Q20) -> 0 | E31: =SUM(W10:W20) -> 0 | F31: =SUM(Z10:Z20) -> 0 | G31: =SUM(AC10:AC20) -> 0 | H31: =SUM(AI10:AI20) -> 0 | I31: =SUM(AL10:AL20) -> 0
A32: น้อยกว่าหรือเท่ากับครึ่งตะกร้า | D32: =SUM(R10:R20) -> 0 | E32: =SUM(X10:X20) -> 0 | F32: =SUM(AA10:AA20) -> 0 | G32: =SUM(AD10:AD20) -> 0 | H32: =SUM(AJ10:AJ20) -> 0 | I32: =SUM(AM10:AM20) -> 0
A35: 4 ล้อ โกลบอล | B35: ตะกร้าเต็ม | C35: 134 | D35: =IF(C35=0, 0, ((SUM(D30:K30)+SUM(D31:K31))/C35)*100) -> 0
B36: ตะกร้าซ้อน | C36: 242 | D36: =IF(C36=0, 0, ((SUM(D32:K32))/C36)*100) -> 0
B37: พื้นที่ที่ต้องใช้ | D37: =D35+D36 -> 0
B38: พื้นที่รถ | D38: 100
B39: จำนวนรถที่ต้องใช้ | D39: =CEILING(D37 /D38, 1) -> 0
A40: 4 ล้อ รถนอก (จัมโบ้) | B40: ตะกร้าเต็ม | C40: 154 | D40: =IF(C40=0, 0, ((SUM(D30:K30)+SUM(D31:K31))/C40)*100) -> 0
B41: ตะกร้าซ้อน | C41: 278 | D41: =IF(C41=0, 0, ((SUM(D32:K32))/C41)*100) -> 0
B42: พื้นที่ที่ต้องใช้ | D42: =D40+D41 -> 0
B43: พื้นที่รถ | D43: 100
B44: จำนวนรถที่ต้องใช้ | D44: =CEILING(D42 /D43, 1) -> 0
...

Sheet คันที่ 1
A5: ผู้ส่ง : 6 ล้อ 77 พี่ปาม | D5: บางบัวทอง
A7: เซเว่น BBT | C7: บรรจุ/ตก. | D7: ผลิตวันที่ 16/10/68 ส่งวันที่ PO 17/10/68 | I7: ยอดรวม
D9: 22.00.-22.30 น. | F9: 20.00-20.30 น | G9: 19.00-19.30 น
D10: ชลุบรี | F10: นครสวรรค์ | G10: นครราชสีมา
D11: PO 1 | E11: PO 2 | F11: PO1 | G11: PO 1 | H11: PO 2 | I11: แพค | J11: ตะกร้า
A12: 1 | B12: องุ่นแดงนอกมีเมล็ด 200 กรัม x 32 P | C12: 32 | D12: 922 | E12: 883 | F12: 873 | G12: 313 | H12: 322 | I12: =SUM(D12:H12) -> 3313 | J12: 106
D13: =IF(D12=0, "", IF(MOD(D12, $C$12) = 0, D12 / $C$12, IF(INT(D12 / $C$12) = 0, MOD(D12, $C$12) & " P", INT(D12 / $C$12) & " + " & MOD(D12, $C$12) & " P"))) -> 28 + 26 P | E13: =IF(E12=0, "", IF(MOD(E12, $C$12) = 0, E12 / $C$12, IF(INT(E12 / $C$12) = 0, MOD(E12, $C$12) & " P", INT(E12 / $C$12) & " + " & MOD(E12, $C$12) & " P"))) -> 27 + 19 P | F13: =IF(F12=0, "", IF(MOD(F12, $C$12) = 0, F12 / $C$12, IF(INT(F12 / $C$12) = 0, MOD(F12, $C$12) & " P", INT(F12 / $C$12) & " + " & MOD(F12, $C$12) & " P"))) -> 27 + 9 P | G13: =IF(G12=0, "", IF(MOD(G12, $C$12) = 0, G12 / $C$12, IF(INT(G12 / $C$12) = 0, MOD(G12, $C$12) & " P", INT(G12 / $C$12) & " + " & MOD(G12, $C$12) & " P"))) -> 9 + 25 P | H13: =IF(H12=0, "", IF(MOD(H12, $C$12) = 0, H12 / $C$12, IF(INT(H12 / $C$12) = 0, MOD(H12, $C$12) & " P", INT(H12 / $C$12) & " + " & MOD(H12, $C$12) & " P"))) -> 10 + 2 P
A14: 3 | B14: องุ่นแดงไร้เมล็ด150กรัม x 32 Pไข่ปลา | C14: 32 | D14: 99 | E14: 62 | F14: 90 | G14: 16 | H14: 23 | I14: =SUM(D14:H14) -> 290 | J14: 11
D15: =IF(D14=0, "", IF(MOD(D14, $C$14) = 0, D14 / $C$14, IF(INT(D14 / $C$14) = 0, MOD(D14, $C$14) & " P", INT(D14 / $C$14) & " + " & MOD(D14, $C$14) & " P"))) -> 3 + 3 P | E15: =IF(E14=0, "", IF(MOD(E14, $C$14) = 0, E14 / $C$14, IF(INT(E14 / $C$14) = 0, MOD(E14, $C$14) & " P", INT(E14 / $C$14) & " + " & MOD(E14, $C$14) & " P"))) -> 1 + 30 P | F15: =IF(F14=0, "", IF(MOD(F14, $C$14) = 0, F14 / $C$14, IF(INT(F14 / $C$14) = 0, MOD(F14, $C$14) & " P", INT(F14 / $C$14) & " + " & MOD(F14, $C$14) & " P"))) -> 2 + 26 P | G15: =IF(G14=0, "", IF(MOD(G14, $C$14) = 0, G14 / $C$14, IF(INT(G14 / $C$14) = 0, MOD(G14, $C$14) & " P", INT(G14 / $C$14) & " + " & MOD(G14, $C$14) & " P"))) -> 16 P | H15: =IF(H14=0, "", IF(MOD(H14, $C$14) = 0, H14 / $C$14, IF(INT(H14 / $C$14) = 0, MOD(H14, $C$14) & " P", INT(H14 / $C$14) & " + " & MOD(H14, $C$14) & " P"))) -> 23 P
A16: 4 | B16: สตรอเบอร์รี่250 กรัม กรัม x 27 AUS | C16: 27 | D16: 58 | E16: 39 | F16: 26 | G16: 6 | H16: 1 | I16: =SUM(D16:H16) -> 130 | J16: 8
D17: =IF(D16=0, "", IF(MOD(D16, $C$16) = 0, D16 / $C$16, IF(INT(D16 / $C$16) = 0, MOD(D16, $C$16) & " P", INT(D16 / $C$16) & " + " & MOD(D16, $C$16) & " P"))) -> 2 + 4 P | E17: =IF(E16=0, "", IF(MOD(E16, $C$16) = 0, E16 / $C$16, IF(INT(E16 / $C$16) = 0, MOD(E16, $C$16) & " P", INT(E16 / $C$16) & " + " & MOD(E16, $C$16) & " P"))) -> 1 + 12 P | F17: =IF(F16=0, "", IF(MOD(F16, $C$16) = 0, F16 / $C$16, IF(INT(F16 / $C$16) = 0, MOD(F16, $C$16) & " P", INT(F16 / $C$16) & " + " & MOD(F16, $C$16) & " P"))) -> 26 P | G17: =IF(G16=0, "", IF(MOD(G16, $C$16) = 0, G16 / $C$16, IF(INT(G16 / $C$16) = 0, MOD(G16, $C$16) & " P", INT(G16 / $C$16) & " + " & MOD(G16, $C$16) & " P"))) -> 6 P | H17: =IF(H16=0, "", IF(MOD(H16, $C$16) = 0, H16 / $C$16, IF(INT(H16 / $C$16) = 0, MOD(H16, $C$16) & " P", INT(H16 / $C$16) & " + " & MOD(H16, $C$16) & " P"))) -> 1 P
A18: 5 | B18: บลูเบอร์รี่ 125 กรัม x 36 P | C18: 36 | D18: 190 | E18: 117 | F18: 66 | G18: 21 | H18: 12 | I18: =SUM(D18:H18) -> 406 | J18: 14
D19: =IF(D18=0, "", IF(MOD(D18, $C$18) = 0, D18 / $C$18, IF(INT(D18 / $C$18) = 0, MOD(D18, $C$18) & " P", INT(D18 / $C$18) & " + " & MOD(D18, $C$18) & " P"))) -> 5 + 10 P | E19: =IF(E18=0, "", IF(MOD(E18, $C$18) = 0, E18 / $C$18, IF(INT(E18 / $C$18) = 0, MOD(E18, $C$18) & " P", INT(E18 / $C$18) & " + " & MOD(E18, $C$18) & " P"))) -> 3 + 9 P | F19: =IF(F18=0, "", IF(MOD(F18, $C$18) = 0, F18 / $C$18, IF(INT(F18 / $C$18) = 0, MOD(F18, $C$18) & " P", INT(F18 / $C$18) & " + " & MOD(F18, $C$18) & " P"))) -> 1 + 30 P | G19: =IF(G18=0, "", IF(MOD(G18, $C$18) = 0, G18 / $C$18, IF(INT(G18 / $C$18) = 0, MOD(G18, $C$18) & " P", INT(G18 / $C$18) & " + " & MOD(G18, $C$18) & " P"))) -> 21 P | H19: =IF(H18=0, "", IF(MOD(H18, $C$18) = 0, H18 / $C$18, IF(INT(H18 / $C$18) = 0, MOD(H18, $C$18) & " P", INT(H18 / $C$18) & " + " & MOD(H18, $C$18) & " P"))) -> 12 P
A20: 6 | B20: องุ่นไชน์มัสแคท 300 กรัม x 15 P | C20: 15 | D20: 67 | E20: 48 | F20: 48 | G20: 8 | H20: 17 | I20: =SUM(D20:H20) -> 188 | J20: 16
D21: =IF(D20=0, "", IF(MOD(D20, $C$20) = 0, D20/ $C$20, IF(INT(D20 / $C$20) = 0, MOD(D20, $C$20) & " P", INT(D20 / $C$20) & " + " & MOD(D20, $C$20) & " P"))) -> 4 + 7 P | E21: =IF(E20=0, "", IF(MOD(E20, $C$20) = 0, E20/ $C$20, IF(INT(E20 / $C$20) = 0, MOD(E20, $C$20) & " P", INT(E20 / $C$20) & " + " & MOD(E20, $C$20) & " P"))) -> 3 + 3 P | F21: =IF(F20=0, "", IF(MOD(F20, $C$20) = 0, F20/ $C$20, IF(INT(F20 / $C$20) = 0, MOD(F20, $C$20) & " P", INT(F20 / $C$20) & " + " & MOD(F20, $C$20) & " P"))) -> 3 + 3 P | G21: =IF(G20=0, "", IF(MOD(G20, $C$20) = 0, G20/ $C$20, IF(INT(G20 / $C$20) = 0, MOD(G20, $C$20) & " P", INT(G20 / $C$20) & " + " & MOD(G20, $C$20) & " P"))) -> 8 P | H21: =IF(H20=0, "", IF(MOD(H20, $C$20) = 0, H20/ $C$20, IF(INT(H20 / $C$20) = 0, MOD(H20, $C$20) & " P", INT(H20 / $C$20) & " + " & MOD(H20, $C$20) & " P"))) -> 1 + 2 P
A22: 7 | B22: แอปเปิ้ลแดงวอชิงตันลูกเดี่ยว x 45 P | C22: 45 | D22: 11 | E22: 6 | F22: 6 | G22: 2 | H22: 1 | I22: =SUM(D22:H22) -> 26 | J22: 5
D23: =IF(D22=0, "", IF(MOD(D22, $C$22) = 0, D22/ $C$22, IF(INT(D22 / $C$22) = 0, MOD(D22, $C$22) & " P", INT(D22 / $C$22) & " + " & MOD(D22, $C$22) & " P"))) -> 11 P | E23: =IF(E22=0, "", IF(MOD(E22, $C$22) = 0, E22/ $C$22, IF(INT(E22 / $C$22) = 0, MOD(E22, $C$22) & " P", INT(E22 / $C$22) & " + " & MOD(E22, $C$22) & " P"))) -> 6 P | F23: =IF(F22=0, "", IF(MOD(F22, $C$22) = 0, F22/ $C$22, IF(INT(F22 / $C$22) = 0, MOD(F22, $C$22) & " P", INT(F22 / $C$22) & " + " & MOD(F22, $C$22) & " P"))) -> 6 P | G23: =IF(G22=0, "", IF(MOD(G22, $C$22) = 0, G22/ $C$22, IF(INT(G22 / $C$22) = 0, MOD(G22, $C$22) & " P", INT(G22 / $C$22) & " + " & MOD(G22, $C$22) & " P"))) -> 2 P | H23: =IF(H22=0, "", IF(MOD(H22, $C$22) = 0, H22/ $C$22, IF(INT(H22 / $C$22) = 0, MOD(H22, $C$22) & " P", INT(H22 / $C$22) & " + " & MOD(H22, $C$22) & " P"))) -> 1 P
A24: 9 | B24: กีวีเขียวแพ็ก 2 ผล 140g.x 45 P | C24: 45 | D24: 79 | E24: 58 | F24: 2600 | G24: 5 | H24: 3 | I24: =SUM(D24:H24) -> 2745 | J24: 64
D25: =IF(D24=0, "", IF(MOD(D24, $C$24) = 0, D24/ $C$24, IF(INT(D24 / $C$24) = 0, MOD(D24, $C$24) & " P", INT(D24 / $C$24) & " + " & MOD(D24, $C$24) & " P"))) -> 1 + 34 P | E25: =IF(E24=0, "", IF(MOD(E24, $C$24) = 0, E24/ $C$24, IF(INT(E24 / $C$24) = 0, MOD(E24, $C$24) & " P", INT(E24 / $C$24) & " + " & MOD(E24, $C$24) & " P"))) -> 1 + 13 P | F25: =IF(F24=0, "", IF(MOD(F24, $C$24) = 0, F24/ $C$24, IF(INT(F24 / $C$24) = 0, MOD(F24, $C$24) & " P", INT(F24 / $C$24) & " + " & MOD(F24, $C$24) & " P"))) -> 57 + 35 P | G25: =IF(G24=0, "", IF(MOD(G24, $C$24) = 0, G24/ $C$24, IF(INT(G24 / $C$24) = 0, MOD(G24, $C$24) & " P", INT(G24 / $C$24) & " + " & MOD(G24, $C$24) & " P"))) -> 5 P | H25: =IF(H24=0, "", IF(MOD(H24, $C$24) = 0, H24/ $C$24, IF(INT(H24 / $C$24) = 0, MOD(H24, $C$24) & " P", INT(H24 / $C$24) & " + " & MOD(H24, $C$24) & " P"))) -> 3 P
A26: 10 | B26: แอปเปิ้ลเจ้าหญิง 200 กรัม x 27 P | C26: 27 | D26: 137 | E26: 92 | F26: 138 | G26: 42 | H26: 43 | I26: =SUM(C26:H26) -> 479 | J26: 20
