Workbook

Sheet สุวรรณภูมิ-ผลิต
C2: ผู้ส่ง : 7-11 สุวรรณภูมิ 4 ล้อจัมโบ้ 62 พี่เอ๋
F3: วันที่ 18/08/69 ส่งวันที่ PO 19/08/69 | P3: ยอดรวม | R3: ของคืน
C4: NO | D4: สุวรรณภูมิ (SB) | E4: บรรจุ/ตก.
F6: PO1 | G6: PO 2 | H6: PO 3 | I6: PO 4 | J6: PO 5 | K6: PO 6 | L6: PO 7 | M6: PO 8 | N6: PO 9 | O6: PO 10 | P6: แพค | Q6: ตะกร้า
C7: 1 | D7: องุ่นดำไร้เมล็ด 150 กรัม x36P | E7: 36 | F7: 43 | G7: 29 | H7: 24 | I7: 21 | J7: 22 | K7: 10 | L7: 12 | M7: 31 | P7: =SUM(F7:O7) -> 192 | Q7: ='สุวรรณภูมิ-รถ'!C10 -> 9
D8: BlackGrapesSeedless150 g.( 8859388000025) | F8: =IF(F7=0, "", IF(MOD(F7, $E$7) = 0, F7 / $E$7, IF(INT(F7 / $E$7) = 0, MOD(F7, $E$7) & " P", INT(F7 / $E$7) & " + " & MOD(F7, $E$7) & " P"))) -> 1 + 7 P | G8: =IF(G7=0, "", IF(MOD(G7, $E$7) = 0, G7 / $E$7, IF(INT(G7 / $E$7) = 0, MOD(G7, $E$7) & " P", INT(G7 / $E$7) & " + " & MOD(G7, $E$7) & " P"))) -> 29 P | H8: =IF(H7=0, "", IF(MOD(H7, $E$7) = 0, H7 / $E$7, IF(INT(H7 / $E$7) = 0, MOD(H7, $E$7) & " P", INT(H7 / $E$7) & " + " & MOD(H7, $E$7) & " P"))) -> 24 P | I8: =IF(I7=0, "", IF(MOD(I7, $E$7) = 0, I7 / $E$7, IF(INT(I7 / $E$7) = 0, MOD(I7, $E$7) & " P", INT(I7 / $E$7) & " + " & MOD(I7, $E$7) & " P"))) -> 21 P | J8: =IF(J7=0, "", IF(MOD(J7, $E$7) = 0, J7 / $E$7, IF(INT(J7 / $E$7) = 0, MOD(J7, $E$7) & " P", INT(J7 / $E$7) & " + " & MOD(J7, $E$7) & " P"))) -> 22 P | K8: =IF(K7=0, "", IF(MOD(K7, $E$7) = 0, K7 / $E$7, IF(INT(K7 / $E$7) = 0, MOD(K7, $E$7) & " P", INT(K7 / $E$7) & " + " & MOD(K7, $E$7) & " P"))) -> 10 P | L8: =IF(L7=0, "", IF(MOD(L7, $E$7) = 0, L7 / $E$7, IF(INT(L7 / $E$7) = 0, MOD(L7, $E$7) & " P", INT(L7 / $E$7) & " + " & MOD(L7, $E$7) & " P"))) -> 12 P | M8: =IF(M7=0, "", IF(MOD(M7, $E$7) = 0, M7 / $E$7, IF(INT(M7 / $E$7) = 0, MOD(M7, $E$7) & " P", INT(M7 / $E$7) & " + " & MOD(M7, $E$7) & " P"))) -> 31 P | ... O8: =IF(O7=0, "", IF(MOD(O7, $E$7) = 0, O7 / $E$7, IF(INT(O7 / $E$7) = 0, MOD(O7, $E$7) & " P", INT(O7 / $E$7) & " + " & MOD(O7, $E$7) & " P")))
C9: 2 | D9: องุ่นแดงนอกมีเมล็ด 200 กรัม x 32 P | E9: 32 | F9: 127 | G9: 53 | H9: 52 | I9: 80 | J9: 49 | K9: 22 | L9: 65 | M9: 92 | P9: =SUM(F9:O9) -> 540 | Q9: ='สุวรรณภูมิ-รถ'!C11 -> 20
D10: Red Seed 200 g. ( 8859388000100 ) | F10: =IF(F9=0, "", IF(MOD(F9, $E$9) = 0, F9 / $E$9, IF(INT(F9 / $E$9) = 0, MOD(F9, $E$9) & " P", INT(F9 / $E$9) & " + " & MOD(F9, $E$9) & " P"))) -> 3 + 31 P | G10: =IF(G9=0, "", IF(MOD(G9, $E$9) = 0, G9 / $E$9, IF(INT(G9 / $E$9) = 0, MOD(G9, $E$9) & " P", INT(G9 / $E$9) & " + " & MOD(G9, $E$9) & " P"))) -> 1 + 21 P | H10: =IF(H9=0, "", IF(MOD(H9, $E$9) = 0, H9 / $E$9, IF(INT(H9 / $E$9) = 0, MOD(H9, $E$9) & " P", INT(H9 / $E$9) & " + " & MOD(H9, $E$9) & " P"))) -> 1 + 20 P | I10: =IF(I9=0, "", IF(MOD(I9, $E$9) = 0, I9 / $E$9, IF(INT(I9 / $E$9) = 0, MOD(I9, $E$9) & " P", INT(I9 / $E$9) & " + " & MOD(I9, $E$9) & " P"))) -> 2 + 16 P | J10: =IF(J9=0, "", IF(MOD(J9, $E$9) = 0, J9 / $E$9, IF(INT(J9 / $E$9) = 0, MOD(J9, $E$9) & " P", INT(J9 / $E$9) & " + " & MOD(J9, $E$9) & " P"))) -> 1 + 17 P | K10: =IF(K9=0, "", IF(MOD(K9, $E$9) = 0, K9 / $E$9, IF(INT(K9 / $E$9) = 0, MOD(K9, $E$9) & " P", INT(K9 / $E$9) & " + " & MOD(K9, $E$9) & " P"))) -> 22 P | L10: =IF(L9=0, "", IF(MOD(L9, $E$9) = 0, L9 / $E$9, IF(INT(L9 / $E$9) = 0, MOD(L9, $E$9) & " P", INT(L9 / $E$9) & " + " & MOD(L9, $E$9) & " P"))) -> 2 + 1 P | M10: =IF(M9=0, "", IF(MOD(M9, $E$9) = 0, M9 / $E$9, IF(INT(M9 / $E$9) = 0, MOD(M9, $E$9) & " P", INT(M9 / $E$9) & " + " & MOD(M9, $E$9) & " P"))) -> 2 + 28 P | ... O10: =IF(O9=0, "", IF(MOD(O9, $E$9) = 0, O9 / $E$9, IF(INT(O9 / $E$9) = 0, MOD(O9, $E$9) & " P", INT(O9 / $E$9) & " + " & MOD(O9, $E$9) & " P")))
C11: 3 | D11: เชอร์รี่สดนำเข้า150 กรัม(อเมริกา)x36P | E11: 36 | F11: 63 | G11: 16 | H11: 13 | I11: 30 | J11: 12 | K11: 7 | L11: 24 | M11: 25 | P11: =SUM(F11:O11) -> 190 | Q11: ='สุวรรณภูมิ-รถ'!C12 -> 9
D12: Cherry 150 g ( 8859388008885 ) | F12: =IF(F11=0, "", IF(MOD(F11, $E$11) = 0, F11/ $E$11, IF(INT(F11 / $E$11) = 0, MOD(F11, $E$11) & " P", INT(F11 / $E$11) & " + " & MOD(F11, $E$11) & " P"))) -> 1 + 27 P | G12: =IF(G11=0, "", IF(MOD(G11, $E$11) = 0, G11/ $E$11, IF(INT(G11 / $E$11) = 0, MOD(G11, $E$11) & " P", INT(G11 / $E$11) & " + " & MOD(G11, $E$11) & " P"))) -> 16 P | H12: =IF(H11=0, "", IF(MOD(H11, $E$11) = 0, H11/ $E$11, IF(INT(H11 / $E$11) = 0, MOD(H11, $E$11) & " P", INT(H11 / $E$11) & " + " & MOD(H11, $E$11) & " P"))) -> 13 P | I12: =IF(I11=0, "", IF(MOD(I11, $E$11) = 0, I11/ $E$11, IF(INT(I11 / $E$11) = 0, MOD(I11, $E$11) & " P", INT(I11 / $E$11) & " + " & MOD(I11, $E$11) & " P"))) -> 30 P | J12: =IF(J11=0, "", IF(MOD(J11, $E$11) = 0, J11/ $E$11, IF(INT(J11 / $E$11) = 0, MOD(J11, $E$11) & " P", INT(J11 / $E$11) & " + " & MOD(J11, $E$11) & " P"))) -> 12 P | K12: =IF(K11=0, "", IF(MOD(K11, $E$11) = 0, K11/ $E$11, IF(INT(K11 / $E$11) = 0, MOD(K11, $E$11) & " P", INT(K11 / $E$11) & " + " & MOD(K11, $E$11) & " P"))) -> 7 P | L12: =IF(L11=0, "", IF(MOD(L11, $E$11) = 0, L11/ $E$11, IF(INT(L11 / $E$11) = 0, MOD(L11, $E$11) & " P", INT(L11 / $E$11) & " + " & MOD(L11, $E$11) & " P"))) -> 24 P | M12: =IF(M11=0, "", IF(MOD(M11, $E$11) = 0, M11/ $E$11, IF(INT(M11 / $E$11) = 0, MOD(M11, $E$11) & " P", INT(M11 / $E$11) & " + " & MOD(M11, $E$11) & " P"))) -> 25 P | ... O12: =IF(O11=0, "", IF(MOD(O11, $E$11) = 0, O11/ $E$11, IF(INT(O11 / $E$11) = 0, MOD(O11, $E$11) & " P", INT(O11 / $E$11) & " + " & MOD(O11, $E$11) & " P")))
C13: 4 | D13: ส้มแพ็ก 4 ผล(450 กรัม) x14 P | E13: 14 | F13: 49 | G13: 22 | H13: 32 | I13: 35 | J13: 22 | K13: 14 | L13: 20 | M13: 37 | P13: =SUM(F13:O13) -> 231 | Q13: ='สุวรรณภูมิ-รถ'!C13 -> 20
D14: Mandarin orange P.4 (8859388000445) | F14: =IF(F13=0, "", IF(MOD(F13, $E$13) = 0, F13/ $E$13, IF(INT(F13 / $E$13) = 0, MOD(F13, $E$13) & " P", INT(F13 / $E$13) & " + " & MOD(F13, $E$13) & " P"))) -> 3 + 7 P | G14: =IF(G13=0, "", IF(MOD(G13, $E$13) = 0, G13/ $E$13, IF(INT(G13 / $E$13) = 0, MOD(G13, $E$13) & " P", INT(G13 / $E$13) & " + " & MOD(G13, $E$13) & " P"))) -> 1 + 8 P | H14: =IF(H13=0, "", IF(MOD(H13, $E$13) = 0, H13/ $E$13, IF(INT(H13 / $E$13) = 0, MOD(H13, $E$13) & " P", INT(H13 / $E$13) & " + " & MOD(H13, $E$13) & " P"))) -> 2 + 4 P | I14: =IF(I13=0, "", IF(MOD(I13, $E$13) = 0, I13/ $E$13, IF(INT(I13 / $E$13) = 0, MOD(I13, $E$13) & " P", INT(I13 / $E$13) & " + " & MOD(I13, $E$13) & " P"))) -> 2 + 7 P | J14: =IF(J13=0, "", IF(MOD(J13, $E$13) = 0, J13/ $E$13, IF(INT(J13 / $E$13) = 0, MOD(J13, $E$13) & " P", INT(J13 / $E$13) & " + " & MOD(J13, $E$13) & " P"))) -> 1 + 8 P | K14: =IF(K13=0, "", IF(MOD(K13, $E$13) = 0, K13/ $E$13, IF(INT(K13 / $E$13) = 0, MOD(K13, $E$13) & " P", INT(K13 / $E$13) & " + " & MOD(K13, $E$13) & " P"))) -> 1 | L14: =IF(L13=0, "", IF(MOD(L13, $E$13) = 0, L13/ $E$13, IF(INT(L13 / $E$13) = 0, MOD(L13, $E$13) & " P", INT(L13 / $E$13) & " + " & MOD(L13, $E$13) & " P"))) -> 1 + 6 P | M14: =IF(M13=0, "", IF(MOD(M13, $E$13) = 0, M13/ $E$13, IF(INT(M13 / $E$13) = 0, MOD(M13, $E$13) & " P", INT(M13 / $E$13) & " + " & MOD(M13, $E$13) & " P"))) -> 2 + 9 P
C15: 5 | D15: แอปเปิ้ลแพ็ก 4 ผล(400 กรัม) x14 P | E15: 14 | F15: 36 | G15: 22 | H15: 12 | I15: 28 | J15: 18 | K15: 9 | L15: 16 | M15: 29 | P15: =SUM(F15:O15) -> 170 | Q15: ='สุวรรณภูมิ-รถ'!C14 -> 16
D16: Apple P.4 (8859388000568 ) | F16: =IF(F15=0, "", IF(MOD(F15, $E$15) = 0, F15/ $E$15, IF(INT(F15 / $E$15) = 0, MOD(F15, $E$15) & " P", INT(F15 / $E$15) & " + " & MOD(F15, $E$15) & " P"))) -> 2 + 8 P | G16: =IF(G15=0, "", IF(MOD(G15, $E$15) = 0, G15/ $E$15, IF(INT(G15 / $E$15) = 0, MOD(G15, $E$15) & " P", INT(G15 / $E$15) & " + " & MOD(G15, $E$15) & " P"))) -> 1 + 8 P | H16: =IF(H15=0, "", IF(MOD(H15, $E$15) = 0, H15/ $E$15, IF(INT(H15 / $E$15) = 0, MOD(H15, $E$15) & " P", INT(H15 / $E$15) & " + " & MOD(H15, $E$15) & " P"))) -> 12 P | I16: =IF(I15=0, "", IF(MOD(I15, $E$15) = 0, I15/ $E$15, IF(INT(I15 / $E$15) = 0, MOD(I15, $E$15) & " P", INT(I15 / $E$15) & " + " & MOD(I15, $E$15) & " P"))) -> 2 | J16: =IF(J15=0, "", IF(MOD(J15, $E$15) = 0, J15/ $E$15, IF(INT(J15 / $E$15) = 0, MOD(J15, $E$15) & " P", INT(J15 / $E$15) & " + " & MOD(J15, $E$15) & " P"))) -> 1 + 4 P | K16: =IF(K15=0, "", IF(MOD(K15, $E$15) = 0, K15/ $E$15, IF(INT(K15 / $E$15) = 0, MOD(K15, $E$15) & " P", INT(K15 / $E$15) & " + " & MOD(K15, $E$15) & " P"))) -> 9 P | L16: =IF(L15=0, "", IF(MOD(L15, $E$15) = 0, L15/ $E$15, IF(INT(L15 / $E$15) = 0, MOD(L15, $E$15) & " P", INT(L15 / $E$15) & " + " & MOD(L15, $E$15) & " P"))) -> 1 + 2 P | M16: =IF(M15=0, "", IF(MOD(M15, $E$15) = 0, M15/ $E$15, IF(INT(M15 / $E$15) = 0, MOD(M15, $E$15) & " P", INT(M15 / $E$15) & " + " & MOD(M15, $E$15) & " P"))) -> 2 + 1 P | ... O16: =IF(O15=0, "", IF(MOD(O15, $E$15) = 0, O15/ $E$15, IF(INT(O15 / $E$15) = 0, MOD(O15, $E$15) & " P", INT(O15 / $E$15) & " + " & MOD(O15, $E$15) & " P")))
C17: 6 | D17: องุ่นแดงไร้เมล็ด150กรัม x 32 Pไข่ปลา | E17: 32 | F17: 60 | G17: 34 | H17: 22 | I17: 38 | J17: 24 | K17: 9 | L17: 20 | M17: 43 | P17: =SUM(F17:O17) -> 250 | Q17: ='สุวรรณภูมิ-รถ'!C15 -> 12
D18: Red Seedless 150 g.( 8859388007000 ) | F18: =IF(F17=0, "", IF(MOD(F17, $E$17) = 0, F17/ $E$17, IF(INT(F17 / $E$17) = 0, MOD(F17, $E$17) & " P", INT(F17 / $E$17) & " + " & MOD(F17, $E$17) & " P"))) -> 1 + 28 P | G18: =IF(G17=0, "", IF(MOD(G17, $E$17) = 0, G17/ $E$17, IF(INT(G17 / $E$17) = 0, MOD(G17, $E$17) & " P", INT(G17 / $E$17) & " + " & MOD(G17, $E$17) & " P"))) -> 1 + 2 P | H18: =IF(H17=0, "", IF(MOD(H17, $E$17) = 0, H17/ $E$17, IF(INT(H17 / $E$17) = 0, MOD(H17, $E$17) & " P", INT(H17 / $E$17) & " + " & MOD(H17, $E$17) & " P"))) -> 22 P | I18: =IF(I17=0, "", IF(MOD(I17, $E$17) = 0, I17/ $E$17, IF(INT(I17 / $E$17) = 0, MOD(I17, $E$17) & " P", INT(I17 / $E$17) & " + " & MOD(I17, $E$17) & " P"))) -> 1 + 6 P | J18: =IF(J17=0, "", IF(MOD(J17, $E$17) = 0, J17/ $E$17, IF(INT(J17 / $E$17) = 0, MOD(J17, $E$17) & " P", INT(J17 / $E$17) & " + " & MOD(J17, $E$17) & " P"))) -> 24 P | K18: =IF(K17=0, "", IF(MOD(K17, $E$17) = 0, K17/ $E$17, IF(INT(K17 / $E$17) = 0, MOD(K17, $E$17) & " P", INT(K17 / $E$17) & " + " & MOD(K17, $E$17) & " P"))) -> 9 P | L18: =IF(L17=0, "", IF(MOD(L17, $E$17) = 0, L17/ $E$17, IF(INT(L17 / $E$17) = 0, MOD(L17, $E$17) & " P", INT(L17 / $E$17) & " + " & MOD(L17, $E$17) & " P"))) -> 20 P | M18: =IF(M17=0, "", IF(MOD(M17, $E$17) = 0, M17/ $E$17, IF(INT(M17 / $E$17) = 0, MOD(M17, $E$17) & " P", INT(M17 / $E$17) & " + " & MOD(M17, $E$17) & " P"))) -> 1 + 11 P | ... O18: =IF(O17=0, "", IF(MOD(O17, $E$17) = 0, O17/ $E$17, IF(INT(O17 / $E$17) = 0, MOD(O17, $E$17) & " P", INT(O17 / $E$17) & " + " & MOD(O17, $E$17) & " P")))
C19: 7 | D19: พุทราจีน 200 กรัม x 27 P | E19: 27 | F19: 92 | G19: 34 | H19: 35 | I19: 34 | J19: 34 | K19: 30 | L19: 32 | M19: 27 | P19: =SUM(F19:O19) -> 318 | Q19: ='สุวรรณภูมิ-รถ'!C16 -> 17
D20: Jujube 200g.(8859388000087 ) | F20: =IF(F19=0, "", IF(MOD(F19, $E$19) = 0, F19/ $E$19, IF(INT(F19 / $E$19) = 0, MOD(F19, $E$19) & " P", INT(F19 / $E$19) & " + " & MOD(F19, $E$19) & " P"))) -> 3 + 11 P | G20: =IF(G19=0, "", IF(MOD(G19, $E$19) = 0, G19/ $E$19, IF(INT(G19 / $E$19) = 0, MOD(G19, $E$19) & " P", INT(G19 / $E$19) & " + " & MOD(G19, $E$19) & " P"))) -> 1 + 7 P | H20: =IF(H19=0, "", IF(MOD(H19, $E$19) = 0, H19/ $E$19, IF(INT(H19 / $E$19) = 0, MOD(H19, $E$19) & " P", INT(H19 / $E$19) & " + " & MOD(H19, $E$19) & " P"))) -> 1 + 8 P | I20: =IF(I19=0, "", IF(MOD(I19, $E$19) = 0, I19/ $E$19, IF(INT(I19 / $E$19) = 0, MOD(I19, $E$19) & " P", INT(I19 / $E$19) & " + " & MOD(I19, $E$19) & " P"))) -> 1 + 7 P | J20: =IF(J19=0, "", IF(MOD(J19, $E$19) = 0, J19/ $E$19, IF(INT(J19 / $E$19) = 0, MOD(J19, $E$19) & " P", INT(J19 / $E$19) & " + " & MOD(J19, $E$19) & " P"))) -> 1 + 7 P | K20: =IF(K19=0, "", IF(MOD(K19, $E$19) = 0, K19/ $E$19, IF(INT(K19 / $E$19) = 0, MOD(K19, $E$19) & " P", INT(K19 / $E$19) & " + " & MOD(K19, $E$19) & " P"))) -> 1 + 3 P | L20: =IF(L19=0, "", IF(MOD(L19, $E$19) = 0, L19/ $E$19, IF(INT(L19 / $E$19) = 0, MOD(L19, $E$19) & " P", INT(L19 / $E$19) & " + " & MOD(L19, $E$19) & " P"))) -> 1 + 5 P | M20: =IF(M19=0, "", IF(MOD(M19, $E$19) = 0, M19/ $E$19, IF(INT(M19 / $E$19) = 0, MOD(M19, $E$19) & " P", INT(M19 / $E$19) & " + " & MOD(M19, $E$19) & " P"))) -> 1 | ... O20: =IF(O19=0, "", IF(MOD(O19, $E$19) = 0, O19/ $E$19, IF(INT(O19 / $E$19) = 0, MOD(O19, $E$19) & " P", INT(O19 / $E$19) & " + " & MOD(O19, $E$19) & " P")))
C21: 8 | D21: สตรอเบอร์รี่ 250 กรัม x 27 P | E21: 27 | F21: 30 | G21: 14 | H21: 22 | I21: 38 | J21: 23 | K21: 13 | L21: 20 | M21: 19 | P21: =SUM(F21:O21) -> 179 | Q21: ='สุวรรณภูมิ-รถ'!C17 -> 10
D22: Straw 250 g.( 2003009710008 ) | F22: =IF(F21=0, "", IF(MOD(F21, $E$21) = 0, F21/ $E$21, IF(INT(F21 / $E$21) = 0, MOD(F21, $E$21) & " P", INT(F21 / $E$21) & " + " & MOD(F21, $E$21) & " P"))) -> 1 + 3 P | G22: =IF(G21=0, "", IF(MOD(G21, $E$21) = 0, G21/ $E$21, IF(INT(G21 / $E$21) = 0, MOD(G21, $E$21) & " P", INT(G21 / $E$21) & " + " & MOD(G21, $E$21) & " P"))) -> 14 P | H22: =IF(H21=0, "", IF(MOD(H21, $E$21) = 0, H21/ $E$21, IF(INT(H21 / $E$21) = 0, MOD(H21, $E$21) & " P", INT(H21 / $E$21) & " + " & MOD(H21, $E$21) & " P"))) -> 22 P | I22: =IF(I21=0, "", IF(MOD(I21, $E$21) = 0, I21/ $E$21, IF(INT(I21 / $E$21) = 0, MOD(I21, $E$21) & " P", INT(I21 / $E$21) & " + " & MOD(I21, $E$21) & " P"))) -> 1 + 11 P | J22: =IF(J21=0, "", IF(MOD(J21, $E$21) = 0, J21/ $E$21, IF(INT(J21 / $E$21) = 0, MOD(J21, $E$21) & " P", INT(J21 / $E$21) & " + " & MOD(J21, $E$21) & " P"))) -> 23 P | K22: =IF(K21=0, "", IF(MOD(K21, $E$21) = 0, K21/ $E$21, IF(INT(K21 / $E$21) = 0, MOD(K21, $E$21) & " P", INT(K21 / $E$21) & " + " & MOD(K21, $E$21) & " P"))) -> 13 P | L22: =IF(L21=0, "", IF(MOD(L21, $E$21) = 0, L21/ $E$21, IF(INT(L21 / $E$21) = 0, MOD(L21, $E$21) & " P", INT(L21 / $E$21) & " + " & MOD(L21, $E$21) & " P"))) -> 20 P | M22: =IF(M21=0, "", IF(MOD(M21, $E$21) = 0, M21/ $E$21, IF(INT(M21 / $E$21) = 0, MOD(M21, $E$21) & " P", INT(M21 / $E$21) & " + " & MOD(M21, $E$21) & " P"))) -> 19 P | ... O22: =IF(O21=0, "", IF(MOD(O21, $E$21) = 0, O21/ $E$21, IF(INT(O21 / $E$21) = 0, MOD(O21, $E$21) & " P", INT(O21 / $E$21) & " + " & MOD(O21, $E$21) & " P")))
C23: 9 | D23: บลูเบอร์รี่ 125 กรัม x 36 P | E23: 36 | F23: 99 | G23: 21 | H23: 20 | I23: 53 | J23: 27 | K23: 27 | L23: 43 | M23: 82 | P23: =SUM(F23:O23) -> 372 | Q23: ='สุวรรณภูมิ-รถ'!C18 -> 14
D24: Blue 125 g. ( 2003009720007 ) | F24: =IF(F23=0, "", IF(MOD(F23, $E$23) = 0, F23/ $E$23, IF(INT(F23 / $E$23) = 0, MOD(F23, $E$23) & " P", INT(F23 / $E$23) & " + " & MOD(F23, $E$23) & " P"))) -> 2 + 27 P | G24: =IF(G23=0, "", IF(MOD(G23, $E$23) = 0, G23/ $E$23, IF(INT(G23 / $E$23) = 0, MOD(G23, $E$23) & " P", INT(G23 / $E$23) & " + " & MOD(G23, $E$23) & " P"))) -> 21 P | H24: =IF(H23=0, "", IF(MOD(H23, $E$23) = 0, H23/ $E$23, IF(INT(H23 / $E$23) = 0, MOD(H23, $E$23) & " P", INT(H23 / $E$23) & " + " & MOD(H23, $E$23) & " P"))) -> 20 P | I24: =IF(I23=0, "", IF(MOD(I23, $E$23) = 0, I23/ $E$23, IF(INT(I23 / $E$23) = 0, MOD(I23, $E$23) & " P", INT(I23 / $E$23) & " + " & MOD(I23, $E$23) & " P"))) -> 1 + 17 P | J24: =IF(J23=0, "", IF(MOD(J23, $E$23) = 0, J23/ $E$23, IF(INT(J23 / $E$23) = 0, MOD(J23, $E$23) & " P", INT(J23 / $E$23) & " + " & MOD(J23, $E$23) & " P"))) -> 27 P | K24: =IF(K23=0, "", IF(MOD(K23, $E$23) = 0, K23/ $E$23, IF(INT(K23 / $E$23) = 0, MOD(K23, $E$23) & " P", INT(K23 / $E$23) & " + " & MOD(K23, $E$23) & " P"))) -> 27 P | L24: =IF(L23=0, "", IF(MOD(L23, $E$23) = 0, L23/ $E$23, IF(INT(L23 / $E$23) = 0, MOD(L23, $E$23) & " P", INT(L23 / $E$23) & " + " & MOD(L23, $E$23) & " P"))) -> 1 + 7 P | M24: =IF(M23=0, "", IF(MOD(M23, $E$23) = 0, M23/ $E$23, IF(INT(M23 / $E$23) = 0, MOD(M23, $E$23) & " P", INT(M23 / $E$23) & " + " & MOD(M23, $E$23) & " P"))) -> 2 + 10 P | ... O24: =IF(O23=0, "", IF(MOD(O23, $E$23) = 0, O23/ $E$23, IF(INT(O23 / $E$23) = 0, MOD(O23, $E$23) & " P", INT(O23 / $E$23) & " + " & MOD(O23, $E$23) & " P")))
C25: 10 | D25: องุ่นดำไร้เมล็ด 300 กรัม x20P | E25: 20 | F25: 43 | G25: 14 | H25: 15 | I25: 22 | J25: 12 | K25: 13 | L25: 7 | M25: 34 | P25: =SUM(F25:O25) -> 160 | Q25: ='สุวรรณภูมิ-รถ'!C19 -> 12
D26: BlackGrapesSeedless300g.( 8859388010284 ) | F26: =IF(F25=0, "", IF(MOD(F25, $E$25) = 0, F25/ $E$25, IF(INT(F25 / $E$25) = 0, MOD(F25, $E$25) & " P", INT(F25 / $E$25) & " + " & MOD(F25, $E$25) & " P"))) -> 2 + 3 P | G26: =IF(G25=0, "", IF(MOD(G25, $E$25) = 0, G25/ $E$25, IF(INT(G25 / $E$25) = 0, MOD(G25, $E$25) & " P", INT(G25 / $E$25) & " + " & MOD(G25, $E$25) & " P"))) -> 14 P | H26: =IF(H25=0, "", IF(MOD(H25, $E$25) = 0, H25/ $E$25, IF(INT(H25 / $E$25) = 0, MOD(H25, $E$25) & " P", INT(H25 / $E$25) & " + " & MOD(H25, $E$25) & " P"))) -> 15 P | I26: =IF(I25=0, "", IF(MOD(I25, $E$25) = 0, I25/ $E$25, IF(INT(I25 / $E$25) = 0, MOD(I25, $E$25) & " P", INT(I25 / $E$25) & " + " & MOD(I25, $E$25) & " P"))) -> 1 + 2 P | J26: =IF(J25=0, "", IF(MOD(J25, $E$25) = 0, J25/ $E$25, IF(INT(J25 / $E$25) = 0, MOD(J25, $E$25) & " P", INT(J25 / $E$25) & " + " & MOD(J25, $E$25) & " P"))) -> 12 P | K26: =IF(K25=0, "", IF(MOD(K25, $E$25) = 0, K25/ $E$25, IF(INT(K25 / $E$25) = 0, MOD(K25, $E$25) & " P", INT(K25 / $E$25) & " + " & MOD(K25, $E$25) & " P"))) -> 13 P | L26: =IF(L25=0, "", IF(MOD(L25, $E$25) = 0, L25/ $E$25, IF(INT(L25 / $E$25) = 0, MOD(L25, $E$25) & " P", INT(L25 / $E$25) & " + " & MOD(L25, $E$25) & " P"))) -> 7 P | M26: =IF(M25=0, "", IF(MOD(M25, $E$25) = 0, M25/ $E$25, IF(INT(M25 / $E$25) = 0, MOD(M25, $E$25) & " P", INT(M25 / $E$25) & " + " & MOD(M25, $E$25) & " P"))) -> 1 + 14 P | ... O26: =IF(O25=0, "", IF(MOD(O25, $E$25) = 0, O25/ $E$25, IF(INT(O25 / $E$25) = 0, MOD(O25, $E$25) & " P", INT(O25 / $E$25) & " + " & MOD(O25, $E$25) & " P")))
C27: 11 | D27: องุ่นไซน์มัสแคท 300 กรัม x 15 P | E27: 15 | F27: 36 | G27: 6 | H27: 7 | I27: 4 | J27: 2 | K27: 2 | L27: 12 | M27: 5 | P27: =SUM(F27:O27) -> 74 | Q27: ='สุวรรณภูมิ-รถ'!C20 -> 10
D28: Shine muscat 300 g ( 885938000018 ) | F28: =IF(F27=0, "", IF(MOD(F27, $E$27) = 0, F27/ $E$27, IF(INT(F27 / $E$27) = 0, MOD(F27, $E$27) & " P", INT(F27 / $E$27) & " + " & MOD(F27, $E$27) & " P"))) -> 2 + 6 P | G28: =IF(G27=0, "", IF(MOD(G27, $E$27) = 0, G27/ $E$27, IF(INT(G27 / $E$27) = 0, MOD(G27, $E$27) & " P", INT(G27 / $E$27) & " + " & MOD(G27, $E$27) & " P"))) -> 6 P | H28: =IF(H27=0, "", IF(MOD(H27, $E$27) = 0, H27/ $E$27, IF(INT(H27 / $E$27) = 0, MOD(H27, $E$27) & " P", INT(H27 / $E$27) & " + " & MOD(H27, $E$27) & " P"))) -> 7 P | I28: =IF(I27=0, "", IF(MOD(I27, $E$27) = 0, I27/ $E$27, IF(INT(I27 / $E$27) = 0, MOD(I27, $E$27) & " P", INT(I27 / $E$27) & " + " & MOD(I27, $E$27) & " P"))) -> 4 P | J28: =IF(J27=0, "", IF(MOD(J27, $E$27) = 0, J27/ $E$27, IF(INT(J27 / $E$27) = 0, MOD(J27, $E$27) & " P", INT(J27 / $E$27) & " + " & MOD(J27, $E$27) & " P"))) -> 2 P | K28: =IF(K27=0, "", IF(MOD(K27, $E$27) = 0, K27/ $E$27, IF(INT(K27 / $E$27) = 0, MOD(K27, $E$27) & " P", INT(K27 / $E$27) & " + " & MOD(K27, $E$27) & " P"))) -> 2 P | L28: =IF(L27=0, "", IF(MOD(L27, $E$27) = 0, L27/ $E$27, IF(INT(L27 / $E$27) = 0, MOD(L27, $E$27) & " P", INT(L27 / $E$27) & " + " & MOD(L27, $E$27) & " P"))) -> 12 P | M28: =IF(M27=0, "", IF(MOD(M27, $E$27) = 0, M27/ $E$27, IF(INT(M27 / $E$27) = 0, MOD(M27, $E$27) & " P", INT(M27 / $E$27) & " + " & MOD(M27, $E$27) & " P"))) -> 5 P | ... O28: =IF(O27=0, "", IF(MOD(O27, $E$27) = 0, O27/ $E$27, IF(INT(O27 / $E$27) = 0, MOD(O27, $E$27) & " P", INT(O27 / $E$27) & " + " & MOD(O27, $E$27) & " P")))
C29: 12 | D29: แอปเปิ้ลแดงวอชิงตันลูกเดี่ยว x 45 P | E29: 45 | F29: 8 | G29: 1 | H29: 3 | I29: 0 | J29: 2 | K29: 1 | L29: 4 | M29: 5 | P29: =SUM(F29:O29) -> 24 | Q29: ='สุวรรณภูมิ-รถ'!C21 -> 7
D30: Washington ( 8859388000759 ) | F30: =IF(F29=0, "", IF(MOD(F29, $E$29) = 0, F29/ $E$29, IF(INT(F29 / $E$29) = 0, MOD(F29, $E$29) & " P", INT(F29 / $E$29) & " + " & MOD(F29, $E$29) & " P"))) -> 8 P | G30: =IF(G29=0, "", IF(MOD(G29, $E$29) = 0, G29/ $E$29, IF(INT(G29 / $E$29) = 0, MOD(G29, $E$29) & " P", INT(G29 / $E$29) & " + " & MOD(G29, $E$29) & " P"))) -> 1 P | H30: =IF(H29=0, "", IF(MOD(H29, $E$29) = 0, H29/ $E$29, IF(INT(H29 / $E$29) = 0, MOD(H29, $E$29) & " P", INT(H29 / $E$29) & " + " & MOD(H29, $E$29) & " P"))) -> 3 P | I30: =IF(I29=0, "", IF(MOD(I29, $E$29) = 0, I29/ $E$29, IF(INT(I29 / $E$29) = 0, MOD(I29, $E$29) & " P", INT(I29 / $E$29) & " + " & MOD(I29, $E$29) & " P"))) | J30: =IF(J29=0, "", IF(MOD(J29, $E$29) = 0, J29/ $E$29, IF(INT(J29 / $E$29) = 0, MOD(J29, $E$29) & " P", INT(J29 / $E$29) & " + " & MOD(J29, $E$29) & " P"))) -> 2 P | K30: =IF(K29=0, "", IF(MOD(K29, $E$29) = 0, K29/ $E$29, IF(INT(K29 / $E$29) = 0, MOD(K29, $E$29) & " P", INT(K29 / $E$29) & " + " & MOD(K29, $E$29) & " P"))) -> 1 P | L30: =IF(L29=0, "", IF(MOD(L29, $E$29) = 0, L29/ $E$29, IF(INT(L29 / $E$29) = 0, MOD(L29, $E$29) & " P", INT(L29 / $E$29) & " + " & MOD(L29, $E$29) & " P"))) -> 4 P | M30: =IF(M29=0, "", IF(MOD(M29, $E$29) = 0, M29/ $E$29, IF(INT(M29 / $E$29) = 0, MOD(M29, $E$29) & " P", INT(M29 / $E$29) & " + " & MOD(M29, $E$29) & " P"))) -> 5 P | ... O30: =IF(O29=0, "", IF(MOD(O29, $E$29) = 0, O29/ $E$29, IF(INT(O29 / $E$29) = 0, MOD(O29, $E$29) & " P", INT(O29 / $E$29) & " + " & MOD(O29, $E$29) & " P")))
C31: 13 | D31: องุ่นสวีทแซฟไฟร์ 300 กรัม x 15 P | E31: 15 | F31: 29 | G31: 10 | H31: 16 | I31: 14 | J31: 6 | K31: 4 | L31: 12 | M31: 30 | P31: =SUM(F31:O31) -> 121 | Q31: ='สุวรรณภูมิ-รถ'!C22 -> 11
D32: Sweet Sapphire 300gx 15 P ( 8859388000223 ) | F32: =IF(F31=0, "", IF(MOD(F31, $E$31) = 0, F31/ $E$31, IF(INT(F31 / $E$31) = 0, MOD(F31, $E$31) & " P", INT(F31 / $E$31) & " + " & MOD(F31, $E$31) & " P"))) -> 1 + 14 P | G32: =IF(G31=0, "", IF(MOD(G31, $E$31) = 0, G31/ $E$31, IF(INT(G31 / $E$31) = 0, MOD(G31, $E$31) & " P", INT(G31 / $E$31) & " + " & MOD(G31, $E$31) & " P"))) -> 10 P | H32: =IF(H31=0, "", IF(MOD(H31, $E$31) = 0, H31/ $E$31, IF(INT(H31 / $E$31) = 0, MOD(H31, $E$31) & " P", INT(H31 / $E$31) & " + " & MOD(H31, $E$31) & " P"))) -> 1 + 1 P | I32: =IF(I31=0, "", IF(MOD(I31, $E$31) = 0, I31/ $E$31, IF(INT(I31 / $E$31) = 0, MOD(I31, $E$31) & " P", INT(I31 / $E$31) & " + " & MOD(I31, $E$31) & " P"))) -> 14 P | J32: =IF(J31=0, "", IF(MOD(J31, $E$31) = 0, J31/ $E$31, IF(INT(J31 / $E$31) = 0, MOD(J31, $E$31) & " P", INT(J31 / $E$31) & " + " & MOD(J31, $E$31) & " P"))) -> 6 P | K32: =IF(K31=0, "", IF(MOD(K31, $E$31) = 0, K31/ $E$31, IF(INT(K31 / $E$31) = 0, MOD(K31, $E$31) & " P", INT(K31 / $E$31) & " + " & MOD(K31, $E$31) & " P"))) -> 4 P | L32: =IF(L31=0, "", IF(MOD(L31, $E$31) = 0, L31/ $E$31, IF(INT(L31 / $E$31) = 0, MOD(L31, $E$31) & " P", INT(L31 / $E$31) & " + " & MOD(L31, $E$31) & " P"))) -> 12 P | M32: =IF(M31=0, "", IF(MOD(M31, $E$31) = 0, M31/ $E$31, IF(INT(M31 / $E$31) = 0, MOD(M31, $E$31) & " P", INT(M31 / $E$31) & " + " & MOD(M31, $E$31) & " P"))) -> 2 | ... O32: =IF(O31=0, "", IF(MOD(O31, $E$31) = 0, O31/ $E$31, IF(INT(O31 / $E$31) = 0, MOD(O31, $E$31) & " P", INT(O31 / $E$31) & " + " & MOD(O31, $E$31) & " P")))
C33: 14 | D33: องุ่นเคียวโฮ 300 กรัม x 15 P | E33: 15 | F33: 17 | G33: 6 | H33: 5 | I33: 2 | J33: 3 | K33: 4 | L33: 5 | M33: 1 | P33: =SUM(F33:O33) -> 43 | Q33: ='สุวรรณภูมิ-รถ'!C23 -> 9
D34: Kyoho Grape300g('88859388000063) | F34: =IF(F33=0, "", IF(MOD(F33, $E$33) = 0, F33/ $E$33, IF(INT(F33 / $E$33) = 0, MOD(F33, $E$33) & " P", INT(F33 / $E$33) & " + " & MOD(F33, $E$33) & " P"))) -> 1 + 2 P | G34: =IF(G33=0, "", IF(MOD(G33, $E$33) = 0, G33/ $E$33, IF(INT(G33 / $E$33) = 0, MOD(G33, $E$33) & " P", INT(G33 / $E$33) & " + " & MOD(G33, $E$33) & " P"))) -> 6 P | H34: =IF(H33=0, "", IF(MOD(H33, $E$33) = 0, H33/ $E$33, IF(INT(H33 / $E$33) = 0, MOD(H33, $E$33) & " P", INT(H33 / $E$33) & " + " & MOD(H33, $E$33) & " P"))) -> 5 P | I34: =IF(I33=0, "", IF(MOD(I33, $E$33) = 0, I33/ $E$33, IF(INT(I33 / $E$33) = 0, MOD(I33, $E$33) & " P", INT(I33 / $E$33) & " + " & MOD(I33, $E$33) & " P"))) -> 2 P | J34: =IF(J33=0, "", IF(MOD(J33, $E$33) = 0, J33/ $E$33, IF(INT(J33 / $E$33) = 0, MOD(J33, $E$33) & " P", INT(J33 / $E$33) & " + " & MOD(J33, $E$33) & " P"))) -> 3 P | K34: =IF(K33=0, "", IF(MOD(K33, $E$33) = 0, K33/ $E$33, IF(INT(K33 / $E$33) = 0, MOD(K33, $E$33) & " P", INT(K33 / $E$33) & " + " & MOD(K33, $E$33) & " P"))) -> 4 P | L34: =IF(L33=0, "", IF(MOD(L33, $E$33) = 0, L33/ $E$33, IF(INT(L33 / $E$33) = 0, MOD(L33, $E$33) & " P", INT(L33 / $E$33) & " + " & MOD(L33, $E$33) & " P"))) -> 5 P | M34: =IF(M33=0, "", IF(MOD(M33, $E$33) = 0, M33/ $E$33, IF(INT(M33 / $E$33) = 0, MOD(M33, $E$33) & " P", INT(M33 / $E$33) & " + " & MOD(M33, $E$33) & " P"))) -> 1 P | ... O34: =IF(O33=0, "", IF(MOD(O33, $E$33) = 0, O33/ $E$33, IF(INT(O33 / $E$33) = 0, MOD(O33, $E$33) & " P", INT(O33 / $E$33) & " + " & MOD(O33, $E$33) & " P")))
C35: 15 | D35: ลูกไหนจิ๋ว 200 g. x 27 p | E35: 27 | F35: 41 | G35: 8 | H35: 10 | I35: 24 | J35: 6 | K35: 6 | L35: 14 | M35: 20 | P35: =SUM(F35:O35) -> 129 | Q35: ='สุวรรณภูมิ-รถ'!C24 -> 9
D36: Plum 200 g. ( 8859388001091 ) | F36: =IF(F35=0, "", IF(MOD(F35, $E$35) = 0, F35/ $E$35, IF(INT(F35 / $E$35) = 0, MOD(F35, $E$35) & " P", INT(F35 / $E$35) & " + " & MOD(F35, $E$35) & " P"))) -> 1 + 14 P | G36: =IF(G35=0, "", IF(MOD(G35, $E$35) = 0, G35/ $E$35, IF(INT(G35 / $E$35) = 0, MOD(G35, $E$35) & " P", INT(G35 / $E$35) & " + " & MOD(G35, $E$35) & " P"))) -> 8 P | H36: =IF(H35=0, "", IF(MOD(H35, $E$35) = 0, H35/ $E$35, IF(INT(H35 / $E$35) = 0, MOD(H35, $E$35) & " P", INT(H35 / $E$35) & " + " & MOD(H35, $E$35) & " P"))) -> 10 P | I36: =IF(I35=0, "", IF(MOD(I35, $E$35) = 0, I35/ $E$35, IF(INT(I35 / $E$35) = 0, MOD(I35, $E$35) & " P", INT(I35 / $E$35) & " + " & MOD(I35, $E$35) & " P"))) -> 24 P | J36: =IF(J35=0, "", IF(MOD(J35, $E$35) = 0, J35/ $E$35, IF(INT(J35 / $E$35) = 0, MOD(J35, $E$35) & " P", INT(J35 / $E$35) & " + " & MOD(J35, $E$35) & " P"))) -> 6 P | K36: =IF(K35=0, "", IF(MOD(K35, $E$35) = 0, K35/ $E$35, IF(INT(K35 / $E$35) = 0, MOD(K35, $E$35) & " P", INT(K35 / $E$35) & " + " & MOD(K35, $E$35) & " P"))) -> 6 P | L36: =IF(L35=0, "", IF(MOD(L35, $E$35) = 0, L35/ $E$35, IF(INT(L35 / $E$35) = 0, MOD(L35, $E$35) & " P", INT(L35 / $E$35) & " + " & MOD(L35, $E$35) & " P"))) -> 14 P | M36: =IF(M35=0, "", IF(MOD(M35, $E$35) = 0, M35/ $E$35, IF(INT(M35 / $E$35) = 0, MOD(M35, $E$35) & " P", INT(M35 / $E$35) & " + " & MOD(M35, $E$35) & " P"))) -> 20 P | ... O36: =IF(O35=0, "", IF(MOD(O35, $E$35) = 0, O35/ $E$35, IF(INT(O35 / $E$35) = 0, MOD(O35, $E$35) & " P", INT(O35 / $E$35) & " + " & MOD(O35, $E$35) & " P")))
C37: 16 | D37: องุ่นแดงไร้เมล็ด 300 g. x 20 p | E37: 20 | F37: 73 | G37: 22 | H37: 29 | I37: 32 | J37: 23 | K37: 10 | L37: 24 | M37: 31 | P37: =SUM(F37:O37) -> 244 | Q37: ='สุวรรณภูมิ-รถ'!C25 -> 17
D38: Red Seedless 300g. ( 8859388001084 ) | F38: =IF(F37=0, "", IF(MOD(F37, $E$37) = 0, F37/ $E$37, IF(INT(F37 / $E$37) = 0, MOD(F37, $E$37) & " P", INT(F37 / $E$37) & " + " & MOD(F37, $E$37) & " P"))) -> 3 + 13 P | G38: =IF(G37=0, "", IF(MOD(G37, $E$37) = 0, G37/ $E$37, IF(INT(G37 / $E$37) = 0, MOD(G37, $E$37) & " P", INT(G37 / $E$37) & " + " & MOD(G37, $E$37) & " P"))) -> 1 + 2 P | H38: =IF(H37=0, "", IF(MOD(H37, $E$37) = 0, H37/ $E$37, IF(INT(H37 / $E$37) = 0, MOD(H37, $E$37) & " P", INT(H37 / $E$37) & " + " & MOD(H37, $E$37) & " P"))) -> 1 + 9 P | I38: =IF(I37=0, "", IF(MOD(I37, $E$37) = 0, I37/ $E$37, IF(INT(I37 / $E$37) = 0, MOD(I37, $E$37) & " P", INT(I37 / $E$37) & " + " & MOD(I37, $E$37) & " P"))) -> 1 + 12 P | J38: =IF(J37=0, "", IF(MOD(J37, $E$37) = 0, J37/ $E$37, IF(INT(J37 / $E$37) = 0, MOD(J37, $E$37) & " P", INT(J37 / $E$37) & " + " & MOD(J37, $E$37) & " P"))) -> 1 + 3 P | K38: =IF(K37=0, "", IF(MOD(K37, $E$37) = 0, K37/ $E$37, IF(INT(K37 / $E$37) = 0, MOD(K37, $E$37) & " P", INT(K37 / $E$37) & " + " & MOD(K37, $E$37) & " P"))) -> 10 P | L38: =IF(L37=0, "", IF(MOD(L37, $E$37) = 0, L37/ $E$37, IF(INT(L37 / $E$37) = 0, MOD(L37, $E$37) & " P", INT(L37 / $E$37) & " + " & MOD(L37, $E$37) & " P"))) -> 1 + 4 P | M38: =IF(M37=0, "", IF(MOD(M37, $E$37) = 0, M37/ $E$37, IF(INT(M37 / $E$37) = 0, MOD(M37, $E$37) & " P", INT(M37 / $E$37) & " + " & MOD(M37, $E$37) & " P"))) -> 1 + 11 P | ... O38: =IF(O37=0, "", IF(MOD(O37, $E$37) = 0, O37/ $E$37, IF(INT(O37 / $E$37) = 0, MOD(O37, $E$37) & " P", INT(O37 / $E$37) & " + " & MOD(O37, $E$37) & " P")))
C39: 17 | D39: เบอร์รี่ดูโอ้ 160 กรัม x 32 P | E39: 32 | F39: 53 | G39: 15 | H39: 7 | I39: 11 | J39: 1 | K39: 2 | L39: 6 | M39: 15 | P39: =SUM(F39:O39) -> 110 | Q39: ='สุวรรณภูมิ-รถ'!C26 -> 9
D40: Berry Duo ( 8859388010239 ) | F40: =IF(F39=0, "", IF(MOD(F39, $E$39) = 0, F39/ $E$39, IF(INT(F39 / $E$39) = 0, MOD(F39, $E$39) & " P", INT(F39 / $E$39) & " + " & MOD(F39, $E$39) & " P"))) -> 1 + 21 P | G40: =IF(G39=0, "", IF(MOD(G39, $E$39) = 0, G39/ $E$39, IF(INT(G39 / $E$39) = 0, MOD(G39, $E$39) & " P", INT(G39 / $E$39) & " + " & MOD(G39, $E$39) & " P"))) -> 15 P | H40: =IF(H39=0, "", IF(MOD(H39, $E$39) = 0, H39/ $E$39, IF(INT(H39 / $E$39) = 0, MOD(H39, $E$39) & " P", INT(H39 / $E$39) & " + " & MOD(H39, $E$39) & " P"))) -> 7 P | I40: =IF(I39=0, "", IF(MOD(I39, $E$39) = 0, I39/ $E$39, IF(INT(I39 / $E$39) = 0, MOD(I39, $E$39) & " P", INT(I39 / $E$39) & " + " & MOD(I39, $E$39) & " P"))) -> 11 P | J40: =IF(J39=0, "", IF(MOD(J39, $E$39) = 0, J39/ $E$39, IF(INT(J39 / $E$39) = 0, MOD(J39, $E$39) & " P", INT(J39 / $E$39) & " + " & MOD(J39, $E$39) & " P"))) -> 1 P | K40: =IF(K39=0, "", IF(MOD(K39, $E$39) = 0, K39/ $E$39, IF(INT(K39 / $E$39) = 0, MOD(K39, $E$39) & " P", INT(K39 / $E$39) & " + " & MOD(K39, $E$39) & " P"))) -> 2 P | L40: =IF(L39=0, "", IF(MOD(L39, $E$39) = 0, L39/ $E$39, IF(INT(L39 / $E$39) = 0, MOD(L39, $E$39) & " P", INT(L39 / $E$39) & " + " & MOD(L39, $E$39) & " P"))) -> 6 P | M40: =IF(M39=0, "", IF(MOD(M39, $E$39) = 0, M39/ $E$39, IF(INT(M39 / $E$39) = 0, MOD(M39, $E$39) & " P", INT(M39 / $E$39) & " + " & MOD(M39, $E$39) & " P"))) -> 15 P | ... O40: =IF(O39=0, "", IF(MOD(O39, $E$39) = 0, O39/ $E$39, IF(INT(O39 / $E$39) = 0, MOD(O39, $E$39) & " P", INT(O39 / $E$39) & " + " & MOD(O39, $E$39) & " P")))
C41: 18 | D41: สาลี่ทอง แพ็ก 2 ผล (400g.) x 15 P | E41: 15 | F41: 18 | G41: 6 | H41: 4 | I41: 8 | J41: 0 | K41: 0 | L41: 13 | M41: 11 | P41: =SUM(F41:O41) -> 60 | Q41: ='สุวรรณภูมิ-รถ'!C27 -> 7
D42: Pear 400g (8859388010284 ) | F42: =IF(F41=0, "", IF(MOD(F41, $E$41) = 0, F41/ $E$41, IF(INT(F41 / $E$41) = 0, MOD(F41, $E$41) & " P", INT(F41 / $E$41) & " + " & MOD(F41, $E$41) & " P"))) -> 1 + 3 P | G42: =IF(G41=0, "", IF(MOD(G41, $E$41) = 0, G41/ $E$41, IF(INT(G41 / $E$41) = 0, MOD(G41, $E$41) & " P", INT(G41 / $E$41) & " + " & MOD(G41, $E$41) & " P"))) -> 6 P | H42: =IF(H41=0, "", IF(MOD(H41, $E$41) = 0, H41/ $E$41, IF(INT(H41 / $E$41) = 0, MOD(H41, $E$41) & " P", INT(H41 / $E$41) & " + " & MOD(H41, $E$41) & " P"))) -> 4 P | I42: =IF(I41=0, "", IF(MOD(I41, $E$41) = 0, I41/ $E$41, IF(INT(I41 / $E$41) = 0, MOD(I41, $E$41) & " P", INT(I41 / $E$41) & " + " & MOD(I41, $E$41) & " P"))) -> 8 P | J42: =IF(J41=0, "", IF(MOD(J41, $E$41) = 0, J41/ $E$41, IF(INT(J41 / $E$41) = 0, MOD(J41, $E$41) & " P", INT(J41 / $E$41) & " + " & MOD(J41, $E$41) & " P"))) | K42: =IF(K41=0, "", IF(MOD(K41, $E$41) = 0, K41/ $E$41, IF(INT(K41 / $E$41) = 0, MOD(K41, $E$41) & " P", INT(K41 / $E$41) & " + " & MOD(K41, $E$41) & " P"))) | L42: =IF(L41=0, "", IF(MOD(L41, $E$41) = 0, L41/ $E$41, IF(INT(L41 / $E$41) = 0, MOD(L41, $E$41) & " P", INT(L41 / $E$41) & " + " & MOD(L41, $E$41) & " P"))) -> 13 P | M42: =IF(M41=0, "", IF(MOD(M41, $E$41) = 0, M41/ $E$41, IF(INT(M41 / $E$41) = 0, MOD(M41, $E$41) & " P", INT(M41 / $E$41) & " + " & MOD(M41, $E$41) & " P"))) -> 11 P | ... O42: =IF(O41=0, "", IF(MOD(O41, $E$41) = 0, O41/ $E$41, IF(INT(O41 / $E$41) = 0, MOD(O41, $E$41) & " P", INT(O41 / $E$41) & " + " & MOD(O41, $E$41) & " P")))
...

Sheet สุวรรณภูมิ-รถ
A1: #VALUE! | B1: Global Trade and Distribution Co., Ltd. บริษัท โกลบอล เทรด แอนด์ ดิสทริบิวชั่น จำกัด | O1: Date:
O3: PO:
A4: ผู้ส่ง:
A6: เซเว่น SB | C6: สุวรรณภูมิ
C7: รับ GTD | D7: เวลาลงสินค้า 02:00-04:00 น.
D8: PO1 | E8: PO2 | F8: PO3 | G8: PO4 | H8: PO5 | I8: PO6 | J8: PO7 | K8: PO8 | L8: PO9 | M8: PO10 | O8: ยอดรับจริง | P8: ยอดส่งคืน | Q8: หมายเหตุ | R8: KK - PO1 | U8: KK - PO2 | X8: SR - PO1 | AA8: SR - PO2 | AD8: CM- PO1 | AG8: CM- PO2 | AJ8: PK- PO1 | AM8: PK- PO2 | AP8: HY- PO1 | AS8: HY- PO2
A9: รายการสินค้า | B9: บรรจุ/ตก. | N9: GTD | R9: F | S9: >H | T9: ≤H | U9: F | V9: >H | W9: ≤H | X9: F | Y9: >H | Z9: ≤H | AA9: F | AB9: >H | AC9: ≤H | AD9: F | AE9: >H | AF9: ≤H | AG9: F | AH9: >H | AI9: ≤H | AJ9: F | AK9: >H | AL9: ≤H | AM9: F | AN9: >H | AO9: ≤H | AP9: F | AQ9: >H | AR9: ≤H | AS9: F | AT9: >H | AU9: ≤H
A10: องุ่นดำไร้เมล็ด 150 กรัม x36P | B10: 36 | C10: {=SUMPRODUCT(ROUNDUP(D10:M10/B10, 0))} -> 9 | D10: ='สุวรรณภูมิ-ผลิต'!F7 -> 43 | E10: ='สุวรรณภูมิ-ผลิต'!G7 -> 29 | F10: ='สุวรรณภูมิ-ผลิต'!H7 -> 24 | G10: ='สุวรรณภูมิ-ผลิต'!I7 -> 21 | H10: ='สุวรรณภูมิ-ผลิต'!J7 -> 22 | I10: ='สุวรรณภูมิ-ผลิต'!K7 -> 10 | J10: ='สุวรรณภูมิ-ผลิต'!L7 -> 12 | K10: ='สุวรรณภูมิ-ผลิต'!M7 -> 31 | ... M10: ='สุวรรณภูมิ-ผลิต'!O7 -> 0 | N10: =INT(SUM(D10:M10)/B10) & " full, " & IF(MOD(SUM(D10:M10), B10)/B10 <= 0.5, "1 less than half", IF(MOD(SUM(D10:M10), B10)/B10 > 0.5, "1 more than half", "")) -> 5 full, 1 less than half | R10: =INT(D10/B10) -> 1 | S10: =IF(MOD(D10,B10)/B10>0.5,1,0) -> 0 | T10: =IF(AND(MOD(D10,B10)/B10<=0.5,MOD(D10,B10)<>0),1,0) -> 1 | U10: =INT(E10/B10) -> 0 | V10: =IF(MOD(E10,B10)/B10>0.5,1,0) -> 1 | W10: =IF(AND(MOD(E10,B10)/B10<=0.5,MOD(E10,B10)<>0),1,0) -> 0 | X10: =INT(F10/B10) -> 0 | Y10: =IF(MOD(F10,B10)/B10>0.5,1,0) -> 1 | Z10: =IF(AND(MOD(F10,B10)/B10<=0.5,MOD(F10,B10)<>0),1,0) -> 0 | AA10: =INT(G10/B10) -> 0 | AB10: =IF(MOD(G10,B10)/B10>0.5,1,0) -> 1 | AC10: =IF(AND(MOD(G10,B10)/B10<=0.5,MOD(G10,B10)<>0),1,0) -> 0 | AD10: =INT(H10/B10) -> 0 | AE10: =IF(MOD(H10,B10)/B10>0.5,1,0) -> 1 | AF10: =IF(AND(MOD(H10,B10)/B10<=0.5,MOD(H10,B10)<>0),1,0) -> 0 | AG10: =INT(I10/B10) -> 0 | AH10: =IF(MOD(I10,B10)/B10>0.5,1,0) -> 0 | AI10: =IF(AND(MOD(I10,B10)/B10<=0.5,MOD(I10,B10)<>0),1,0) -> 1 | AJ10: =INT(J10/B10) -> 0 | AK10: =IF(MOD(J10,B10)/B10>0.5,1,0) -> 0 | AL10: =IF(AND(MOD(J10,B10)/B10<=0.5,MOD(J10,B10)<>0),1,0) -> 1 | AM10: =INT(K10/B10) -> 0 | AN10: =IF(MOD(K10,B10)/B10>0.5,1,0) -> 1 | AO10: =IF(AND(MOD(K10,B10)/B10<=0.5,MOD(K10,B10)<>0),1,0) -> 0 | AP10: =INT(L10/B10) -> 0 | AQ10: =IF(MOD(L10,B10)/B10>0.5,1,0) -> 0 | AR10: =IF(AND(MOD(L10,B10)/B10<=0.5,MOD(L10,B10)<>0),1,0) -> 0 | AS10: =INT(M10/B10) -> 0 | AT10: =IF(MOD(M10,B10)/B10>0.5,1,0) -> 0 | AU10: =IF(AND(MOD(M10,B10)/B10<=0.5,MOD(M10,B10)<>0),1,0) -> 0
A11: องุ่นแดงนอกมีเมล็ด 200 กรัม x 32 P | B11: 32 | C11: {=SUMPRODUCT(ROUNDUP(D11:M11/B11, 0))} -> 20 | D11: ='สุวรรณภูมิ-ผลิต'!F9 -> 127 | E11: ='สุวรรณภูมิ-ผลิต'!G9 -> 53 | F11: ='สุวรรณภูมิ-ผลิต'!H9 -> 52 | G11: ='สุวรรณภูมิ-ผลิต'!I9 -> 80 | H11: ='สุวรรณภูมิ-ผลิต'!J9 -> 49 | I11: ='สุวรรณภูมิ-ผลิต'!K9 -> 22 | J11: ='สุวรรณภูมิ-ผลิต'!L9 -> 65 | K11: ='สุวรรณภูมิ-ผลิต'!M9 -> 92 | ... M11: ='สุวรรณภูมิ-ผลิต'!O9 -> 0 | N11: =INT(SUM(D11:M11)/B11) & " full, " & IF(MOD(SUM(D11:M11), B11)/B11 <= 0.5, "1 less than half", IF(MOD(SUM(D11:M11), B11)/B11 > 0.5, "1 more than half", "")) -> 16 full, 1 more than half | R11: =INT(D11/B11) -> 3 | S11: =IF(MOD(D11,B11)/B11>0.5,1,0) -> 1 | T11: =IF(AND(MOD(D11,B11)/B11<=0.5,MOD(D11,B11)<>0),1,0) -> 0 | U11: =INT(E11/B11) -> 1 | V11: =IF(MOD(E11,B11)/B11>0.5,1,0) -> 1 | W11: =IF(AND(MOD(E11,B11)/B11<=0.5,MOD(E11,B11)<>0),1,0) -> 0 | X11: =INT(F11/B11) -> 1 | Y11: =IF(MOD(F11,B11)/B11>0.5,1,0) -> 1 | Z11: =IF(AND(MOD(F11,B11)/B11<=0.5,MOD(F11,B11)<>0),1,0) -> 0 | AA11: =INT(G11/B11) -> 2 | AB11: =IF(MOD(G11,B11)/B11>0.5,1,0) -> 0 | AC11: =IF(AND(MOD(G11,B11)/B11<=0.5,MOD(G11,B11)<>0),1,0) -> 1 | AD11: =INT(H11/B11) -> 1 | AE11: =IF(MOD(H11,B11)/B11>0.5,1,0) -> 1 | AF11: =IF(AND(MOD(H11,B11)/B11<=0.5,MOD(H11,B11)<>0),1,0) -> 0 | AG11: =INT(I11/B11) -> 0 | AH11: =IF(MOD(I11,B11)/B11>0.5,1,0) -> 1 | AI11: =IF(AND(MOD(I11,B11)/B11<=0.5,MOD(I11,B11)<>0),1,0) -> 0 | AJ11: =INT(J11/B11) -> 2 | AK11: =IF(MOD(J11,B11)/B11>0.5,1,0) -> 0 | AL11: =IF(AND(MOD(J11,B11)/B11<=0.5,MOD(J11,B11)<>0),1,0) -> 1 | AM11: =INT(K11/B11) -> 2 | AN11: =IF(MOD(K11,B11)/B11>0.5,1,0) -> 1 | AO11: =IF(AND(MOD(K11,B11)/B11<=0.5,MOD(K11,B11)<>0),1,0) -> 0 | AP11: =INT(L11/B11) -> 0 | AQ11: =IF(MOD(L11,B11)/B11>0.5,1,0) -> 0 | AR11: =IF(AND(MOD(L11,B11)/B11<=0.5,MOD(L11,B11)<>0),1,0) -> 0 | AS11: =INT(M11/B11) -> 0 | AT11: =IF(MOD(M11,B11)/B11>0.5,1,0) -> 0 | AU11: =IF(AND(MOD(M11,B11)/B11<=0.5,MOD(M11,B11)<>0),1,0) -> 0
A12: เชอร์รี่สดนำเข้า150 กรัม(อเมริกา)x36P | B12: 36 | C12: {=SUMPRODUCT(ROUNDUP(D12:M12/B12, 0))} -> 9 | D12: ='สุวรรณภูมิ-ผลิต'!F11 -> 63 | E12: ='สุวรรณภูมิ-ผลิต'!G11 -> 16 | F12: ='สุวรรณภูมิ-ผลิต'!H11 -> 13 | G12: ='สุวรรณภูมิ-ผลิต'!I11 -> 30 | H12: ='สุวรรณภูมิ-ผลิต'!J11 -> 12 | I12: ='สุวรรณภูมิ-ผลิต'!K11 -> 7 | J12: ='สุวรรณภูมิ-ผลิต'!L11 -> 24 | K12: ='สุวรรณภูมิ-ผลิต'!M11 -> 25 | ... M12: ='สุวรรณภูมิ-ผลิต'!O11 -> 0 | N12: =INT(SUM(D12:M12)/B12) & " full, " & IF(MOD(SUM(D12:M12), B12)/B12 <= 0.5, "1 less than half", IF(MOD(SUM(D12:M12), B12)/B12 > 0.5, "1 more than half", "")) -> 5 full, 1 less than half | R12: =INT(D12/B12) -> 1 | S12: =IF(MOD(D12,B12)/B12>0.5,1,0) -> 1 | T12: =IF(AND(MOD(D12,B12)/B12<=0.5,MOD(D12,B12)<>0),1,0) -> 0 | U12: =INT(E12/B12) -> 0 | V12: =IF(MOD(E12,B12)/B12>0.5,1,0) -> 0 | W12: =IF(AND(MOD(E12,B12)/B12<=0.5,MOD(E12,B12)<>0),1,0) -> 1 | X12: =INT(F12/B12) -> 0 | Y12: =IF(MOD(F12,B12)/B12>0.5,1,0) -> 0 | Z12: =IF(AND(MOD(F12,B12)/B12<=0.5,MOD(F12,B12)<>0),1,0) -> 1 | AA12: =INT(G12/B12) -> 0 | AB12: =IF(MOD(G12,B12)/B12>0.5,1,0) -> 1 | AC12: =IF(AND(MOD(G12,B12)/B12<=0.5,MOD(G12,B12)<>0),1,0) -> 0 | AD12: =INT(H12/B12) -> 0 | AE12: =IF(MOD(H12,B12)/B12>0.5,1,0) -> 0 | AF12: =IF(AND(MOD(H12,B12)/B12<=0.5,MOD(H12,B12)<>0),1,0) -> 1 | AG12: =INT(I12/B12) -> 0 | AH12: =IF(MOD(I12,B12)/B12>0.5,1,0) -> 0 | AI12: =IF(AND(MOD(I12,B12)/B12<=0.5,MOD(I12,B12)<>0),1,0) -> 1 | AJ12: =INT(J12/B12) -> 0 | AK12: =IF(MOD(J12,B12)/B12>0.5,1,0) -> 1 | AL12: =IF(AND(MOD(J12,B12)/B12<=0.5,MOD(J12,B12)<>0),1,0) -> 0 | AM12: =INT(K12/B12) -> 0 | AN12: =IF(MOD(K12,B12)/B12>0.5,1,0) -> 1 | AO12: =IF(AND(MOD(K12,B12)/B12<=0.5,MOD(K12,B12)<>0),1,0) -> 0 | AP12: =INT(L12/B12) -> 0 | AQ12: =IF(MOD(L12,B12)/B12>0.5,1,0) -> 0 | AR12: =IF(AND(MOD(L12,B12)/B12<=0.5,MOD(L12,B12)<>0),1,0) -> 0 | AS12: =INT(M12/B12) -> 0 | AT12: =IF(MOD(M12,B12)/B12>0.5,1,0) -> 0 | AU12: =IF(AND(MOD(M12,B12)/B12<=0.5,MOD(M12,B12)<>0),1,0) -> 0
A13: ส้มแพ็ก 4 ผล(450 กรัม) x14 P | B13: 14 | C13: {=SUMPRODUCT(ROUNDUP(D13:M13/B13, 0))} -> 20 | D13: ='สุวรรณภูมิ-ผลิต'!F13 -> 49 | E13: ='สุวรรณภูมิ-ผลิต'!G13 -> 22 | F13: ='สุวรรณภูมิ-ผลิต'!H13 -> 32 | G13: ='สุวรรณภูมิ-ผลิต'!I13 -> 35 | H13: ='สุวรรณภูมิ-ผลิต'!J13 -> 22 | I13: ='สุวรรณภูมิ-ผลิต'!K13 -> 14 | J13: ='สุวรรณภูมิ-ผลิต'!L13 -> 20 | K13: ='สุวรรณภูมิ-ผลิต'!M13 -> 37 | ... M13: ='สุวรรณภูมิ-ผลิต'!O13 -> 0
A14: แอปเปิ้ลแพ็ก 4 ผล(400 กรัม) x14 P | B14: 14 | C14: {=SUMPRODUCT(ROUNDUP(D14:M14/B14, 0))} -> 16 | D14: ='สุวรรณภูมิ-ผลิต'!F15 -> 36 | E14: ='สุวรรณภูมิ-ผลิต'!G15 -> 22 | F14: ='สุวรรณภูมิ-ผลิต'!H15 -> 12 | G14: ='สุวรรณภูมิ-ผลิต'!I15 -> 28 | H14: ='สุวรรณภูมิ-ผลิต'!J15 -> 18 | I14: ='สุวรรณภูมิ-ผลิต'!K15 -> 9 | J14: ='สุวรรณภูมิ-ผลิต'!L15 -> 16 | K14: ='สุวรรณภูมิ-ผลิต'!M15 -> 29 | ... M14: ='สุวรรณภูมิ-ผลิต'!O15 -> 0
A15: องุ่นแดงไร้เมล็ด150กรัม x 32 Pไข่ปลา | B15: 32 | C15: {=SUMPRODUCT(ROUNDUP(D15:M15/B15, 0))} -> 12 | D15: ='สุวรรณภูมิ-ผลิต'!F17 -> 60 | E15: ='สุวรรณภูมิ-ผลิต'!G17 -> 34 | F15: ='สุวรรณภูมิ-ผลิต'!H17 -> 22 | G15: ='สุวรรณภูมิ-ผลิต'!I17 -> 38 | H15: ='สุวรรณภูมิ-ผลิต'!J17 -> 24 | I15: ='สุวรรณภูมิ-ผลิต'!K17 -> 9 | J15: ='สุวรรณภูมิ-ผลิต'!L17 -> 20 | K15: ='สุวรรณภูมิ-ผลิต'!M17 -> 43 | ... M15: ='สุวรรณภูมิ-ผลิต'!O17 -> 0 | N15: =INT(SUM(D15:M15)/B15) & " full, " & IF(MOD(SUM(D15:M15), B15)/B15 <= 0.5, "1 less than half", IF(MOD(SUM(D15:M15), B15)/B15 > 0.5, "1 more than half", "")) -> 7 full, 1 more than half | R15: =INT(D15/B15) -> 1 | S15: =IF(MOD(D15,B15)/B15>0.5,1,0) -> 1 | T15: =IF(AND(MOD(D15,B15)/B15<=0.5,MOD(D15,B15)<>0),1,0) -> 0 | U15: =INT(E15/B15) -> 1 | V15: =IF(MOD(E15,B15)/B15>0.5,1,0) -> 0 | W15: =IF(AND(MOD(E15,B15)/B15<=0.5,MOD(E15,B15)<>0),1,0) -> 1 | X15: =INT(F15/B15) -> 0 | Y15: =IF(MOD(F15,B15)/B15>0.5,1,0) -> 1 | Z15: =IF(AND(MOD(F15,B15)/B15<=0.5,MOD(F15,B15)<>0),1,0) -> 0 | AA15: =INT(G15/B15) -> 1 | AB15: =IF(MOD(G15,B15)/B15>0.5,1,0) -> 0 | AC15: =IF(AND(MOD(G15,B15)/B15<=0.5,MOD(G15,B15)<>0),1,0) -> 1 | AD15: =INT(H15/B15) -> 0 | AE15: =IF(MOD(H15,B15)/B15>0.5,1,0) -> 1 | AF15: =IF(AND(MOD(H15,B15)/B15<=0.5,MOD(H15,B15)<>0),1,0) -> 0 | AG15: =INT(I15/B15) -> 0 | AH15: =IF(MOD(I15,B15)/B15>0.5,1,0) -> 0 | AI15: =IF(AND(MOD(I15,B15)/B15<=0.5,MOD(I15,B15)<>0),1,0) -> 1 | AJ15: =INT(J15/B15) -> 0 | AK15: =IF(MOD(J15,B15)/B15>0.5,1,0) -> 1 | AL15: =IF(AND(MOD(J15,B15)/B15<=0.5,MOD(J15,B15)<>0),1,0) -> 0 | AM15: =INT(K15/B15) -> 1 | AN15: =IF(MOD(K15,B15)/B15>0.5,1,0) -> 0 | AO15: =IF(AND(MOD(K15,B15)/B15<=0.5,MOD(K15,B15)<>0),1,0) -> 1 | AP15: =INT(L15/B15) -> 0 | AQ15: =IF(MOD(L15,B15)/B15>0.5,1,0) -> 0 | AR15: =IF(AND(MOD(L15,B15)/B15<=0.5,MOD(L15,B15)<>0),1,0) -> 0 | AS15: =INT(M15/B15) -> 0 | AT15: =IF(MOD(M15,B15)/B15>0.5,1,0) -> 0 | AU15: =IF(AND(MOD(M15,B15)/B15<=0.5,MOD(M15,B15)<>0),1,0) -> 0
A16: พุทราจีน 200 กรัม x 27 P | B16: 27 | C16: {=SUMPRODUCT(ROUNDUP(D16:M16/B16, 0))} -> 17 | D16: ='สุวรรณภูมิ-ผลิต'!F19 -> 92 | E16: ='สุวรรณภูมิ-ผลิต'!G19 -> 34 | F16: ='สุวรรณภูมิ-ผลิต'!H19 -> 35 | G16: ='สุวรรณภูมิ-ผลิต'!I19 -> 34 | H16: ='สุวรรณภูมิ-ผลิต'!J19 -> 34 | I16: ='สุวรรณภูมิ-ผลิต'!K19 -> 30 | J16: ='สุวรรณภูมิ-ผลิต'!L19 -> 32 | K16: ='สุวรรณภูมิ-ผลิต'!M19 -> 27 | ... M16: ='สุวรรณภูมิ-ผลิต'!O19 -> 0
A17: สตรอเบอร์รี่ 250 กรัม x 27 P | B17: 27 | C17: {=SUMPRODUCT(ROUNDUP(D17:M17/B17, 0))} -> 10 | D17: ='สุวรรณภูมิ-ผลิต'!F21 -> 30 | E17: ='สุวรรณภูมิ-ผลิต'!G21 -> 14 | F17: ='สุวรรณภูมิ-ผลิต'!H21 -> 22 | G17: ='สุวรรณภูมิ-ผลิต'!I21 -> 38 | H17: ='สุวรรณภูมิ-ผลิต'!J21 -> 23 | I17: ='สุวรรณภูมิ-ผลิต'!K21 -> 13 | J17: ='สุวรรณภูมิ-ผลิต'!L21 -> 20 | K17: ='สุวรรณภูมิ-ผลิต'!M21 -> 19 | ... M17: ='สุวรรณภูมิ-ผลิต'!O21 -> 0
A18: บลูเบอร์รี่ 125 กรัม x 36 P | B18: 36 | C18: {=SUMPRODUCT(ROUNDUP(D18:M18/B18, 0))} -> 14 | D18: ='สุวรรณภูมิ-ผลิต'!F23 -> 99 | E18: ='สุวรรณภูมิ-ผลิต'!G23 -> 21 | F18: ='สุวรรณภูมิ-ผลิต'!H23 -> 20 | G18: ='สุวรรณภูมิ-ผลิต'!I23 -> 53 | H18: ='สุวรรณภูมิ-ผลิต'!J23 -> 27 | I18: ='สุวรรณภูมิ-ผลิต'!K23 -> 27 | J18: ='สุวรรณภูมิ-ผลิต'!L23 -> 43 | K18: ='สุวรรณภูมิ-ผลิต'!M23 -> 82 | ... M18: ='สุวรรณภูมิ-ผลิต'!O23 -> 0 | N18: =INT(SUM(D18:M18)/B18) & " full, " & IF(MOD(SUM(D18:M18), B18)/B18 <= 0.5, "1 less than half", IF(MOD(SUM(D18:M18), B18)/B18 > 0.5, "1 more than half", "")) -> 10 full, 1 less than half | R18: =INT(D18/B18) -> 2 | S18: =IF(MOD(D18,B18)/B18>0.5,1,0) -> 1 | T18: =IF(AND(MOD(D18,B18)/B18<=0.5,MOD(D18,B18)<>0),1,0) -> 0 | U18: =INT(E18/B18) -> 0 | V18: =IF(MOD(E18,B18)/B18>0.5,1,0) -> 1 | W18: =IF(AND(MOD(E18,B18)/B18<=0.5,MOD(E18,B18)<>0),1,0) -> 0 | X18: =INT(F18/B18) -> 0 | Y18: =IF(MOD(F18,B18)/B18>0.5,1,0) -> 1 | Z18: =IF(AND(MOD(F18,B18)/B18<=0.5,MOD(F18,B18)<>0),1,0) -> 0 | AA18: =INT(G18/B18) -> 1 | AB18: =IF(MOD(G18,B18)/B18>0.5,1,0) -> 0 | AC18: =IF(AND(MOD(G18,B18)/B18<=0.5,MOD(G18,B18)<>0),1,0) -> 1 | AD18: =INT(H18/B18) -> 0 | AE18: =IF(MOD(H18,B18)/B18>0.5,1,0) -> 1 | AF18: =IF(AND(MOD(H18,B18)/B18<=0.5,MOD(H18,B18)<>0),1,0) -> 0 | AG18: =INT(I18/B18) -> 0 | AH18: =IF(MOD(I18,B18)/B18>0.5,1,0) -> 1 | AI18: =IF(AND(MOD(I18,B18)/B18<=0.5,MOD(I18,B18)<>0),1,0) -> 0 | AJ18: =INT(J18/B18) -> 1 | AK18: =IF(MOD(J18,B18)/B18>0.5,1,0) -> 0 | AL18: =IF(AND(MOD(J18,B18)/B18<=0.5,MOD(J18,B18)<>0),1,0) -> 1 | AM18: =INT(K18/B18) -> 2 | AN18: =IF(MOD(K18,B18)/B18>0.5,1,0) -> 0 | AO18: =IF(AND(MOD(K18,B18)/B18<=0.5,MOD(K18,B18)<>0),1,0) -> 1 | AP18: =INT(L18/B18) -> 0 | AQ18: =IF(MOD(L18,B18)/B18>0.5,1,0) -> 0 | AR18: =IF(AND(MOD(L18,B18)/B18<=0.5,MOD(L18,B18)<>0),1,0) -> 0 | AS18: =INT(M18/B18) -> 0 | AT18: =IF(MOD(M18,B18)/B18>0.5,1,0) -> 0 | AU18: =IF(AND(MOD(M18,B18)/B18<=0.5,MOD(M18,B18)<>0),1,0) -> 0
A19: องุ่นดำไร้เมล็ด 300 กรัม x20P | B19: 20 | C19: {=SUMPRODUCT(ROUNDUP(D19:M19/B19, 0))} -> 12 | D19: ='สุวรรณภูมิ-ผลิต'!F25 -> 43 | E19: ='สุวรรณภูมิ-ผลิต'!G25 -> 14 | F19: ='สุวรรณภูมิ-ผลิต'!H25 -> 15 | G19: ='สุวรรณภูมิ-ผลิต'!I25 -> 22 | H19: ='สุวรรณภูมิ-ผลิต'!J25 -> 12 | I19: ='สุวรรณภูมิ-ผลิต'!K25 -> 13 | J19: ='สุวรรณภูมิ-ผลิต'!L25 -> 7 | K19: ='สุวรรณภูมิ-ผลิต'!M25 -> 34 | ... M19: ='สุวรรณภูมิ-ผลิต'!O25 -> 0
A20: องุ่นไซน์มัสแคท 300 กรัม x 15 P | B20: 15 | C20: {=SUMPRODUCT(ROUNDUP(D20:M20/B20, 0))} -> 10 | D20: ='สุวรรณภูมิ-ผลิต'!F27 -> 36 | E20: ='สุวรรณภูมิ-ผลิต'!G27 -> 6 | F20: ='สุวรรณภูมิ-ผลิต'!H27 -> 7 | G20: ='สุวรรณภูมิ-ผลิต'!I27 -> 4 | H20: ='สุวรรณภูมิ-ผลิต'!J27 -> 2 | I20: ='สุวรรณภูมิ-ผลิต'!K27 -> 2 | J20: ='สุวรรณภูมิ-ผลิต'!L27 -> 12 | K20: ='สุวรรณภูมิ-ผลิต'!M27 -> 5 | ... N20: ='สุวรรณภูมิ-ผลิต'!P27 -> 74
A21: แอปเปิ้ลแดงวอชิงตันลูกเดี่ยว x 45 P | B21: 45 | C21: {=SUMPRODUCT(ROUNDUP(D21:M21/B21, 0))} -> 7 | D21: ='สุวรรณภูมิ-ผลิต'!F29 -> 8 | E21: ='สุวรรณภูมิ-ผลิต'!G29 -> 1 | F21: ='สุวรรณภูมิ-ผลิต'!H29 -> 3 | G21: ='สุวรรณภูมิ-ผลิต'!I29 -> 0 | H21: ='สุวรรณภูมิ-ผลิต'!J29 -> 2 | I21: ='สุวรรณภูมิ-ผลิต'!K29 -> 1 | J21: ='สุวรรณภูมิ-ผลิต'!L29 -> 4 | K21: ='สุวรรณภูมิ-ผลิต'!M29 -> 5 | ... M21: ='สุวรรณภูมิ-ผลิต'!O29 -> 0 | N21: ='สุวรรณภูมิ-ผลิต'!#REF! -> #REF! | R21: =INT(D21/B21) -> 0 | S21: =IF(MOD(D21,B21)/B21>0.5,1,0) -> 0 | T21: =IF(AND(MOD(D21,B21)/B21<=0.5,MOD(D21,B21)<>0),1,0) -> 1 | U21: =INT(E21/B21) -> 0 | V21: =IF(MOD(E21,B21)/B21>0.5,1,0) -> 0 | W21: =IF(AND(MOD(E21,B21)/B21<=0.5,MOD(E21,B21)<>0),1,0) -> 1 | X21: =INT(F21/B21) -> 0 | Y21: =IF(MOD(F21,B21)/B21>0.5,1,0) -> 0 | Z21: =IF(AND(MOD(F21,B21)/B21<=0.5,MOD(F21,B21)<>0),1,0) -> 1 | AA21: =INT(G21/B21) -> 0 | AB21: =IF(MOD(G21,B21)/B21>0.5,1,0) -> 0 | AC21: =IF(AND(MOD(G21,B21)/B21<=0.5,MOD(G21,B21)<>0),1,0) -> 0 | AD21: =INT(H21/B21) -> 0 | AE21: =IF(MOD(H21,B21)/B21>0.5,1,0) -> 0 | AF21: =IF(AND(MOD(H21,B21)/B21<=0.5,MOD(H21,B21)<>0),1,0) -> 1 | AG21: =INT(I21/B21) -> 0 | AH21: =IF(MOD(I21,B21)/B21>0.5,1,0) -> 0 | AI21: =IF(AND(MOD(I21,B21)/B21<=0.5,MOD(I21,B21)<>0),1,0) -> 1 | AJ21: =INT(J21/B21) -> 0 | AK21: =IF(MOD(J21,B21)/B21>0.5,1,0) -> 0 | AL21: =IF(AND(MOD(J21,B21)/B21<=0.5,MOD(J21,B21)<>0),1,0) -> 1 | AM21: =INT(K21/B21) -> 0 | AN21: =IF(MOD(K21,B21)/B21>0.5,1,0) -> 0 | AO21: =IF(AND(MOD(K21,B21)/B21<=0.5,MOD(K21,B21)<>0),1,0) -> 1 | AP21: =INT(L21/B21) -> 0 | AQ21: =IF(MOD(L21,B21)/B21>0.5,1,0) -> 0 | AR21: =IF(AND(MOD(L21,B21)/B21<=0.5,MOD(L21,B21)<>0),1,0) -> 0 | AS21: =INT(M21/B21) -> 0 | AT21: =IF(MOD(M21,B21)/B21>0.5,1,0) -> 0 | AU21: =IF(AND(MOD(M21,B21)/B21<=0.5,MOD(M21,B21)<>0),1,0) -> 0
A22: องุ่นสวีทแซฟไฟร์ 300 กรัม x 15 P | B22: 15 | C22: {=SUMPRODUCT(ROUNDUP(D22:M22/B22, 0))} -> 11 | D22: ='สุวรรณภูมิ-ผลิต'!F31 -> 29 | E22: ='สุวรรณภูมิ-ผลิต'!G31 -> 10 | F22: ='สุวรรณภูมิ-ผลิต'!H31 -> 16 | G22: ='สุวรรณภูมิ-ผลิต'!I31 -> 14 | H22: ='สุวรรณภูมิ-ผลิต'!J31 -> 6 | I22: ='สุวรรณภูมิ-ผลิต'!K31 -> 4 | J22: ='สุวรรณภูมิ-ผลิต'!L31 -> 12 | K22: ='สุวรรณภูมิ-ผลิต'!M31 -> 30 | ... M22: ='สุวรรณภูมิ-ผลิต'!O31 -> 0 | N22: ='สุวรรณภูมิ-ผลิต'!#REF! -> #REF! | R22: =INT(D22/B22) -> 1 | S22: =IF(MOD(D22,B22)/B22>0.5,1,0) -> 1 | T22: =IF(AND(MOD(D22,B22)/B22<=0.5,MOD(D22,B22)<>0),1,0) -> 0 | U22: =INT(E22/B22) -> 0 | V22: =IF(MOD(E22,B22)/B22>0.5,1,0) -> 1 | W22: =IF(AND(MOD(E22,B22)/B22<=0.5,MOD(E22,B22)<>0),1,0) -> 0 | X22: =INT(F22/B22) -> 1 | Y22: =IF(MOD(F22,B22)/B22>0.5,1,0) -> 0 | Z22: =IF(AND(MOD(F22,B22)/B22<=0.5,MOD(F22,B22)<>0),1,0) -> 1 | AA22: =INT(G22/B22) -> 0 | AB22: =IF(MOD(G22,B22)/B22>0.5,1,0) -> 1 | AC22: =IF(AND(MOD(G22,B22)/B22<=0.5,MOD(G22,B22)<>0),1,0) -> 0 | AD22: =INT(H22/B22) -> 0 | AE22: =IF(MOD(H22,B22)/B22>0.5,1,0) -> 0 | AF22: =IF(AND(MOD(H22,B22)/B22<=0.5,MOD(H22,B22)<>0),1,0) -> 1 | AG22: =INT(I22/B22) -> 0 | AH22: =IF(MOD(I22,B22)/B22>0.5,1,0) -> 0 | AI22: =IF(AND(MOD(I22,B22)/B22<=0.5,MOD(I22,B22)<>0),1,0) -> 1 | AJ22: =INT(J22/B22) -> 0 | AK22: =IF(MOD(J22,B22)/B22>0.5,1,0) -> 1 | AL22: =IF(AND(MOD(J22,B22)/B22<=0.5,MOD(J22,B22)<>0),1,0) -> 0 | AM22: =INT(K22/B22) -> 2 | AN22: =IF(MOD(K22,B22)/B22>0.5,1,0) -> 0 | AO22: =IF(AND(MOD(K22,B22)/B22<=0.5,MOD(K22,B22)<>0),1,0) -> 0 | AP22: =INT(L22/B22) -> 0 | AQ22: =IF(MOD(L22,B22)/B22>0.5,1,0) -> 0 | AR22: =IF(AND(MOD(L22,B22)/B22<=0.5,MOD(L22,B22)<>0),1,0) -> 0 | AS22: =INT(M22/B22) -> 0 | AT22: =IF(MOD(M22,B22)/B22>0.5,1,0) -> 0 | AU22: =IF(AND(MOD(M22,B22)/B22<=0.5,MOD(M22,B22)<>0),1,0) -> 0
A23: องุ่นเคียวโฮ 300 กรัม x 15 P | B23: 15 | C23: {=SUMPRODUCT(ROUNDUP(D23:M23/B23, 0))} -> 9 | D23: ='สุวรรณภูมิ-ผลิต'!F33 -> 17 | E23: ='สุวรรณภูมิ-ผลิต'!G33 -> 6 | F23: ='สุวรรณภูมิ-ผลิต'!H33 -> 5 | G23: ='สุวรรณภูมิ-ผลิต'!I33 -> 2 | H23: ='สุวรรณภูมิ-ผลิต'!J33 -> 3 | I23: ='สุวรรณภูมิ-ผลิต'!K33 -> 4 | J23: ='สุวรรณภูมิ-ผลิต'!L33 -> 5 | K23: ='สุวรรณภูมิ-ผลิต'!M33 -> 1 | ... M23: ='สุวรรณภูมิ-ผลิต'!O33 -> 0 | N23: ='สุวรรณภูมิ-ผลิต'!#REF! -> #REF! | R23: =INT(D23/B23) -> 1 | S23: =IF(MOD(D23,B23)/B23>0.5,1,0) -> 0 | T23: =IF(AND(MOD(D23,B23)/B23<=0.5,MOD(D23,B23)<>0),1,0) -> 1 | U23: =INT(E23/B23) -> 0 | V23: =IF(MOD(E23,B23)/B23>0.5,1,0) -> 0 | W23: =IF(AND(MOD(E23,B23)/B23<=0.5,MOD(E23,B23)<>0),1,0) -> 1 | X23: =INT(F23/B23) -> 0 | Y23: =IF(MOD(F23,B23)/B23>0.5,1,0) -> 0 | Z23: =IF(AND(MOD(F23,B23)/B23<=0.5,MOD(F23,B23)<>0),1,0) -> 1 | AA23: =INT(G23/B23) -> 0 | AB23: =IF(MOD(G23,B23)/B23>0.5,1,0) -> 0 | AC23: =IF(AND(MOD(G23,B23)/B23<=0.5,MOD(G23,B23)<>0),1,0) -> 1 | AD23: =INT(H23/B23) -> 0 | AE23: =IF(MOD(H23,B23)/B23>0.5,1,0) -> 0 | AF23: =IF(AND(MOD(H23,B23)/B23<=0.5,MOD(H23,B23)<>0),1,0) -> 1 | AG23: =INT(I23/B23) -> 0 | AH23: =IF(MOD(I23,B23)/B23>0.5,1,0) -> 0 | AI23: =IF(AND(MOD(I23,B23)/B23<=0.5,MOD(I23,B23)<>0),1,0) -> 1 | AJ23: =INT(J23/B23) -> 0 | AK23: =IF(MOD(J23,B23)/B23>0.5,1,0) -> 0 | AL23: =IF(AND(MOD(J23,B23)/B23<=0.5,MOD(J23,B23)<>0),1,0) -> 1 | AM23: =INT(K23/B23) -> 0 | AN23: =IF(MOD(K23,B23)/B23>0.5,1,0) -> 0 | AO23: =IF(AND(MOD(K23,B23)/B23<=0.5,MOD(K23,B23)<>0),1,0) -> 1 | AP23: =INT(L23/B23) -> 0 | AQ23: =IF(MOD(L23,B23)/B23>0.5,1,0) -> 0 | AR23: =IF(AND(MOD(L23,B23)/B23<=0.5,MOD(L23,B23)<>0),1,0) -> 0 | AS23: =INT(M23/B23) -> 0 | AT23: =IF(MOD(M23,B23)/B23>0.5,1,0) -> 0 | AU23: =IF(AND(MOD(M23,B23)/B23<=0.5,MOD(M23,B23)<>0),1,0) -> 0
A24: ลูกไหนจิ๋ว 200 g. x 27 p | B24: 27 | C24: {=SUMPRODUCT(ROUNDUP(D24:M24/B24, 0))} -> 9 | D24: ='สุวรรณภูมิ-ผลิต'!F35 -> 41 | E24: ='สุวรรณภูมิ-ผลิต'!G35 -> 8 | F24: ='สุวรรณภูมิ-ผลิต'!H35 -> 10 | G24: ='สุวรรณภูมิ-ผลิต'!I35 -> 24 | H24: ='สุวรรณภูมิ-ผลิต'!J35 -> 6 | I24: ='สุวรรณภูมิ-ผลิต'!K35 -> 6 | J24: ='สุวรรณภูมิ-ผลิต'!L35 -> 14 | K24: ='สุวรรณภูมิ-ผลิต'!M35 -> 20 | ... M24: ='สุวรรณภูมิ-ผลิต'!O35 -> 0
A25: องุ่นแดงไร้เมล็ด 300 g. x 20 p | B25: 20 | C25: {=SUMPRODUCT(ROUNDUP(D25:M25/B25, 0))} -> 17 | D25: ='สุวรรณภูมิ-ผลิต'!F37 -> 73 | E25: ='สุวรรณภูมิ-ผลิต'!G37 -> 22 | F25: ='สุวรรณภูมิ-ผลิต'!H37 -> 29 | G25: ='สุวรรณภูมิ-ผลิต'!I37 -> 32 | H25: ='สุวรรณภูมิ-ผลิต'!J37 -> 23 | I25: ='สุวรรณภูมิ-ผลิต'!K37 -> 10 | J25: ='สุวรรณภูมิ-ผลิต'!L37 -> 24 | K25: ='สุวรรณภูมิ-ผลิต'!M37 -> 31 | ... M25: ='สุวรรณภูมิ-ผลิต'!O37 -> 0
A26: เบอร์รี่ดูโอ้ 160 กรัม x 32 P | B26: 32 | C26: {=SUMPRODUCT(ROUNDUP(D26:M26/B26, 0))} -> 9 | D26: ='สุวรรณภูมิ-ผลิต'!F39 -> 53 | E26: ='สุวรรณภูมิ-ผลิต'!G39 -> 15 | F26: ='สุวรรณภูมิ-ผลิต'!H39 -> 7 | G26: ='สุวรรณภูมิ-ผลิต'!I39 -> 11 | H26: ='สุวรรณภูมิ-ผลิต'!J39 -> 1 | I26: ='สุวรรณภูมิ-ผลิต'!K39 -> 2 | J26: ='สุวรรณภูมิ-ผลิต'!L39 -> 6 | K26: ='สุวรรณภูมิ-ผลิต'!M39 -> 15 | ... M26: ='สุวรรณภูมิ-ผลิต'!O39 -> 0
A27: สาลี่ทอง แพ็ก 2 ผล (400g.) x 15 P | B27: 15 | C27: {=SUMPRODUCT(ROUNDUP(D27:M27/B27, 0))} -> 7 | D27: ='สุวรรณภูมิ-ผลิต'!F41 -> 18 | E27: ='สุวรรณภูมิ-ผลิต'!G41 -> 6 | F27: ='สุวรรณภูมิ-ผลิต'!H41 -> 4 | G27: ='สุวรรณภูมิ-ผลิต'!I41 -> 8 | H27: ='สุวรรณภูมิ-ผลิต'!J41 -> 0 | I27: ='สุวรรณภูมิ-ผลิต'!K41 -> 0 | J27: ='สุวรรณภูมิ-ผลิต'!L41 -> 13 | K27: ='สุวรรณภูมิ-ผลิต'!M41 -> 11 | ... N27: ='สุวรรณภูมิ-ผลิต'!P41 -> 60
A28: สาลี่ทอง แพ็ก 2 ผล (400g.) x 8 P | B28: 8 | C28: {=SUMPRODUCT(ROUNDUP(D28:M28/B28, 0))} -> 20 | D28: ='สุวรรณภูมิ-ผลิต'!F43 -> 24 | E28: ='สุวรรณภูมิ-ผลิต'!G43 -> 17 | F28: ='สุวรรณภูมิ-ผลิต'!H43 -> 12 | G28: ='สุวรรณภูมิ-ผลิต'!I43 -> 11 | H28: ='สุวรรณภูมิ-ผลิต'!J43 -> 25 | I28: ='สุวรรณภูมิ-ผลิต'!K43 -> 13 | J28: ='สุวรรณภูมิ-ผลิต'!L43 -> 7 | K28: ='สุวรรณภูมิ-ผลิต'!M43 -> 17 | ... M28: ='สุวรรณภูมิ-ผลิต'!O43 -> 0
A29: รวม | C29: =SUM(C10:C28) -> 238 | D29: =SUM(D30:D32)*-1 -> -18 | E29: =SUM(E30:E32)*-1 -> -10 | F29: =SUM(F30:F32)*-1 -> -10 | G29: =SUM(G30:G32)*-1 -> -11 | H29: =SUM(H30:H32)*-1 -> -9 | I29: =SUM(I30:I32)*-1 -> -8 | J29: =SUM(J30:J32)*-1 -> -11 | K29: =SUM(K30:K32)*-1 -> -14 | ... M29: =SUM(M30:M32)*-1 -> 0
A30: ตะกร้าเต็ม | D30: =SUM(R10:R24) -> 10 | E30: =SUM(U10:U24) -> 2 | F30: =SUM(X10:X24) -> 2 | G30: =SUM(AA10:AA24) -> 4 | H30: =SUM(AD10:AD24) -> 1 | I30: =SUM(AG10:AG24) -> 0 | J30: =SUM(AJ10:AJ24) -> 3 | K30: =SUM(AM10:AM24) -> 7 | L30: =SUM(AP10:AP24) -> 0 | M30: =SUM(AS10:AS24) -> 0
A31: เกินครึ่งตะกร้า | D31: =SUM(S10:S24) -> 5 | E31: =SUM(V10:V24) -> 4 | F31: =SUM(Y10:Y24) -> 4 | G31: =SUM(AB10:AB24) -> 3 | H31: =SUM(AE10:AE24) -> 4 | I31: =SUM(AH10:AH24) -> 2 | J31: =SUM(AK10:AK24) -> 3 | K31: =SUM(AN10:AN24) -> 3 | L31: =SUM(AQ10:AQ24) -> 0 | M31: =SUM(AT10:AT24) -> 0
A32: น้อยกว่าหรือเท่ากับครึ่งตะกร้า | D32: =SUM(T10:T24) -> 3 | E32: =SUM(W10:W24) -> 4 | F32: =SUM(Z10:Z24) -> 4 | G32: =SUM(AC10:AC24) -> 4 | H32: =SUM(AF10:AF24) -> 4 | I32: =SUM(AI10:AI24) -> 6 | J32: =SUM(AL10:AL24) -> 5 | K32: =SUM(AO10:AO24) -> 4 | L32: =SUM(AR10:AR24) -> 0 | M32: =SUM(AU10:AU24) -> 0
A35: 4 ล้อ โกลบอล | B35: ตะกร้าเต็ม | C35: 134 | D35: =IF(C35=0, 0, ((SUM(D30:M30)+SUM(D31:M31))/C35)*100) -> 42.537313 | E35: %
B36: ตะกร้าซ้อน | C36: 242 | D36: =IF(C36=0, 0, ((SUM(D32:M32))/C36)*100) -> 14.049587 | E36: %
B37: พื้นที่ที่ต้องใช้ | D37: =D35+D36 -> 56.5869 | E37: %
B38: พื้นที่รถ | D38: 100 | E38: %
B39: จำนวนรถที่ต้องใช้ | D39: =CEILING(D37 /D38, 1) -> 1 | E39: คัน
A40: 4 ล้อ รถนอก (จัมโบ้) | B40: ตะกร้าเต็ม | C40: 154 | D40: =IF(C40=0, 0, ((SUM(D30:M30)+SUM(D31:M31))/C40)*100) -> 37.012987 | E40: %
B41: ตะกร้าซ้อน | C41: 278 | D41: =IF(C41=0, 0, ((SUM(D32:M32))/C41)*100) -> 12.230216 | E41: %
B42: พื้นที่ที่ต้องใช้ | D42: =D40+D41 -> 49.243203 | E42: %
B43: พื้นที่รถ | D43: 100 | E43: %
B44: จำนวนรถที่ต้องใช้ | D44: =CEILING(D42 /D43, 1) -> 1 | E44: คัน
...

Sheet คันที่1
A5: ผู้ส่ง : KNA 7-11 สุวรรณภูมิ คันที่ 1
A7: เซเว่น DC สุวรรณภูมิ | C7: บรรจุ/ตก. | D7: ='สุวรรณภูมิ-ผลิต'!F3 -> วันที่ 18/08/69 ส่งวันที่ PO 19/08/69 | I7: ยอดรวม
D9: PO1 | E9: PO 2 | F9: PO 3 | G9: PO 4 | H9: PO 5 | I9: แพค | J9: ตะกร้า
A10: 1 | B10: องุ่นแดงนอกมีเมล็ด 200 กรัม x 32 P | C10: 32 | D10: ='สุวรรณภูมิ-ผลิต'!F7 -> 43 | E10: ='สุวรรณภูมิ-ผลิต'!G7 -> 29 | F10: ='สุวรรณภูมิ-ผลิต'!H7 -> 24 | G10: ='สุวรรณภูมิ-ผลิต'!I7 -> 21 | H10: ='สุวรรณภูมิ-ผลิต'!J7 -> 22 | I10: =SUM(D10:H10) -> 139 | J10: 13
B11: Red Seed 200 g. x 32 P ( 8859388000100 ) | D11: =IF(D10=0, "", IF(MOD(D10, $C$10) = 0, D10 / $C$10, IF(INT(D10 / $C$10) = 0, MOD(D10, $C$10) & " P", INT(D10 / $C$10) & " + " & MOD(D10, $C$10) & " P"))) -> 1 + 11 P | E11: =IF(E10=0, "", IF(MOD(E10, $C$10) = 0, E10 / $C$10, IF(INT(E10 / $C$10) = 0, MOD(E10, $C$10) & " P", INT(E10 / $C$10) & " + " & MOD(E10, $C$10) & " P"))) -> 29 P | F11: =IF(F10=0, "", IF(MOD(F10, $C$10) = 0, F10 / $C$10, IF(INT(F10 / $C$10) = 0, MOD(F10, $C$10) & " P", INT(F10 / $C$10) & " + " & MOD(F10, $C$10) & " P"))) -> 24 P | G11: =IF(G10=0, "", IF(MOD(G10, $C$10) = 0, G10 / $C$10, IF(INT(G10 / $C$10) = 0, MOD(G10, $C$10) & " P", INT(G10 / $C$10) & " + " & MOD(G10, $C$10) & " P"))) -> 21 P | H11: =IF(H10=0, "", IF(MOD(H10, $C$10) = 0, H10 / $C$10, IF(INT(H10 / $C$10) = 0, MOD(H10, $C$10) & " P", INT(H10 / $C$10) & " + " & MOD(H10, $C$10) & " P"))) -> 22 P
A12: 2 | B12: องุ่นแดงไร้เมล็ด150กรัม x 32 Pไข่ปลา | C12: 32 | D12: ='สุวรรณภูมิ-ผลิต'!F9 -> 127 | E12: ='สุวรรณภูมิ-ผลิต'!G9 -> 53 | F12: ='สุวรรณภูมิ-ผลิต'!H9 -> 52 | G12: ='สุวรรณภูมิ-ผลิต'!I9 -> 80 | H12: ='สุวรรณภูมิ-ผลิต'!J9 -> 49 | I12: =SUM(D12:H12) -> 361 | J12: 6
B13: Red Seedless 150 g. x 32 P ( 8859388007000 ) | D13: =IF(D12=0, "", IF(MOD(D12, $C$12) = 0, D12 / $C$12, IF(INT(D12 / $C$12) = 0, MOD(D12, $C$12) & " P", INT(D12 / $C$12) & " + " & MOD(D12, $C$12) & " P"))) -> 3 + 31 P | E13: =IF(E12=0, "", IF(MOD(E12, $C$12) = 0, E12 / $C$12, IF(INT(E12 / $C$12) = 0, MOD(E12, $C$12) & " P", INT(E12 / $C$12) & " + " & MOD(E12, $C$12) & " P"))) -> 1 + 21 P | F13: =IF(F12=0, "", IF(MOD(F12, $C$12) = 0, F12 / $C$12, IF(INT(F12 / $C$12) = 0, MOD(F12, $C$12) & " P", INT(F12 / $C$12) & " + " & MOD(F12, $C$12) & " P"))) -> 1 + 20 P | G13: =IF(G12=0, "", IF(MOD(G12, $C$12) = 0, G12 / $C$12, IF(INT(G12 / $C$12) = 0, MOD(G12, $C$12) & " P", INT(G12 / $C$12) & " + " & MOD(G12, $C$12) & " P"))) -> 2 + 16 P | H13: =IF(H12=0, "", IF(MOD(H12, $C$12) = 0, H12 / $C$12, IF(INT(H12 / $C$12) = 0, MOD(H12, $C$12) & " P", INT(H12 / $C$12) & " + " & MOD(H12, $C$12) & " P"))) -> 1 + 17 P
A14: 4 | B14: สตรอเบอร์รี่ ออส 250 กรัม x 27 P | C14: 27 | D14: ='สุวรรณภูมิ-ผลิต'!#REF! -> #REF! | E14: ='สุวรรณภูมิ-ผลิต'!#REF! -> #REF! | F14: ='สุวรรณภูมิ-ผลิต'!#REF! -> #REF! | G14: ='สุวรรณภูมิ-ผลิต'!#REF! -> #REF! | H14: ='สุวรรณภูมิ-ผลิต'!#REF! -> #REF! | I14: =SUM(D14:H14) -> #REF! | J14: 5
B15: Straw Aus 250 g. x 27 P ( 2003009710008 ) | D15: =IF(D14=0, "", IF( MOD(D14,#REF!) = 0, D14 /#REF!, IF(INT(D14 /#REF!) = 0, MOD(D14,#REF!) & " P", INT(D14 /#REF!) & " + " & MOD(D14,#REF!) & " P"))) -> #REF! | E15: =IF(E14=0, "", IF( MOD(E14,#REF!) = 0, E14 /#REF!, IF(INT(E14 /#REF!) = 0, MOD(E14,#REF!) & " P", INT(E14 /#REF!) & " + " & MOD(E14,#REF!) & " P"))) -> #REF! | F15: =IF(F14=0, "", IF( MOD(F14,#REF!) = 0, F14 /#REF!, IF(INT(F14 /#REF!) = 0, MOD(F14,#REF!) & " P", INT(F14 /#REF!) & " + " & MOD(F14,#REF!) & " P"))) -> #REF! | G15: =IF(G14=0, "", IF( MOD(G14,#REF!) = 0, G14 /#REF!, IF(INT(G14 /#REF!) = 0, MOD(G14,#REF!) & " P", INT(G14 /#REF!) & " + " & MOD(G14,#REF!) & " P"))) -> #REF! | H15: =IF(H14=0, "", IF( MOD(H14,#REF!) = 0, H14 /#REF!, IF(INT(H14 /#REF!) = 0, MOD(H14,#REF!) & " P", INT(H14 /#REF!) & " + " & MOD(H14,#REF!) & " P"))) -> #REF!
A16: 5 | B16: บลูเบอร์รี่ 125 กรัม x 36 P | C16: 36 | D16: ='สุวรรณภูมิ-ผลิต'!#REF! -> #REF! | E16: ='สุวรรณภูมิ-ผลิต'!#REF! -> #REF! | F16: ='สุวรรณภูมิ-ผลิต'!#REF! -> #REF! | G16: ='สุวรรณภูมิ-ผลิต'!#REF! -> #REF! | H16: ='สุวรรณภูมิ-ผลิต'!#REF! -> #REF! | I16: =SUM(D16:H16) -> #REF! | J16: 7
B17: Blue 125 g. x 36 P ( 2003009720007 ) | D17: =IF(D16=0, "", IF(MOD(D16, $C$16) = 0, D16 / $C$16, IF(INT(D16 / $C$16) = 0, MOD(D16, $C$16) & " P", INT(D16 / $C$16) & " + " & MOD(D16, $C$16) & " P"))) -> #REF! | E17: =IF(E16=0, "", IF(MOD(E16, $C$16) = 0, E16 / $C$16, IF(INT(E16 / $C$16) = 0, MOD(E16, $C$16) & " P", INT(E16 / $C$16) & " + " & MOD(E16, $C$16) & " P"))) -> #REF! | F17: =IF(F16=0, "", IF(MOD(F16, $C$16) = 0, F16 / $C$16, IF(INT(F16 / $C$16) = 0, MOD(F16, $C$16) & " P", INT(F16 / $C$16) & " + " & MOD(F16, $C$16) & " P"))) -> #REF! | G17: =IF(G16=0, "", IF(MOD(G16, $C$16) = 0, G16 / $C$16, IF(INT(G16 / $C$16) = 0, MOD(G16, $C$16) & " P", INT(G16 / $C$16) & " + " & MOD(G16, $C$16) & " P"))) -> #REF! | H17: =IF(H16=0, "", IF(MOD(H16, $C$16) = 0, H16 / $C$16, IF(INT(H16 / $C$16) = 0, MOD(H16, $C$16) & " P", INT(H16 / $C$16) & " + " & MOD(H16, $C$16) & " P"))) -> #REF!
A18: 6 | B18: องุ่นไชน์มัสแคท 300 กรัม x 15 P | C18: 15 | D18: ='สุวรรณภูมิ-ผลิต'!F11 -> 63 | E18: ='สุวรรณภูมิ-ผลิต'!G11 -> 16 | F18: ='สุวรรณภูมิ-ผลิต'!H11 -> 13 | G18: ='สุวรรณภูมิ-ผลิต'!I11 -> 30 | H18: ='สุวรรณภูมิ-ผลิต'!J11 -> 12 | I18: =SUM(D18:H18) -> 134 | J18: 7
