Workbook

Sheet มหาชัย-ผลิต
B4: ผู้ส่ง : 7-11 มหาชัย 6 ล้อ 83-8096 พี่ปาล์ม+คาย | D4: วันที่ 18/08/69 ส่งวันที่ PO. 19/08/69
B5: เซเว่น - มหาชัย | D5: บรรจุ/ตก. | E5: ตี 01.00 น. | F5: ยอดรวม | H5: ของคืน
F7: แพค | G7: ตะกร้า
B8: 1 | C8: องุ่นดำไร้เมล็ด 150 กรัม x36P | D8: 36 | E8: 171 | F8: =SUM(E8:E8) -> 171 | G8: =มหาชัย!C10 -> 5
C9: BlackGrapesSeedless150g.( 8859388000025 ) | E9: =IF(E8=0, "", IF(MOD(E8, $D$8) = 0, E8 / $D$8, IF(INT(E8 / $D$8) = 0, MOD(E8, $D$8) & " P", INT(E8 / $D$8) & " + " & MOD(E8, $D$8) & " P"))) -> 4 + 27 P
B10: 2 | C10: องุ่นแดงนอกมีเมล็ด 200 กรัม x 32 P | D10: 32 | E10: 384 | F10: =SUM(E10:E10) -> 384 | G10: =มหาชัย!C11 -> 12
C11: Red Seed ( 8859388000100 ) | E11: =IF(E10=0, "", IF(MOD(E10, $D$10) = 0, E10 / $D$10, IF(INT(E10 / $D$10) = 0, MOD(E10, $D$10) & " P", INT(E10 / $D$10) & " + " & MOD(E10, $D$10) & " P"))) -> 12
B12: 3 | C12: เชอร์รี่สดนำเข้า150 กรัม(อเมริกา)x36P | D12: 36 | E12: 154 | F12: =SUM(E12:E12) -> 154 | G12: =มหาชัย!C12 -> 5
C13: Cherry 150 g ( 8859388008885 ) | E13: =IF(E12=0, "", IF(MOD(E12, $D$12) = 0, E12/ $D$12, IF(INT(E12 / $D$12) = 0, MOD(E12, $D$12) & " P", INT(E12 / $D$12) & " + " & MOD(E12, $D$12) & " P"))) -> 4 + 10 P
B14: 4 | C14: ส้มแพ็ก 4 ผล(450 กรัม) x14 P | D14: 14 | E14: 115 | F14: =SUM(E14:E14) -> 115 | G14: =มหาชัย!C13 -> 9
C15: Mandarin orange P.4 (8859388000445) | E15: =IF(E14=0, "", IF(MOD(E14, $D$14) = 0, E14/ $D$14, IF(INT(E14 / $D$14) = 0, MOD(E14, $D$14) & " P", INT(E14 / $D$14) & " + " & MOD(E14, $D$14) & " P"))) -> 8 + 3 P
B16: 5 | C16: แอปเปิ้ลแพ็ก 4 ผล(400 กรัม) x14 P | D16: 14 | E16: 95 | F16: =SUM(E16:E16) -> 95 | G16: =มหาชัย!C14 -> 7
C17: Apple P.4 (8859388000568 ) | E17: =IF(E16=0, "", IF(MOD(E16, $D$16) = 0, E16/ $D$16, IF(INT(E16 / $D$16) = 0, MOD(E16, $D$16) & " P", INT(E16 / $D$16) & " + " & MOD(E16, $D$16) & " P"))) -> 6 + 11 P
B18: 6 | C18: องุ่นแดงไร้เมล็ด150กรัม x 32 Pไข่ปลา | D18: 32 | E18: 183 | F18: =SUM(E18:E18) -> 183 | G18: =มหาชัย!C15 -> 6
C19: Red Seedless ( 8859388007000 ) | E19: =IF(E18=0, "", IF(MOD(E18, $D$18) = 0, E18/ $D$18, IF(INT(E18 / $D$18) = 0, MOD(E18, $D$18) & " P", INT(E18 / $D$18) & " + " & MOD(E18, $D$18) & " P"))) -> 5 + 23 P
B20: 7 | C20: พุทราจีน 200 กรัม x 27 P | D20: 27 | E20: 316 | F20: =SUM(E20:E20) -> 316 | G20: =มหาชัย!C16 -> 12
C21: Jujube 200g.(8859388000087 ) | E21: =IF(E20=0, "", IF(MOD(E20, $D$20) = 0, E20/ $D$20, IF(INT(E20 / $D$20) = 0, MOD(E20, $D$20) & " P", INT(E20 / $D$20) & " + " & MOD(E20, $D$20) & " P"))) -> 11 + 19 P
B22: 8 | C22: สตรอเบอร์รี่ 250 กรัม x 27 P | D22: 27 | E22: 322 | F22: =SUM(E22:E22) -> 322 | G22: =มหาชัย!C17 -> 12
C23: Straw250 g. ( 2003009710008 ) | E23: =IF(E22=0, "", IF(MOD(E22, $D$22) = 0, E22/ $D$22, IF(INT(E22 / $D$22) = 0, MOD(E22, $D$22) & " P", INT(E22 / $D$22) & " + " & MOD(E22, $D$22) & " P"))) -> 11 + 25 P
B24: 9 | C24: บลูเบอร์รี่ 125 กรัม x 36 P | D24: 36 | E24: 257 | F24: =SUM(E24:E24) -> 257 | G24: =มหาชัย!C18 -> 8
C25: Blue ( 2003009720007 ) | E25: =IF(E24=0, "", IF(MOD(E24, $D$24) = 0, E24/ $D$24, IF(INT(E24 / $D$24) = 0, MOD(E24, $D$24) & " P", INT(E24 / $D$24) & " + " & MOD(E24, $D$24) & " P"))) -> 7 + 5 P
B26: 10 | C26: องุ่นดำไร้เมล็ด 300 กรัม x20P | D26: 20 | E26: 127 | F26: =SUM(E26:E26) -> 127 | G26: =มหาชัย!C19 -> 7
C27: Black Grapes Seedless ( 8859388002562 ) | E27: =IF(E26=0, "", IF(MOD(E26, $D$26) = 0, E26/ $D$26, IF(INT(E26 / $D$26) = 0, MOD(E26, $D$26) & " P", INT(E26 / $D$26) & " + " & MOD(E26, $D$26) & " P"))) -> 6 + 7 P
B28: 11 | C28: องุ่นไซน์มัสแคท 300 กรัม x 15 P | D28: 15 | E28: 54 | F28: =SUM(E28:E28) -> 54 | G28: =มหาชัย!C20 -> 4
C29: Shine muscat 300 g ( 885938000018 ) | E29: =IF(E28=0, "", IF(MOD(E28, $D$28) = 0, E28/ $D$28, IF(INT(E28 / $D$28) = 0, MOD(E28, $D$28) & " P", INT(E28 / $D$28) & " + " & MOD(E28, $D$28) & " P"))) -> 3 + 9 P
B30: 12 | C30: แอปเปิ้ลแดงวอชิงตันลูกเดี่ยว x 45 P | D30: 45 | E30: 8 | F30: =SUM(E30:E30) -> 8 | G30: =มหาชัย!C21 -> 1
C31: Washington ( 8859388000759 ) | E31: =IF(E30=0, "", IF(MOD(E30, $D$30) = 0, E30/ $D$30, IF(INT(E30 / $D$30) = 0, MOD(E30, $D$30) & " P", INT(E30 / $D$30) & " + " & MOD(E30, $D$30) & " P"))) -> 8 P
B32: 13 | C32: องุ่นสวีทแซฟไฟร์ 300 กรัม x 15 P | D32: 15 | E32: 118 | F32: =SUM(E32:E32) -> 118 | G32: =มหาชัย!C22 -> 8
C33: Sweet Sapphire 300gx 15 P ( '8859388000223 ) | E33: =IF(E32=0, "", IF(MOD(E32, $D$32) = 0, E32/ $D$32, IF(INT(E32 / $D$32) = 0, MOD(E32, $D$32) & " P", INT(E32 / $D$32) & " + " & MOD(E32, $D$32) & " P"))) -> 7 + 13 P
B34: 14 | C34: องุ่นเคียวโฮ 300 กรัม x 15 P | D34: 15 | E34: 41 | F34: =SUM(E34:E34) -> 41 | G34: =มหาชัย!C23 -> 3
C35: Kyoho Grape 300g ( 8859388000063 ) | E35: =IF(E34=0, "", IF(MOD(E34, $D$34) = 0, E34/ $D$34, IF(INT(E34 / $D$34) = 0, MOD(E34, $D$34) & " P", INT(E34 / $D$34) & " + " & MOD(E34, $D$34) & " P"))) -> 2 + 11 P
B36: 15 | C36: ลูกไหนจิ๋ว 200 g. x 27 p | D36: 27 | E36: 90 | F36: =SUM(E36:E36) -> 90 | G36: =มหาชัย!C24 -> 4
C37: Plum 200 g. ( 8859388001091 ) | E37: =IF(E36=0, "", IF(MOD(E36, $D$36) = 0, E36/ $D$36, IF(INT(E36 / $D$36) = 0, MOD(E36, $D$36) & " P", INT(E36 / $D$36) & " + " & MOD(E36, $D$36) & " P"))) -> 3 + 9 P
B38: 16 | C38: องุ่นแดงไร้เมล็ด 300 g. x 20 p | D38: 20 | E38: 182 | F38: =SUM(E38:E38) -> 182 | G38: =มหาชัย!C25 -> 10
C39: Red Seedless 300 g.( 8859388001084 ) | E39: =IF(E38=0, "", IF(MOD(E38, $D$38) = 0, E38/ $D$38, IF(INT(E38 / $D$38) = 0, MOD(E38, $D$38) & " P", INT(E38 / $D$38) & " + " & MOD(E38, $D$38) & " P"))) -> 9 + 2 P
B40: 17 | C40: เบอร์รี่ดูโอ้ 160 กรัม x 32 P | D40: 32 | E40: 89 | F40: =SUM(E40:E40) -> 89 | G40: =มหาชัย!C26 -> 3
C41: Berry Duo 160g. ( 8859388010239 ) | E41: =IF(E40=0, "", IF(MOD(E40, $D$40) = 0, E40/ $D$40, IF(INT(E40 / $D$40) = 0, MOD(E40, $D$40) & " P", INT(E40 / $D$40) & " + " & MOD(E40, $D$40) & " P"))) -> 2 + 25 P
B42: 18 | C42: สาลี่ทอง แพ็ก 2 ผล (400g.) x 15 P | D42: 15 | E42: 13 | F42: =SUM(E42:E42) -> 13 | G42: =มหาชัย!C27 -> 1
C43: Pear 400g ( 8859388010284 ) | E43: =IF(E42=0, "", IF(MOD(E42, $D$42) = 0, E42/ $D$42, IF(INT(E42 / $D$42) = 0, MOD(E42, $D$42) & " P", INT(E42 / $D$42) & " + " & MOD(E42, $D$42) & " P"))) -> 13 P
B44: 19 | C44: สาลี่ทอง แพ็ก 4 ผล (800g.) x 8 P | D44: 8 | E44: 74 | F44: =SUM(E44:E44) -> 74 | G44: =มหาชัย!C28 -> 10
...

Sheet มหาชัย
A1: #VALUE! | B1: Global Trade and Distribution Co., Ltd. บริษัท โกลบอล เทรด แอนด์ ดิสทริบิวชั่น จำกัด | O1: Date:
O3: PO:
A4: ผู้ส่ง:
A6: เซเว่น SB | C6: สุวรรณภูมิ
C7: รับ GTD | D7: เวลาลงสินค้า 02:00-04:00 น.
D8: PO1 | E8: PO2 | F8: PO3 | G8: PO4 | H8: PO5 | I8: PO6 | J8: PO7 | K8: PO8 | L8: PO9 | M8: PO10 | O8: ยอดรับจริง | P8: ยอดส่งคืน | Q8: หมายเหตุ | R8: KK - PO1 | U8: KK - PO2 | X8: SR - PO1 | AA8: SR - PO2 | AD8: CM- PO1 | AG8: CM- PO2 | AJ8: PK- PO1 | AM8: PK- PO2 | AP8: HY- PO1 | AS8: HY- PO2
A9: รายการสินค้า | B9: บรรจุ/ตก. | N9: GTD | R9: F | S9: >H | T9: ≤H | U9: F | V9: >H | W9: ≤H | X9: F | Y9: >H | Z9: ≤H | AA9: F | AB9: >H | AC9: ≤H | AD9: F | AE9: >H | AF9: ≤H | AG9: F | AH9: >H | AI9: ≤H | AJ9: F | AK9: >H | AL9: ≤H | AM9: F | AN9: >H | AO9: ≤H | AP9: F | AQ9: >H | AR9: ≤H | AS9: F | AT9: >H | AU9: ≤H
A10: องุ่นดำไร้เมล็ด 150 กรัม x36P | B10: 36 | C10: =SUMPRODUCT(ROUNDUP(D10/B10,0)) -> 5 | D10: ='มหาชัย-ผลิต'!E8 -> 171 | N10: ='มหาชัย-ผลิต'!F8 -> 171 | R10: =INT(D10/B10) -> 4 | S10: =IF(MOD(D10,B10)/B10>0.5,1,0) -> 1 | T10: =IF(AND(MOD(D10,B10)/B10<=0.5,MOD(D10,B10)<>0),1,0) -> 0 | U10: =INT(E10/B10) -> 0 | V10: =IF(MOD(E10,B10)/B10>0.5,1,0) -> 0 | W10: =IF(AND(MOD(E10,B10)/B10<=0.5,MOD(E10,B10)<>0),1,0) -> 0 | X10: =INT(F10/B10) -> 0 | Y10: =IF(MOD(F10,B10)/B10>0.5,1,0) -> 0 | Z10: =IF(AND(MOD(F10,B10)/B10<=0.5,MOD(F10,B10)<>0),1,0) -> 0 | AA10: =INT(G10/B10) -> 0 | AB10: =IF(MOD(G10,B10)/B10>0.5,1,0) -> 0 | AC10: =IF(AND(MOD(G10,B10)/B10<=0.5,MOD(G10,B10)<>0),1,0) -> 0 | AD10: =INT(H10/B10) -> 0 | AE10: =IF(MOD(H10,B10)/B10>0.5,1,0) -> 0 | AF10: =IF(AND(MOD(H10,B10)/B10<=0.5,MOD(H10,B10)<>0),1,0) -> 0 | AG10: =INT(I10/B10) -> 0 | AH10: =IF(MOD(I10,B10)/B10>0.5,1,0) -> 0 | AI10: =IF(AND(MOD(I10,B10)/B10<=0.5,MOD(I10,B10)<>0),1,0) -> 0 | AJ10: =INT(J10/B10) -> 0 | AK10: =IF(MOD(J10,B10)/B10>0.5,1,0) -> 0 | AL10: =IF(AND(MOD(J10,B10)/B10<=0.5,MOD(J10,B10)<>0),1,0) -> 0 | AM10: =INT(K10/B10) -> 0 | AN10: =IF(MOD(K10,B10)/B10>0.5,1,0) -> 0 | AO10: =IF(AND(MOD(K10,B10)/B10<=0.5,MOD(K10,B10)<>0),1,0) -> 0 | AP10: =INT(L10/B10) -> 0 | AQ10: =IF(MOD(L10,B10)/B10>0.5,1,0) -> 0 | AR10: =IF(AND(MOD(L10,B10)/B10<=0.5,MOD(L10,B10)<>0),1,0) -> 0 | AS10: =INT(M10/B10) -> 0 | AT10: =IF(MOD(M10,B10)/B10>0.5,1,0) -> 0 | AU10: =IF(AND(MOD(M10,B10)/B10<=0.5,MOD(M10,B10)<>0),1,0) -> 0
A11: องุ่นแดงนอกมีเมล็ด 200 กรัม x 32 P | B11: 32 | C11: =SUMPRODUCT(ROUNDUP(D11/B11,0)) -> 12 | D11: ='มหาชัย-ผลิต'!E10 -> 384 | N11: =INT(SUM(D11:M11)/B11) & " full, " & IF(MOD(SUM(D11:M11), B11)/B11 <= 0.5, "1 less than half", IF(MOD(SUM(D11:M11), B11)/B11 > 0.5, "1 more than half", "")) -> 12 full, 1 less than half | R11: =INT(D11/B11) -> 12 | S11: =IF(MOD(D11,B11)/B11>0.5,1,0) -> 0 | T11: =IF(AND(MOD(D11,B11)/B11<=0.5,MOD(D11,B11)<>0),1,0) -> 0 | U11: =INT(E11/B11) -> 0 | V11: =IF(MOD(E11,B11)/B11>0.5,1,0) -> 0 | W11: =IF(AND(MOD(E11,B11)/B11<=0.5,MOD(E11,B11)<>0),1,0) -> 0 | X11: =INT(F11/B11) -> 0 | Y11: =IF(MOD(F11,B11)/B11>0.5,1,0) -> 0 | Z11: =IF(AND(MOD(F11,B11)/B11<=0.5,MOD(F11,B11)<>0),1,0) -> 0 | AA11: =INT(G11/B11) -> 0 | AB11: =IF(MOD(G11,B11)/B11>0.5,1,0) -> 0 | AC11: =IF(AND(MOD(G11,B11)/B11<=0.5,MOD(G11,B11)<>0),1,0) -> 0 | AD11: =INT(H11/B11) -> 0 | AE11: =IF(MOD(H11,B11)/B11>0.5,1,0) -> 0 | AF11: =IF(AND(MOD(H11,B11)/B11<=0.5,MOD(H11,B11)<>0),1,0) -> 0 | AG11: =INT(I11/B11) -> 0 | AH11: =IF(MOD(I11,B11)/B11>0.5,1,0) -> 0 | AI11: =IF(AND(MOD(I11,B11)/B11<=0.5,MOD(I11,B11)<>0),1,0) -> 0 | AJ11: =INT(J11/B11) -> 0 | AK11: =IF(MOD(J11,B11)/B11>0.5,1,0) -> 0 | AL11: =IF(AND(MOD(J11,B11)/B11<=0.5,MOD(J11,B11)<>0),1,0) -> 0 | AM11: =INT(K11/B11) -> 0 | AN11: =IF(MOD(K11,B11)/B11>0.5,1,0) -> 0 | AO11: =IF(AND(MOD(K11,B11)/B11<=0.5,MOD(K11,B11)<>0),1,0) -> 0 | AP11: =INT(L11/B11) -> 0 | AQ11: =IF(MOD(L11,B11)/B11>0.5,1,0) -> 0 | AR11: =IF(AND(MOD(L11,B11)/B11<=0.5,MOD(L11,B11)<>0),1,0) -> 0 | AS11: =INT(M11/B11) -> 0 | AT11: =IF(MOD(M11,B11)/B11>0.5,1,0) -> 0 | AU11: =IF(AND(MOD(M11,B11)/B11<=0.5,MOD(M11,B11)<>0),1,0) -> 0
A12: เชอร์รี่สดนำเข้า150 กรัม(อเมริกา)x36P | B12: 36 | C12: =SUMPRODUCT(ROUNDUP(D12/B12,0)) -> 5 | D12: ='มหาชัย-ผลิต'!E12 -> 154 | N12: =INT(SUM(D12:M12)/B12) & " full, " & IF(MOD(SUM(D12:M12), B12)/B12 <= 0.5, "1 less than half", IF(MOD(SUM(D12:M12), B12)/B12 > 0.5, "1 more than half", "")) -> 4 full, 1 less than half | R12: =INT(D12/B12) -> 4 | S12: =IF(MOD(D12,B12)/B12>0.5,1,0) -> 0 | T12: =IF(AND(MOD(D12,B12)/B12<=0.5,MOD(D12,B12)<>0),1,0) -> 1 | U12: =INT(E12/B12) -> 0 | V12: =IF(MOD(E12,B12)/B12>0.5,1,0) -> 0 | W12: =IF(AND(MOD(E12,B12)/B12<=0.5,MOD(E12,B12)<>0),1,0) -> 0 | X12: =INT(F12/B12) -> 0 | Y12: =IF(MOD(F12,B12)/B12>0.5,1,0) -> 0 | Z12: =IF(AND(MOD(F12,B12)/B12<=0.5,MOD(F12,B12)<>0),1,0) -> 0 | AA12: =INT(G12/B12) -> 0 | AB12: =IF(MOD(G12,B12)/B12>0.5,1,0) -> 0 | AC12: =IF(AND(MOD(G12,B12)/B12<=0.5,MOD(G12,B12)<>0),1,0) -> 0 | AD12: =INT(H12/B12) -> 0 | AE12: =IF(MOD(H12,B12)/B12>0.5,1,0) -> 0 | AF12: =IF(AND(MOD(H12,B12)/B12<=0.5,MOD(H12,B12)<>0),1,0) -> 0 | AG12: =INT(I12/B12) -> 0 | AH12: =IF(MOD(I12,B12)/B12>0.5,1,0) -> 0 | AI12: =IF(AND(MOD(I12,B12)/B12<=0.5,MOD(I12,B12)<>0),1,0) -> 0 | AJ12: =INT(J12/B12) -> 0 | AK12: =IF(MOD(J12,B12)/B12>0.5,1,0) -> 0 | AL12: =IF(AND(MOD(J12,B12)/B12<=0.5,MOD(J12,B12)<>0),1,0) -> 0 | AM12: =INT(K12/B12) -> 0 | AN12: =IF(MOD(K12,B12)/B12>0.5,1,0) -> 0 | AO12: =IF(AND(MOD(K12,B12)/B12<=0.5,MOD(K12,B12)<>0),1,0) -> 0 | AP12: =INT(L12/B12) -> 0 | AQ12: =IF(MOD(L12,B12)/B12>0.5,1,0) -> 0 | AR12: =IF(AND(MOD(L12,B12)/B12<=0.5,MOD(L12,B12)<>0),1,0) -> 0 | AS12: =INT(M12/B12) -> 0 | AT12: =IF(MOD(M12,B12)/B12>0.5,1,0) -> 0 | AU12: =IF(AND(MOD(M12,B12)/B12<=0.5,MOD(M12,B12)<>0),1,0) -> 0
A13: ส้มแพ็ก 4 ผล(450 กรัม) x14 P | B13: 14 | C13: =SUMPRODUCT(ROUNDUP(D13/B13,0)) -> 9 | D13: ='มหาชัย-ผลิต'!E14 -> 115
A14: แอปเปิ้ลแพ็ก 4 ผล(400 กรัม) x14 P | B14: 14 | C14: =SUMPRODUCT(ROUNDUP(D14/B14,0)) -> 7 | D14: ='มหาชัย-ผลิต'!E16 -> 95
A15: องุ่นแดงไร้เมล็ด150กรัม x 32 Pไข่ปลา | B15: 32 | C15: =SUMPRODUCT(ROUNDUP(D15/B15,0)) -> 6 | D15: ='มหาชัย-ผลิต'!E18 -> 183 | N15: =INT(SUM(D15:M15)/B15) & " full, " & IF(MOD(SUM(D15:M15), B15)/B15 <= 0.5, "1 less than half", IF(MOD(SUM(D15:M15), B15)/B15 > 0.5, "1 more than half", "")) -> 5 full, 1 more than half | R15: =INT(D15/B15) -> 5 | S15: =IF(MOD(D15,B15)/B15>0.5,1,0) -> 1 | T15: =IF(AND(MOD(D15,B15)/B15<=0.5,MOD(D15,B15)<>0),1,0) -> 0 | U15: =INT(E15/B15) -> 0 | V15: =IF(MOD(E15,B15)/B15>0.5,1,0) -> 0 | W15: =IF(AND(MOD(E15,B15)/B15<=0.5,MOD(E15,B15)<>0),1,0) -> 0 | X15: =INT(F15/B15) -> 0 | Y15: =IF(MOD(F15,B15)/B15>0.5,1,0) -> 0 | Z15: =IF(AND(MOD(F15,B15)/B15<=0.5,MOD(F15,B15)<>0),1,0) -> 0 | AA15: =INT(G15/B15) -> 0 | AB15: =IF(MOD(G15,B15)/B15>0.5,1,0) -> 0 | AC15: =IF(AND(MOD(G15,B15)/B15<=0.5,MOD(G15,B15)<>0),1,0) -> 0 | AD15: =INT(H15/B15) -> 0 | AE15: =IF(MOD(H15,B15)/B15>0.5,1,0) -> 0 | AF15: =IF(AND(MOD(H15,B15)/B15<=0.5,MOD(H15,B15)<>0),1,0) -> 0 | AG15: =INT(I15/B15) -> 0 | AH15: =IF(MOD(I15,B15)/B15>0.5,1,0) -> 0 | AI15: =IF(AND(MOD(I15,B15)/B15<=0.5,MOD(I15,B15)<>0),1,0) -> 0 | AJ15: =INT(J15/B15) -> 0 | AK15: =IF(MOD(J15,B15)/B15>0.5,1,0) -> 0 | AL15: =IF(AND(MOD(J15,B15)/B15<=0.5,MOD(J15,B15)<>0),1,0) -> 0 | AM15: =INT(K15/B15) -> 0 | AN15: =IF(MOD(K15,B15)/B15>0.5,1,0) -> 0 | AO15: =IF(AND(MOD(K15,B15)/B15<=0.5,MOD(K15,B15)<>0),1,0) -> 0 | AP15: =INT(L15/B15) -> 0 | AQ15: =IF(MOD(L15,B15)/B15>0.5,1,0) -> 0 | AR15: =IF(AND(MOD(L15,B15)/B15<=0.5,MOD(L15,B15)<>0),1,0) -> 0 | AS15: =INT(M15/B15) -> 0 | AT15: =IF(MOD(M15,B15)/B15>0.5,1,0) -> 0 | AU15: =IF(AND(MOD(M15,B15)/B15<=0.5,MOD(M15,B15)<>0),1,0) -> 0
A16: พุทราจีน 200 กรัม x 27 P | B16: 27 | C16: =SUMPRODUCT(ROUNDUP(D16/B16,0)) -> 12 | D16: ='มหาชัย-ผลิต'!E20 -> 316 | U16: =INT(E16/B16) -> 0 | V16: =IF(MOD(E16,B16)/B16>0.5,1,0) -> 0 | W16: =IF(AND(MOD(E16,B16)/B16<=0.5,MOD(E16,B16)<>0),1,0) -> 0 | X16: =INT(F16/B16) -> 0 | Y16: =IF(MOD(F16,B16)/B16>0.5,1,0) -> 0 | Z16: =IF(AND(MOD(F16,B16)/B16<=0.5,MOD(F16,B16)<>0),1,0) -> 0 | AA16: =INT(G16/B16) -> 0 | AB16: =IF(MOD(G16,B16)/B16>0.5,1,0) -> 0 | AC16: =IF(AND(MOD(G16,B16)/B16<=0.5,MOD(G16,B16)<>0),1,0) -> 0 | AD16: =INT(H16/B16) -> 0 | AE16: =IF(MOD(H16,B16)/B16>0.5,1,0) -> 0 | AF16: =IF(AND(MOD(H16,B16)/B16<=0.5,MOD(H16,B16)<>0),1,0) -> 0 | AG16: =INT(I16/B16) -> 0 | AH16: =IF(MOD(I16,B16)/B16>0.5,1,0) -> 0 | AI16: =IF(AND(MOD(I16,B16)/B16<=0.5,MOD(I16,B16)<>0),1,0) -> 0 | AJ16: =INT(J16/B16) -> 0 | AK16: =IF(MOD(J16,B16)/B16>0.5,1,0) -> 0 | AL16: =IF(AND(MOD(J16,B16)/B16<=0.5,MOD(J16,B16)<>0),1,0) -> 0 | AM16: =INT(K16/B16) -> 0 | AN16: =IF(MOD(K16,B16)/B16>0.5,1,0) -> 0 | AO16: =IF(AND(MOD(K16,B16)/B16<=0.5,MOD(K16,B16)<>0),1,0) -> 0 | AP16: =INT(L16/B16) -> 0 | AQ16: =IF(MOD(L16,B16)/B16>0.5,1,0) -> 0 | AR16: =IF(AND(MOD(L16,B16)/B16<=0.5,MOD(L16,B16)<>0),1,0) -> 0 | AS16: =INT(M16/B16) -> 0 | AT16: =IF(MOD(M16,B16)/B16>0.5,1,0) -> 0 | AU16: =IF(AND(MOD(M16,B16)/B16<=0.5,MOD(M16,B16)<>0),1,0) -> 0
A17: สตรอเบอร์รี่ 250 กรัม x 27 P | B17: 27 | C17: =SUMPRODUCT(ROUNDUP(D17/B17,0)) -> 12 | D17: ='มหาชัย-ผลิต'!E22 -> 322 | U17: =INT(E17/B17) -> 0 | V17: =IF(MOD(E17,B17)/B17>0.5,1,0) -> 0 | W17: =IF(AND(MOD(E17,B17)/B17<=0.5,MOD(E17,B17)<>0),1,0) -> 0 | X17: =INT(F17/B17) -> 0 | Y17: =IF(MOD(F17,B17)/B17>0.5,1,0) -> 0 | Z17: =IF(AND(MOD(F17,B17)/B17<=0.5,MOD(F17,B17)<>0),1,0) -> 0 | AA17: =INT(G17/B17) -> 0 | AB17: =IF(MOD(G17,B17)/B17>0.5,1,0) -> 0 | AC17: =IF(AND(MOD(G17,B17)/B17<=0.5,MOD(G17,B17)<>0),1,0) -> 0 | AD17: =INT(H17/B17) -> 0 | AE17: =IF(MOD(H17,B17)/B17>0.5,1,0) -> 0 | AF17: =IF(AND(MOD(H17,B17)/B17<=0.5,MOD(H17,B17)<>0),1,0) -> 0 | AG17: =INT(I17/B17) -> 0 | AH17: =IF(MOD(I17,B17)/B17>0.5,1,0) -> 0 | AI17: =IF(AND(MOD(I17,B17)/B17<=0.5,MOD(I17,B17)<>0),1,0) -> 0 | AJ17: =INT(J17/B17) -> 0 | AK17: =IF(MOD(J17,B17)/B17>0.5,1,0) -> 0 | AL17: =IF(AND(MOD(J17,B17)/B17<=0.5,MOD(J17,B17)<>0),1,0) -> 0 | AM17: =INT(K17/B17) -> 0 | AN17: =IF(MOD(K17,B17)/B17>0.5,1,0) -> 0 | AO17: =IF(AND(MOD(K17,B17)/B17<=0.5,MOD(K17,B17)<>0),1,0) -> 0 | AP17: =INT(L17/B17) -> 0 | AQ17: =IF(MOD(L17,B17)/B17>0.5,1,0) -> 0 | AR17: =IF(AND(MOD(L17,B17)/B17<=0.5,MOD(L17,B17)<>0),1,0) -> 0 | AS17: =INT(M17/B17) -> 0 | AT17: =IF(MOD(M17,B17)/B17>0.5,1,0) -> 0 | AU17: =IF(AND(MOD(M17,B17)/B17<=0.5,MOD(M17,B17)<>0),1,0) -> 0
A18: บลูเบอร์รี่ 125 กรัม x 36 P | B18: 36 | C18: =SUMPRODUCT(ROUNDUP(D18/B18,0)) -> 8 | D18: ='มหาชัย-ผลิต'!E24 -> 257 | N18: =INT(SUM(D18:M18)/B18) & " full, " & IF(MOD(SUM(D18:M18), B18)/B18 <= 0.5, "1 less than half", IF(MOD(SUM(D18:M18), B18)/B18 > 0.5, "1 more than half", "")) -> 7 full, 1 less than half | R18: =INT(D18/B18) -> 7 | S18: =IF(MOD(D18,B18)/B18>0.5,1,0) -> 0 | T18: =IF(AND(MOD(D18,B18)/B18<=0.5,MOD(D18,B18)<>0),1,0) -> 1 | U18: =INT(E18/B18) -> 0 | V18: =IF(MOD(E18,B18)/B18>0.5,1,0) -> 0 | W18: =IF(AND(MOD(E18,B18)/B18<=0.5,MOD(E18,B18)<>0),1,0) -> 0 | X18: =INT(F18/B18) -> 0 | Y18: =IF(MOD(F18,B18)/B18>0.5,1,0) -> 0 | Z18: =IF(AND(MOD(F18,B18)/B18<=0.5,MOD(F18,B18)<>0),1,0) -> 0 | AA18: =INT(G18/B18) -> 0 | AB18: =IF(MOD(G18,B18)/B18>0.5,1,0) -> 0 | AC18: =IF(AND(MOD(G18,B18)/B18<=0.5,MOD(G18,B18)<>0),1,0) -> 0 | AD18: =INT(H18/B18) -> 0 | AE18: =IF(MOD(H18,B18)/B18>0.5,1,0) -> 0 | AF18: =IF(AND(MOD(H18,B18)/B18<=0.5,MOD(H18,B18)<>0),1,0) -> 0 | AG18: =INT(I18/B18) -> 0 | AH18: =IF(MOD(I18,B18)/B18>0.5,1,0) -> 0 | AI18: =IF(AND(MOD(I18,B18)/B18<=0.5,MOD(I18,B18)<>0),1,0) -> 0 | AJ18: =INT(J18/B18) -> 0 | AK18: =IF(MOD(J18,B18)/B18>0.5,1,0) -> 0 | AL18: =IF(AND(MOD(J18,B18)/B18<=0.5,MOD(J18,B18)<>0),1,0) -> 0 | AM18: =INT(K18/B18) -> 0 | AN18: =IF(MOD(K18,B18)/B18>0.5,1,0) -> 0 | AO18: =IF(AND(MOD(K18,B18)/B18<=0.5,MOD(K18,B18)<>0),1,0) -> 0 | AP18: =INT(L18/B18) -> 0 | AQ18: =IF(MOD(L18,B18)/B18>0.5,1,0) -> 0 | AR18: =IF(AND(MOD(L18,B18)/B18<=0.5,MOD(L18,B18)<>0),1,0) -> 0 | AS18: =INT(M18/B18) -> 0 | AT18: =IF(MOD(M18,B18)/B18>0.5,1,0) -> 0 | AU18: =IF(AND(MOD(M18,B18)/B18<=0.5,MOD(M18,B18)<>0),1,0) -> 0
A19: องุ่นดำไร้เมล็ด 300 กรัม x20P | B19: 20 | C19: =SUMPRODUCT(ROUNDUP(D19/B19,0)) -> 7 | D19: ='มหาชัย-ผลิต'!E26 -> 127 | N19: ='มหาชัย-ผลิต'!#REF! -> #REF! | R19: =INT(D19/B19) -> 6 | S19: =IF(MOD(D19,B19)/B19>0.5,1,0) -> 0 | T19: =IF(AND(MOD(D19,B19)/B19<=0.5,MOD(D19,B19)<>0),1,0) -> 1 | U19: =INT(E19/B19) -> 0 | V19: =IF(MOD(E19,B19)/B19>0.5,1,0) -> 0 | W19: =IF(AND(MOD(E19,B19)/B19<=0.5,MOD(E19,B19)<>0),1,0) -> 0 | X19: =INT(F19/B19) -> 0 | Y19: =IF(MOD(F19,B19)/B19>0.5,1,0) -> 0 | Z19: =IF(AND(MOD(F19,B19)/B19<=0.5,MOD(F19,B19)<>0),1,0) -> 0 | AA19: =INT(G19/B19) -> 0 | AB19: =IF(MOD(G19,B19)/B19>0.5,1,0) -> 0 | AC19: =IF(AND(MOD(G19,B19)/B19<=0.5,MOD(G19,B19)<>0),1,0) -> 0 | AD19: =INT(H19/B19) -> 0 | AE19: =IF(MOD(H19,B19)/B19>0.5,1,0) -> 0 | AF19: =IF(AND(MOD(H19,B19)/B19<=0.5,MOD(H19,B19)<>0),1,0) -> 0 | AG19: =INT(I19/B19) -> 0 | AH19: =IF(MOD(I19,B19)/B19>0.5,1,0) -> 0 | AI19: =IF(AND(MOD(I19,B19)/B19<=0.5,MOD(I19,B19)<>0),1,0) -> 0 | AJ19: =INT(J19/B19) -> 0 | AK19: =IF(MOD(J19,B19)/B19>0.5,1,0) -> 0 | AL19: =IF(AND(MOD(J19,B19)/B19<=0.5,MOD(J19,B19)<>0),1,0) -> 0 | AM19: =INT(K19/B19) -> 0 | AN19: =IF(MOD(K19,B19)/B19>0.5,1,0) -> 0 | AO19: =IF(AND(MOD(K19,B19)/B19<=0.5,MOD(K19,B19)<>0),1,0) -> 0 | AP19: =INT(L19/B19) -> 0 | AQ19: =IF(MOD(L19,B19)/B19>0.5,1,0) -> 0 | AR19: =IF(AND(MOD(L19,B19)/B19<=0.5,MOD(L19,B19)<>0),1,0) -> 0 | AS19: =INT(M19/B19) -> 0 | AT19: =IF(MOD(M19,B19)/B19>0.5,1,0) -> 0 | AU19: =IF(AND(MOD(M19,B19)/B19<=0.5,MOD(M19,B19)<>0),1,0) -> 0
A20: องุ่นไซน์มัสแคท 300 กรัมx 15P | B20: 15 | C20: =SUMPRODUCT(ROUNDUP(D20/B20,0)) -> 4 | D20: ='มหาชัย-ผลิต'!E28 -> 54 | U20: =INT(E20/B20) -> 0 | V20: =IF(MOD(E20,B20)/B20>0.5,1,0) -> 0 | W20: =IF(AND(MOD(E20,B20)/B20<=0.5,MOD(E20,B20)<>0),1,0) -> 0 | X20: =INT(F20/B20) -> 0 | Y20: =IF(MOD(F20,B20)/B20>0.5,1,0) -> 0 | Z20: =IF(AND(MOD(F20,B20)/B20<=0.5,MOD(F20,B20)<>0),1,0) -> 0 | AA20: =INT(G20/B20) -> 0 | AB20: =IF(MOD(G20,B20)/B20>0.5,1,0) -> 0 | AC20: =IF(AND(MOD(G20,B20)/B20<=0.5,MOD(G20,B20)<>0),1,0) -> 0 | AD20: =INT(H20/B20) -> 0 | AE20: =IF(MOD(H20,B20)/B20>0.5,1,0) -> 0 | AF20: =IF(AND(MOD(H20,B20)/B20<=0.5,MOD(H20,B20)<>0),1,0) -> 0 | AG20: =INT(I20/B20) -> 0 | AH20: =IF(MOD(I20,B20)/B20>0.5,1,0) -> 0 | AI20: =IF(AND(MOD(I20,B20)/B20<=0.5,MOD(I20,B20)<>0),1,0) -> 0 | AJ20: =INT(J20/B20) -> 0 | AK20: =IF(MOD(J20,B20)/B20>0.5,1,0) -> 0 | AL20: =IF(AND(MOD(J20,B20)/B20<=0.5,MOD(J20,B20)<>0),1,0) -> 0 | AM20: =INT(K20/B20) -> 0 | AN20: =IF(MOD(K20,B20)/B20>0.5,1,0) -> 0 | AO20: =IF(AND(MOD(K20,B20)/B20<=0.5,MOD(K20,B20)<>0),1,0) -> 0 | AP20: =INT(L20/B20) -> 0 | AQ20: =IF(MOD(L20,B20)/B20>0.5,1,0) -> 0 | AR20: =IF(AND(MOD(L20,B20)/B20<=0.5,MOD(L20,B20)<>0),1,0) -> 0 | AS20: =INT(M20/B20) -> 0 | AT20: =IF(MOD(M20,B20)/B20>0.5,1,0) -> 0 | AU20: =IF(AND(MOD(M20,B20)/B20<=0.5,MOD(M20,B20)<>0),1,0) -> 0
A21: แอปเปิ้ลแดงวอชิงตันลูกเดี่ยว x 45 P | B21: 45 | C21: =SUMPRODUCT(ROUNDUP(D21/B21,0)) -> 1 | D21: ='มหาชัย-ผลิต'!E30 -> 8 | U21: =INT(E21/B21) -> 0 | V21: =IF(MOD(E21,B21)/B21>0.5,1,0) -> 0 | W21: =IF(AND(MOD(E21,B21)/B21<=0.5,MOD(E21,B21)<>0),1,0) -> 0 | X21: =INT(F21/B21) -> 0 | Y21: =IF(MOD(F21,B21)/B21>0.5,1,0) -> 0 | Z21: =IF(AND(MOD(F21,B21)/B21<=0.5,MOD(F21,B21)<>0),1,0) -> 0 | AA21: =INT(G21/B21) -> 0 | AB21: =IF(MOD(G21,B21)/B21>0.5,1,0) -> 0 | AC21: =IF(AND(MOD(G21,B21)/B21<=0.5,MOD(G21,B21)<>0),1,0) -> 0 | AD21: =INT(H21/B21) -> 0 | AE21: =IF(MOD(H21,B21)/B21>0.5,1,0) -> 0 | AF21: =IF(AND(MOD(H21,B21)/B21<=0.5,MOD(H21,B21)<>0),1,0) -> 0 | AG21: =INT(I21/B21) -> 0 | AH21: =IF(MOD(I21,B21)/B21>0.5,1,0) -> 0 | AI21: =IF(AND(MOD(I21,B21)/B21<=0.5,MOD(I21,B21)<>0),1,0) -> 0 | AJ21: =INT(J21/B21) -> 0 | AK21: =IF(MOD(J21,B21)/B21>0.5,1,0) -> 0 | AL21: =IF(AND(MOD(J21,B21)/B21<=0.5,MOD(J21,B21)<>0),1,0) -> 0 | AM21: =INT(K21/B21) -> 0 | AN21: =IF(MOD(K21,B21)/B21>0.5,1,0) -> 0 | AO21: =IF(AND(MOD(K21,B21)/B21<=0.5,MOD(K21,B21)<>0),1,0) -> 0 | AP21: =INT(L21/B21) -> 0 | AQ21: =IF(MOD(L21,B21)/B21>0.5,1,0) -> 0 | AR21: =IF(AND(MOD(L21,B21)/B21<=0.5,MOD(L21,B21)<>0),1,0) -> 0 | AS21: =INT(M21/B21) -> 0 | AT21: =IF(MOD(M21,B21)/B21>0.5,1,0) -> 0 | AU21: =IF(AND(MOD(M21,B21)/B21<=0.5,MOD(M21,B21)<>0),1,0) -> 0
A22: องุ่นสวีทแซฟไฟร์ 300 กรัม x 15 P | B22: 15 | C22: =SUMPRODUCT(ROUNDUP(D22/B22,0)) -> 8 | D22: ='มหาชัย-ผลิต'!E32 -> 118 | U22: =INT(E22/B22) -> 0 | V22: =IF(MOD(E22,B22)/B22>0.5,1,0) -> 0 | W22: =IF(AND(MOD(E22,B22)/B22<=0.5,MOD(E22,B22)<>0),1,0) -> 0 | X22: =INT(F22/B22) -> 0 | Y22: =IF(MOD(F22,B22)/B22>0.5,1,0) -> 0 | Z22: =IF(AND(MOD(F22,B22)/B22<=0.5,MOD(F22,B22)<>0),1,0) -> 0 | AA22: =INT(G22/B22) -> 0 | AB22: =IF(MOD(G22,B22)/B22>0.5,1,0) -> 0 | AC22: =IF(AND(MOD(G22,B22)/B22<=0.5,MOD(G22,B22)<>0),1,0) -> 0 | AD22: =INT(H22/B22) -> 0 | AE22: =IF(MOD(H22,B22)/B22>0.5,1,0) -> 0 | AF22: =IF(AND(MOD(H22,B22)/B22<=0.5,MOD(H22,B22)<>0),1,0) -> 0 | AG22: =INT(I22/B22) -> 0 | AH22: =IF(MOD(I22,B22)/B22>0.5,1,0) -> 0 | AI22: =IF(AND(MOD(I22,B22)/B22<=0.5,MOD(I22,B22)<>0),1,0) -> 0 | AJ22: =INT(J22/B22) -> 0 | AK22: =IF(MOD(J22,B22)/B22>0.5,1,0) -> 0 | AL22: =IF(AND(MOD(J22,B22)/B22<=0.5,MOD(J22,B22)<>0),1,0) -> 0 | AM22: =INT(K22/B22) -> 0 | AN22: =IF(MOD(K22,B22)/B22>0.5,1,0) -> 0 | AO22: =IF(AND(MOD(K22,B22)/B22<=0.5,MOD(K22,B22)<>0),1,0) -> 0 | AP22: =INT(L22/B22) -> 0 | AQ22: =IF(MOD(L22,B22)/B22>0.5,1,0) -> 0 | AR22: =IF(AND(MOD(L22,B22)/B22<=0.5,MOD(L22,B22)<>0),1,0) -> 0 | AS22: =INT(M22/B22) -> 0 | AT22: =IF(MOD(M22,B22)/B22>0.5,1,0) -> 0 | AU22: =IF(AND(MOD(M22,B22)/B22<=0.5,MOD(M22,B22)<>0),1,0) -> 0
A23: องุ่นเคียวโฮ 300 กรัม x 15 P | B23: 15 | C23: =SUMPRODUCT(ROUNDUP(D23/B23,0)) -> 3 | D23: ='มหาชัย-ผลิต'!E34 -> 41 | N23: ='มหาชัย-ผลิต'!#REF! -> #REF! | R23: =INT(D23/B23) -> 2 | S23: =IF(MOD(D23,B23)/B23>0.5,1,0) -> 1 | T23: =IF(AND(MOD(D23,B23)/B23<=0.5,MOD(D23,B23)<>0),1,0) -> 0 | U23: =INT(E23/B23) -> 0 | V23: =IF(MOD(E23,B23)/B23>0.5,1,0) -> 0 | W23: =IF(AND(MOD(E23,B23)/B23<=0.5,MOD(E23,B23)<>0),1,0) -> 0 | X23: =INT(F23/B23) -> 0 | Y23: =IF(MOD(F23,B23)/B23>0.5,1,0) -> 0 | Z23: =IF(AND(MOD(F23,B23)/B23<=0.5,MOD(F23,B23)<>0),1,0) -> 0 | AA23: =INT(G23/B23) -> 0 | AB23: =IF(MOD(G23,B23)/B23>0.5,1,0) -> 0 | AC23: =IF(AND(MOD(G23,B23)/B23<=0.5,MOD(G23,B23)<>0),1,0) -> 0 | AD23: =INT(H23/B23) -> 0 | AE23: =IF(MOD(H23,B23)/B23>0.5,1,0) -> 0 | AF23: =IF(AND(MOD(H23,B23)/B23<=0.5,MOD(H23,B23)<>0),1,0) -> 0 | AG23: =INT(I23/B23) -> 0 | AH23: =IF(MOD(I23,B23)/B23>0.5,1,0) -> 0 | AI23: =IF(AND(MOD(I23,B23)/B23<=0.5,MOD(I23,B23)<>0),1,0) -> 0 | AJ23: =INT(J23/B23) -> 0 | AK23: =IF(MOD(J23,B23)/B23>0.5,1,0) -> 0 | AL23: =IF(AND(MOD(J23,B23)/B23<=0.5,MOD(J23,B23)<>0),1,0) -> 0 | AM23: =INT(K23/B23) -> 0 | AN23: =IF(MOD(K23,B23)/B23>0.5,1,0) -> 0 | AO23: =IF(AND(MOD(K23,B23)/B23<=0.5,MOD(K23,B23)<>0),1,0) -> 0 | AP23: =INT(L23/B23) -> 0 | AQ23: =IF(MOD(L23,B23)/B23>0.5,1,0) -> 0 | AR23: =IF(AND(MOD(L23,B23)/B23<=0.5,MOD(L23,B23)<>0),1,0) -> 0 | AS23: =INT(M23/B23) -> 0 | AT23: =IF(MOD(M23,B23)/B23>0.5,1,0) -> 0 | AU23: =IF(AND(MOD(M23,B23)/B23<=0.5,MOD(M23,B23)<>0),1,0) -> 0
A24: ลูกไหนจิ๋ว 200 g. x 27 p | B24: 27 | C24: =SUMPRODUCT(ROUNDUP(D24/B24,0)) -> 4 | D24: ='มหาชัย-ผลิต'!E36 -> 90 | U24: =INT(E24/B24) -> 0 | V24: =IF(MOD(E24,B24)/B24>0.5,1,0) -> 0 | W24: =IF(AND(MOD(E24,B24)/B24<=0.5,MOD(E24,B24)<>0),1,0) -> 0 | X24: =INT(F24/B24) -> 0 | Y24: =IF(MOD(F24,B24)/B24>0.5,1,0) -> 0 | Z24: =IF(AND(MOD(F24,B24)/B24<=0.5,MOD(F24,B24)<>0),1,0) -> 0 | AA24: =INT(G24/B24) -> 0 | AB24: =IF(MOD(G24,B24)/B24>0.5,1,0) -> 0 | AC24: =IF(AND(MOD(G24,B24)/B24<=0.5,MOD(G24,B24)<>0),1,0) -> 0 | AD24: =INT(H24/B24) -> 0 | AE24: =IF(MOD(H24,B24)/B24>0.5,1,0) -> 0 | AF24: =IF(AND(MOD(H24,B24)/B24<=0.5,MOD(H24,B24)<>0),1,0) -> 0 | AG24: =INT(I24/B24) -> 0 | AH24: =IF(MOD(I24,B24)/B24>0.5,1,0) -> 0 | AI24: =IF(AND(MOD(I24,B24)/B24<=0.5,MOD(I24,B24)<>0),1,0) -> 0 | AJ24: =INT(J24/B24) -> 0 | AK24: =IF(MOD(J24,B24)/B24>0.5,1,0) -> 0 | AL24: =IF(AND(MOD(J24,B24)/B24<=0.5,MOD(J24,B24)<>0),1,0) -> 0 | AM24: =INT(K24/B24) -> 0 | AN24: =IF(MOD(K24,B24)/B24>0.5,1,0) -> 0 | AO24: =IF(AND(MOD(K24,B24)/B24<=0.5,MOD(K24,B24)<>0),1,0) -> 0 | AP24: =INT(L24/B24) -> 0 | AQ24: =IF(MOD(L24,B24)/B24>0.5,1,0) -> 0 | AR24: =IF(AND(MOD(L24,B24)/B24<=0.5,MOD(L24,B24)<>0),1,0) -> 0 | AS24: =INT(M24/B24) -> 0 | AT24: =IF(MOD(M24,B24)/B24>0.5,1,0) -> 0 | AU24: =IF(AND(MOD(M24,B24)/B24<=0.5,MOD(M24,B24)<>0),1,0) -> 0
A25: องุ่นแดงไร้เมล็ด 300 g. x 20 p | B25: 20 | C25: =SUMPRODUCT(ROUNDUP(D25/B25,0)) -> 10 | D25: ='มหาชัย-ผลิต'!E38 -> 182 | U25: =INT(E25/B25) -> 0 | V25: =IF(MOD(E25,B25)/B25>0.5,1,0) -> 0 | W25: =IF(AND(MOD(E25,B25)/B25<=0.5,MOD(E25,B25)<>0),1,0) -> 0 | X25: =INT(F25/B25) -> 0 | Y25: =IF(MOD(F25,B25)/B25>0.5,1,0) -> 0 | Z25: =IF(AND(MOD(F25,B25)/B25<=0.5,MOD(F25,B25)<>0),1,0) -> 0 | AA25: =INT(G25/B25) -> 0 | AB25: =IF(MOD(G25,B25)/B25>0.5,1,0) -> 0 | AC25: =IF(AND(MOD(G25,B25)/B25<=0.5,MOD(G25,B25)<>0),1,0) -> 0 | AD25: =INT(H25/B25) -> 0 | AE25: =IF(MOD(H25,B25)/B25>0.5,1,0) -> 0 | AF25: =IF(AND(MOD(H25,B25)/B25<=0.5,MOD(H25,B25)<>0),1,0) -> 0 | AG25: =INT(I25/B25) -> 0 | AH25: =IF(MOD(I25,B25)/B25>0.5,1,0) -> 0 | AI25: =IF(AND(MOD(I25,B25)/B25<=0.5,MOD(I25,B25)<>0),1,0) -> 0 | AJ25: =INT(J25/B25) -> 0 | AK25: =IF(MOD(J25,B25)/B25>0.5,1,0) -> 0 | AL25: =IF(AND(MOD(J25,B25)/B25<=0.5,MOD(J25,B25)<>0),1,0) -> 0 | AM25: =INT(K25/B25) -> 0 | AN25: =IF(MOD(K25,B25)/B25>0.5,1,0) -> 0 | AO25: =IF(AND(MOD(K25,B25)/B25<=0.5,MOD(K25,B25)<>0),1,0) -> 0 | AP25: =INT(L25/B25) -> 0 | AQ25: =IF(MOD(L25,B25)/B25>0.5,1,0) -> 0 | AR25: =IF(AND(MOD(L25,B25)/B25<=0.5,MOD(L25,B25)<>0),1,0) -> 0 | AS25: =INT(M25/B25) -> 0 | AT25: =IF(MOD(M25,B25)/B25>0.5,1,0) -> 0 | AU25: =IF(AND(MOD(M25,B25)/B25<=0.5,MOD(M25,B25)<>0),1,0) -> 0
A26: เบอร์รี่ดูโอ้ 160 กรัม x 32 P | B26: 32 | C26: =SUMPRODUCT(ROUNDUP(D26/B26,0)) -> 3 | D26: ='มหาชัย-ผลิต'!E40 -> 89
A27: สาลี่ทอง แพ็ก 2 ผล (400g.) x 15 P | B27: 15 | C27: =SUMPRODUCT(ROUNDUP(D27/B27,0)) -> 1 | D27: ='มหาชัย-ผลิต'!E42 -> 13
A28: สาลี่ทอง แพ็ก 2 ผล (400g.) x 8 P | B28: 8 | C28: =SUMPRODUCT(ROUNDUP(D28/B28,0)) -> 10 | D28: ='มหาชัย-ผลิต'!E44 -> 74
A29: รวม | C29: =SUM(C10:C28) -> 127 | D29: =SUM(D30:D32)*-1 -> -46
A30: ตะกร้าเต็ม | D30: =SUM(R10:R23) -> 40
A31: เกินครึ่งตะกร้า | D31: =SUM(S10:S23) -> 3
A32: น้อยกว่าหรือเท่ากับครึ่งตะกร้า | D32: =SUM(T10:T23) -> 3
A35: 4 ล้อ โกลบอล | B35: ตะกร้าเต็ม | C35: 134 | D35: =IF(C35=0, 0, ((SUM(D30:M30)+SUM(D31:M31))/C35)*100) -> 32.089552 | E35: %
B36: ตะกร้าซ้อน | C36: 242 | D36: =IF(C36=0, 0, ((SUM(D32:M32))/C36)*100) -> 1.2396694 | E36: %
B37: พื้นที่ที่ต้องใช้ | D37: =D35+D36 -> 33.329222 | E37: %
B38: พื้นที่รถ | D38: 100 | E38: %
B39: จำนวนรถที่ต้องใช้ | D39: =CEILING(D37 /D38, 1) -> 1 | E39: คัน
A40: 4 ล้อ รถนอก (จัมโบ้) | B40: ตะกร้าเต็ม | C40: 154 | D40: =IF(C40=0, 0, ((SUM(D30:M30)+SUM(D31:M31))/C40)*100) -> 27.922078 | E40: %
B41: ตะกร้าซ้อน | C41: 278 | D41: =IF(C41=0, 0, ((SUM(D32:M32))/C41)*100) -> 1.0791367 | E41: %
B42: พื้นที่ที่ต้องใช้ | D42: =D40+D41 -> 29.001215 | E42: %
B43: พื้นที่รถ | D43: 100 | E43: %
B44: จำนวนรถที่ต้องใช้ | D44: =CEILING(D42 /D43, 1) -> 1 | E44: คัน
...

Sheet คันที่ 2
A5: ผู้ส่ง : | B5: 4 ล้อ 41 พี่เอ๋ คันที่ 2 | C5: มหาชัย
A6: เซเว่น MC | C6: บรรจุ/ตก. | D6: วันที่ 08/10/68 ส่งวันที่ PO.09/10/68 | E6: ยอดรวม
D8: 01.00-06.00 น
E9: แพค | F9: ตะกร้า
A10: 1 | B10: องุ่นสวิทแซฟฟร์ 300 กรัม x15 P | C10: 15 | D10: 1888 | E10: =SUM(D10:D10) -> 1888 | F10: 126
D11: 125+13 P
A12: รวมยอดตะกร้า | D12: 126 | E12: = | F12: =SUM(F10:F11) -> 126
A14: ลายมือชื่อ | C14: เริ่มโหลด | D14: โหลดเสร็จ | E14: หมายเหตุ
A15: แพ็คกิ้ง
A16: เช็คเกอร์
A17: ขนส่ง
D19: *เบิกตะกร้ากลับด้วยนะคะ | E19: =F12 -> 126 | F19: ใบ
E20: รถมีผ้าม่านปิด หรือไม่( ✓)
E21: มี | F21: ไม่มี
D24: ลายเซ็น คนขึ้นของ

Sheet คันที่ 1
A5: ผู้ส่ง : | B5: 4 ล้อ 47 พี่เอก (พิเศษ) คันที่ 1 | C5: มหาชัย
A6: เซเว่น MC | C6: บรรจุ/ตก. | D6: วันที่ 08/10/68 ส่งวันที่ PO.09/10/68 | E6: ยอดรวม
D8: 01.00-06.00 น
E9: แพค | F9: ตะกร้า
A10: 1 | B10: องุ่นแดงนอกมีเมล็ด 200 กรัม x 32 P | C10: 32 | D10: 566 | E10: =SUM(D10:D10) -> 566 | F10: 18
D11: 17+22 P
A12: 2 | B12: ส้มแพ็ก 4 ผล x 14 P (450 กรัม) | C12: 14 | E12: =SUM(D12:D12) -> 0 | F12: =มหาชัย!C11 -> 12
D13: =IF(D12=0, "", IF(MOD(D12, $C$11) = 0, D12 / $C$11, IF(INT(D12 / $C$11) = 0, MOD(D12, $C$11) & " P", INT(D12 / $C$11) & " + " & MOD(D12, $C$11) & " P")))
A14: 2 | B14: องุ่นแดงไร้เมล็ด150กรัม x 32 Pไข่ปลา | C14: 32 | D14: 275 | E14: =SUM(D14:D14) -> 275 | F14: =มหาชัย!#REF! -> #REF!
D15: 8+19 P
A16: 3 | B16: พุทราจีน 200 กรัม x 27 | C16: 27 | D16: 228 | E16: =SUM(D16:D16) -> 228 | F16: 9
D17: 8+12 P
A18: 4 | B18: บลูเบอร์รี่ 125 กรัม x 36 P | C18: 36 | D18: 181 | E18: =SUM(D18:D18) -> 181 | F18: 6
D19: 5+1 P
A20: 5 | B20: องุ่นไชน์มัสแคท 300 กรัม x 15 P | C20: 15 | D20: 272 | E20: =SUM(D20:D20) -> 272 | F20: 19
D21: 18+2 P
A22: 6 | B22: แอปเปิ้ลแดงวอชิงตันลูกเดี่ยว x 45 P | C22: 45 | D22: 24 | E22: =SUM(D22:D22) -> 24 | F22: 1
D23: 24 P
A24: 7 | B24: แอปเปิ้ลเจ้าหญิง 200 กรัม x27 P | C24: 27 | D24: 390 | E24: =SUM(D24:D24) -> 390 | F24: 15
D25: 14+12 P
A26: 8 | B26: องุ่นเคียวโฮ 300 กรัม x 15 P | C26: 15 | D26: 40 | E26: =SUM(D26:D26) -> 40 | F26: 3
D27: 2+10 P
A28: 9 | B28: ลูกไหนจิ๋ว 200 กรัม x27 P | C28: 27 | D28: 172 | E28: =SUM(D28:D28) -> 172 | F28: 7
D29: 6+10 P
A30: 10 | B30: องุ่นแดงไร้เมล็ด 300 g. x 20 p | C30: 20 | D30: 239 | E30: =SUM(D30:D30) -> 239 | F30: 12
D31: 11+19 P
A32: 11 | B32: เบอร์รี่ดูโอ้ 160 กรัม x 32 P | C32: 32 | D32: 121 | E32: =SUM(D32:D32) -> 121 | F32: 4
D33: 3+25 P
A34: 12 | B34: อโวคาโดแฮส 150 กรัม x 45 P | C34: 45 | D34: 54 | E34: =SUM(D34:D34) -> 54 | F34: 2
D35: 1+9 P
A36: รวมยอดตะกร้า | D36: 105 | E36: = | F36: 105
A38: ลายมือชื่อ | C38: เริ่มโหลด | D38: โหลดเสร็จ | E38: หมายเหตุ
A39: แพ็คกิ้ง
A40: เช็คเกอร์
A41: ขนส่ง
D43: *เบิกตะกร้ากลับด้วยนะคะ | E43: =F36 -> 105 | F43: ใบ
E44: รถมีผ้าม่านปิด หรือไม่( ✓)
E45: มี | F45: ไม่มี
D48: ลายเซ็น คนขึ้นของ
